<mujoco model="panda">

    <option timestep="0.001" integrator="Euler" gravity="0 0 -9.81">
        <flag sensornoise="disable" energy="disable" contact="enable" />
    </option>

    <default>
        <geom condim="4" solimp="0.99 0.99 0" solref="0.01 1" />
    </default>

    <compiler angle="radian" />
    <size njmax="500" nconmax="100" />
    <asset>
        <mesh name="bowl" file="dual_panda_arm_with_bowl/meshes/bowl_side.stl" />
        <mesh name="bowl_bottom" file="dual_panda_arm_with_bowl/meshes/bowl_bottom.stl" />
        <mesh name="hand" file="dual_panda_arm_with_bowl/meshes/hand.stl" />
        <mesh name="finger" file="dual_panda_arm_with_bowl/meshes/finger.stl" />
    </asset>
    <worldbody>
        <geom size="10 10 0.1" type="plane" rgba="0.5 0.5 0.5 1" />
        <geom size="0.5 1 0.5" pos="0 0 0.5" type="box" rgba="1 1 1 1" />
        <geom size="0.09 0.015" pos="-0.075 -0.5 1.06" quat="0.707107 0 0.707107 0" type="cylinder" />
        <geom size="0.09" pos="-0.06 -0.5 1.06" />
        <geom size="0.09" pos="-0.09 -0.5 1.06" />
        <geom size="0.09 0.015" pos="-0.075 0.5 1.06" quat="0.707107 0 0.707107 0" type="cylinder" />
        <geom size="0.09" pos="-0.06 0.5 1.06" />
        <geom size="0.09" pos="-0.09 0.5 1.06" />
        <body name="panda_1_link1" pos="0 -0.5 1.333">
            <inertial pos="0 0 -0.1915" mass="13.3087" diaginertia="0.204715 0.204715 0.0489535" />
            <joint name="panda_1_joint1" pos="0 0 0" axis="0 0 1" limited="true" range="-2.8973 2.8973" />
            <geom size="0.09 0.1415" pos="0 0 -0.1915" type="cylinder" />
            <geom size="0.09" pos="0 0 -0.333" />
            <geom size="0.09" pos="0 0 -0.05" />
            <body name="panda_1_link2" pos="0 0 0" quat="0.707107 -0.707107 0 0">
                <inertial pos="0 0 0" mass="9.16088" diaginertia="0.0516216 0.0516216 0.0321547" />
                <joint name="panda_1_joint2" pos="0 0 0" axis="0 0 1" limited="true" range="-1.7628 1.7628" />
                <geom size="0.09 0.06" type="cylinder" />
                <geom size="0.09" pos="0 0 -0.06" />
                <geom size="0.09" pos="0 0 0.06" />
                <body name="panda_1_link3" pos="0 -0.316 0" quat="0.707107 0.707107 0 0">
                    <inertial pos="0 0 -0.145" mass="9.92429" diaginertia="0.0690273 0.0690273 0.0352465" />
                    <joint name="panda_1_joint3" pos="0 0 0" axis="0 0 1" limited="true" range="-2.8973 2.8973" />
                    <geom size="0.09 0.075" pos="0 0 -0.145" type="cylinder" />
                    <geom size="0.09" pos="0 0 -0.22" />
                    <geom size="0.09" pos="0 0 -0.07" />
                    <body name="panda_1_link4" pos="0.0825 0 0" quat="0.707107 0.707107 0 0">
                        <inertial pos="0 0 0" mass="9.16088" diaginertia="0.0516216 0.0516216 0.0321547" />
                        <joint name="panda_1_joint4" pos="0 0 0" axis="0 0 1" limited="true" range="-3.0718 -0.0698" />
                        <geom size="0.09 0.06" type="cylinder" />
                        <geom size="0.09" pos="0 0 0.06" />
                        <geom size="0.09" pos="0 0 -0.06" />
                        <body name="panda_1_link5" pos="-0.0825 0.384 0" quat="0.707107 -0.707107 0 0">
                            <inertial pos="0 0.0191577 -0.228869" quat="0.980145 -0.198283 0 0" mass="11.3762" diaginertia="0.1023 0.0981299 0.0379623" />
                            <joint name="panda_1_joint5" pos="0 0 0" axis="0 0 1" limited="true" range="-2.8973 2.8973" />
                            <geom size="0.09 0.05" pos="0 0 -0.26" type="cylinder" />
                            <geom size="0.09" pos="0 0 -0.31" />
                            <geom size="0.09" pos="0 0 -0.21" />
                            <geom size="0.055 0.07" pos="0 0.08 -0.13" type="cylinder" />
                            <geom size="0.055" pos="0 0.08 -0.06" />
                            <geom size="0.055" pos="0 0.08 -0.2" />
                            <body name="panda_1_link6" pos="0 0 0" quat="0.707107 0.707107 0 0">
                                <inertial pos="0 0 -0.03" mass="5.89782" diaginertia="0.021275 0.021275 0.0161278" />
                                <joint name="panda_1_joint6" pos="0 0 0" axis="0 0 1" limited="true" range="-0.0175 3.7525" />
                                <geom size="0.08 0.04" pos="0 0 -0.03" type="cylinder" />
                                <geom size="0.08" pos="0 0 0.01" />
                                <geom size="0.08" pos="0 0 -0.07" />
                                <body name="panda_1_link7" pos="0.088 0 0" quat="0.707107 0.707107 0 0">
                                    <inertial pos="0.0106568 0.0106572 0.0388043" quat="0.916928 -0.0992588 0.040817 -0.38435" mass="7.62208" diaginertia="0.0495877 0.0436748 0.0197738" />
                                    <joint name="panda_1_joint7" pos="0 0 0" axis="0 0 1" limited="true" range="-2.8973 2.8973" />
                                    <geom size="0.07 0.07" pos="0 0 0.01" type="cylinder" />
                                    <geom size="0.07" pos="0 0 0.08" />
                                    <geom size="0.07" pos="0 0 -0.06" />
                                    <geom size="0.06 0.005" pos="0.0424 0.0424 0.082" quat="0.5 0.5 0.5 -0.5" type="cylinder" />
                                    <geom size="0.06" pos="0.0424 0.0424 0.087" />
                                    <geom size="0.06" pos="0.0424 0.0424 0.077" />
                                    <geom pos="0 0 0.107" quat="0.92388 0 0 -0.382683" type="mesh" mesh="hand" />
                                    <body name="panda_1_leftfinger" pos="0 0 0.1654" quat="0.92388 0 0 -0.382683">
                                        <inertial pos="-1.82909e-06 0.0123159 0.0245396" quat="0.70113 0.0854958 -0.0855768 0.702698" mass="0.0166274" diaginertia="4.87247e-06 4.85977e-06 8.12278e-07" />
                                        <joint name="panda_1_finger_joint1" pos="0 0 0" axis="0 1 0" type="slide" limited="true" range="0 0.04" stiffness="100.0" springref="0.0" damping="1.0" />
                                        <!-- <geom name="panda_1_leftfinger" pos="0 0.002 0" size="0.01 0.002 0.053" type="box" /> -->
                                        <geom name="panda_1_leftfinger" type="mesh" mesh="finger" />
                                    </body>
                                    <body name="panda_1_rightfinger" pos="0 0 0.1654" quat="0.92388 0 0 -0.382683">
                                        <inertial pos="1.82909e-06 -0.0123159 0.0245396" quat="-0.702698 0.0855768 0.0854958 0.70113" mass="0.0166274" diaginertia="4.87247e-06 4.85977e-06 8.12278e-07" />
                                        <joint name="panda_1_finger_joint2" pos="0 0 0" axis="0 -1 0" type="slide" limited="true" range="0 0.04" stiffness="100.0" springref="0.0" damping="1.0" />
                                        <!-- <geom name="panda_1_rightfinger" pos="0 -0.002 0" quat="0 0 0 1" size="0.01 0.002 0.053" type="box" /> -->
                                        <geom name="panda_1_rightfinger" quat="0 0 0 1" type="mesh" mesh="finger" />
                                    </body>
                                </body>
                            </body>
                        </body>
                    </body>
                </body>
            </body>
        </body>
        <body name="panda_2_link1" pos="0 0.5 1.333">
            <inertial pos="0 0 -0.1915" mass="13.3087" diaginertia="0.204715 0.204715 0.0489535" />
            <joint name="panda_2_joint1" pos="0 0 0" axis="0 0 1" limited="true" range="-2.8973 2.8973" />
            <geom size="0.09 0.1415" pos="0 0 -0.1915" type="cylinder" />
            <geom size="0.09" pos="0 0 -0.333" />
            <geom size="0.09" pos="0 0 -0.05" />
            <body name="panda_2_link2" pos="0 0 0" quat="0.707107 -0.707107 0 0">
                <inertial pos="0 0 0" mass="9.16088" diaginertia="0.0516216 0.0516216 0.0321547" />
                <joint name="panda_2_joint2" pos="0 0 0" axis="0 0 1" limited="true" range="-1.7628 1.7628" />
                <geom size="0.09 0.06" type="cylinder" />
                <geom size="0.09" pos="0 0 -0.06" />
                <geom size="0.09" pos="0 0 0.06" />
                <body name="panda_2_link3" pos="0 -0.316 0" quat="0.707107 0.707107 0 0">
                    <inertial pos="0 0 -0.145" mass="9.92429" diaginertia="0.0690273 0.0690273 0.0352465" />
                    <joint name="panda_2_joint3" pos="0 0 0" axis="0 0 1" limited="true" range="-2.8973 2.8973" />
                    <geom size="0.09 0.075" pos="0 0 -0.145" type="cylinder" />
                    <geom size="0.09" pos="0 0 -0.22" />
                    <geom size="0.09" pos="0 0 -0.07" />
                    <body name="panda_2_link4" pos="0.0825 0 0" quat="0.707107 0.707107 0 0">
                        <inertial pos="0 0 0" mass="9.16088" diaginertia="0.0516216 0.0516216 0.0321547" />
                        <joint name="panda_2_joint4" pos="0 0 0" axis="0 0 1" limited="true" range="-3.0718 -0.0698" />
                        <geom size="0.09 0.06" type="cylinder" />
                        <geom size="0.09" pos="0 0 0.06" />
                        <geom size="0.09" pos="0 0 -0.06" />
                        <body name="panda_2_link5" pos="-0.0825 0.384 0" quat="0.707107 -0.707107 0 0">
                            <inertial pos="0 0.0191577 -0.228869" quat="0.980145 -0.198283 0 0" mass="11.3762" diaginertia="0.1023 0.0981299 0.0379623" />
                            <joint name="panda_2_joint5" pos="0 0 0" axis="0 0 1" limited="true" range="-2.8973 2.8973" />
                            <geom size="0.09 0.05" pos="0 0 -0.26" type="cylinder" />
                            <geom size="0.09" pos="0 0 -0.31" />
                            <geom size="0.09" pos="0 0 -0.21" />
                            <geom size="0.055 0.07" pos="0 0.08 -0.13" type="cylinder" />
                            <geom size="0.055" pos="0 0.08 -0.06" />
                            <geom size="0.055" pos="0 0.08 -0.2" />
                            <body name="panda_2_link6" pos="0 0 0" quat="0.707107 0.707107 0 0">
                                <inertial pos="0 0 -0.03" mass="5.89782" diaginertia="0.021275 0.021275 0.0161278" />
                                <joint name="panda_2_joint6" pos="0 0 0" axis="0 0 1" limited="true" range="-0.0175 3.7525" />
                                <geom size="0.08 0.04" pos="0 0 -0.03" type="cylinder" />
                                <geom size="0.08" pos="0 0 0.01" />
                                <geom size="0.08" pos="0 0 -0.07" />
                                <body name="panda_2_link7" pos="0.088 0 0" quat="0.707107 0.707107 0 0">
                                    <inertial pos="0.0106568 0.0106572 0.0388043" quat="0.916928 -0.0992588 0.040817 -0.38435" mass="7.62208" diaginertia="0.0495877 0.0436748 0.0197738" />
                                    <joint name="panda_2_joint7" pos="0 0 0" axis="0 0 1" limited="true" range="-2.8973 2.8973" />
                                    <geom size="0.07 0.07" pos="0 0 0.01" type="cylinder" />
                                    <geom size="0.07" pos="0 0 0.08" />
                                    <geom size="0.07" pos="0 0 -0.06" />
                                    <geom size="0.06 0.005" pos="0.0424 0.0424 0.082" quat="0.5 0.5 0.5 -0.5" type="cylinder" />
                                    <geom size="0.06" pos="0.0424 0.0424 0.087" />
                                    <geom size="0.06" pos="0.0424 0.0424 0.077" />
                                    <geom pos="0 0 0.107" quat="0.92388 0 0 -0.382683" type="mesh" mesh="hand" />
                                    <body name="panda_2_leftfinger" pos="0 0 0.1654" quat="0.92388 0 0 -0.382683">
                                        <inertial pos="-1.82909e-06 0.0123159 0.0245396" quat="0.70113 0.0854958 -0.0855768 0.702698" mass="0.0166274" diaginertia="4.87247e-06 4.85977e-06 8.12278e-07" />
                                        <joint name="panda_2_finger_joint1" pos="0 0 0" axis="0 1 0" type="slide" limited="true" range="0 0.04" stiffness="100.0" springref="0.0" damping="1.0" />
                                        <geom name="panda_2_leftfinger" type="mesh" mesh="finger" />
                                    </body>
                                    <body name="panda_2_rightfinger" pos="0 0 0.1654" quat="0.92388 0 0 -0.382683">
                                        <inertial pos="1.82909e-06 -0.0123159 0.0245396" quat="-0.702698 0.0855768 0.0854958 0.70113" mass="0.0166274" diaginertia="4.87247e-06 4.85977e-06 8.12278e-07" />
                                        <joint name="panda_2_finger_joint2" pos="0 0 0" axis="0 -1 0" type="slide" limited="true" range="0 0.04" stiffness="100.0" springref="0.0" damping="1.0" />
                                        <geom name="panda_2_rightfinger" quat="0 0 0 1" type="mesh" mesh="finger" />
                                    </body>
                                </body>
                            </body>
                        </body>
                    </body>
                </body>
            </body>
        </body>
        <body name="bowl" pos="0 0 1">
            <freejoint />
            <geom name="bowl_bottom" type="mesh" mesh="bowl_bottom" rgba="1 1 1 1" />
            <geom name="bowl_side_1" type="mesh" euler="0 0 0.1745" mesh="bowl" rgba="1 1 1 1" />
            <geom name="bowl_side_2" type="mesh" euler="0 0 0.3491" mesh="bowl" rgba="1 1 1 1" />
            <geom name="bowl_side_3" type="mesh" euler="0 0 0.5236" mesh="bowl" rgba="1 1 1 1" />
            <geom name="bowl_side_4" type="mesh" euler="0 0 0.6981" mesh="bowl" rgba="1 1 1 1" />
            <geom name="bowl_side_5" type="mesh" euler="0 0 0.8727" mesh="bowl" rgba="1 1 1 1" />
            <geom name="bowl_side_6" type="mesh" euler="0 0 1.0472" mesh="bowl" rgba="1 1 1 1" />
            <geom name="bowl_side_7" type="mesh" euler="0 0 1.2217" mesh="bowl" rgba="1 1 1 1" />
            <geom name="bowl_side_8" type="mesh" euler="0 0 1.3963" mesh="bowl" rgba="1 1 1 1" />
            <geom name="bowl_side_9" type="mesh" euler="0 0 1.5708" mesh="bowl" rgba="1 1 1 1" />
            <geom name="bowl_side_10" type="mesh" euler="0 0 1.7453" mesh="bowl" rgba="1 1 1 1" />
            <geom name="bowl_side_11" type="mesh" euler="0 0 1.9199" mesh="bowl" rgba="1 1 1 1" />
            <geom name="bowl_side_12" type="mesh" euler="0 0 2.0944" mesh="bowl" rgba="1 1 1 1" />
            <geom name="bowl_side_13" type="mesh" euler="0 0 2.2689" mesh="bowl" rgba="1 1 1 1" />
            <geom name="bowl_side_14" type="mesh" euler="0 0 2.4435" mesh="bowl" rgba="1 1 1 1" />
            <geom name="bowl_side_15" type="mesh" euler="0 0 2.6218" mesh="bowl" rgba="1 1 1 1" />
            <geom name="bowl_side_16" type="mesh" euler="0 0 2.7925" mesh="bowl" rgba="1 1 1 1" />
            <geom name="bowl_side_17" type="mesh" euler="0 0 2.9671" mesh="bowl" rgba="1 1 1 1" />
            <geom name="bowl_side_18" type="mesh" euler="0 0 3.1416" mesh="bowl" rgba="1 1 1 1" />
            <geom name="bowl_side_19" type="mesh" euler="0 0 3.3161" mesh="bowl" rgba="1 1 1 1" />
            <geom name="bowl_side_20" type="mesh" euler="0 0 3.4907" mesh="bowl" rgba="1 1 1 1" />
            <geom name="bowl_side_21" type="mesh" euler="0 0 3.6652" mesh="bowl" rgba="1 1 1 1" />
            <geom name="bowl_side_22" type="mesh" euler="0 0 3.8397" mesh="bowl" rgba="1 1 1 1" />
            <geom name="bowl_side_23" type="mesh" euler="0 0 4.0143" mesh="bowl" rgba="1 1 1 1" />
            <geom name="bowl_side_24" type="mesh" euler="0 0 4.1888" mesh="bowl" rgba="1 1 1 1" />
            <geom name="bowl_side_25" type="mesh" euler="0 0 4.3633" mesh="bowl" rgba="1 1 1 1" />
            <geom name="bowl_side_26" type="mesh" euler="0 0 4.5379" mesh="bowl" rgba="1 1 1 1" />
            <geom name="bowl_side_27" type="mesh" euler="0 0 4.7124" mesh="bowl" rgba="1 1 1 1" />
            <geom name="bowl_side_28" type="mesh" euler="0 0 4.8869" mesh="bowl" rgba="1 1 1 1" />
            <geom name="bowl_side_29" type="mesh" euler="0 0 5.0615" mesh="bowl" rgba="1 1 1 1" />
            <geom name="bowl_side_30" type="mesh" euler="0 0 5.2360" mesh="bowl" rgba="1 1 1 1" />
            <geom name="bowl_side_31" type="mesh" euler="0 0 5.4105" mesh="bowl" rgba="1 1 1 1" />
            <geom name="bowl_side_32" type="mesh" euler="0 0 5.5851" mesh="bowl" rgba="1 1 1 1" />
            <geom name="bowl_side_33" type="mesh" euler="0 0 5.7596" mesh="bowl" rgba="1 1 1 1" />
            <geom name="bowl_side_34" type="mesh" euler="0 0 5.9341" mesh="bowl" rgba="1 1 1 1" />
            <geom name="bowl_side_35" type="mesh" euler="0 0 6.1087" mesh="bowl" rgba="1 1 1 1" />
            <geom name="bowl_side_36" type="mesh" euler="0 0 6.2832" mesh="bowl" rgba="1 1 1 1" />
        </body>
    </worldbody>

    <contact>
        <exclude body1="world" body2="panda_1_link1" />
        <exclude body1="world" body2="panda_1_link2" />
        <exclude body1="world" body2="panda_1_link3" />
        <exclude body1="world" body2="panda_1_link4" />
        <exclude body1="world" body2="panda_1_link5" />
        <exclude body1="world" body2="panda_1_link6" />
        <exclude body1="world" body2="panda_1_link7" />

        <exclude body1="panda_1_link1" body2="panda_1_link2" />
        <exclude body1="panda_1_link1" body2="panda_1_link3" />
        <exclude body1="panda_1_link1" body2="panda_1_link3" />
        <exclude body1="panda_1_link1" body2="panda_1_link4" />
        <exclude body1="panda_1_link1" body2="panda_1_link5" />
        <exclude body1="panda_1_link1" body2="panda_1_link6" />
        <exclude body1="panda_1_link1" body2="panda_1_link7" />

        <exclude body1="panda_1_link2" body2="panda_1_link3" />
        <exclude body1="panda_1_link2" body2="panda_1_link4" />
        <exclude body1="panda_1_link2" body2="panda_1_link5" />
        <exclude body1="panda_1_link2" body2="panda_1_link6" />
        <exclude body1="panda_1_link2" body2="panda_1_link7" />

        <exclude body1="panda_1_link3" body2="panda_1_link4" />
        <exclude body1="panda_1_link3" body2="panda_1_link5" />
        <exclude body1="panda_1_link3" body2="panda_1_link6" />
        <exclude body1="panda_1_link3" body2="panda_1_link7" />

        <exclude body1="panda_1_link4" body2="panda_1_link5" />
        <exclude body1="panda_1_link4" body2="panda_1_link6" />
        <exclude body1="panda_1_link4" body2="panda_1_link7" />

        <exclude body1="panda_1_link5" body2="panda_1_link6" />
        <exclude body1="panda_1_link5" body2="panda_1_link7" />

        <exclude body1="panda_1_link6" body2="panda_1_link7" />

        <exclude body1="world" body2="panda_2_link1" />
        <exclude body1="world" body2="panda_2_link2" />
        <exclude body1="world" body2="panda_2_link3" />
        <exclude body1="world" body2="panda_2_link4" />
        <exclude body1="world" body2="panda_2_link5" />
        <exclude body1="world" body2="panda_2_link6" />
        <exclude body1="world" body2="panda_2_link7" />

        <exclude body1="panda_2_link1" body2="panda_2_link2" />
        <exclude body1="panda_2_link1" body2="panda_2_link3" />
        <exclude body1="panda_2_link1" body2="panda_2_link3" />
        <exclude body1="panda_2_link1" body2="panda_2_link4" />
        <exclude body1="panda_2_link1" body2="panda_2_link5" />
        <exclude body1="panda_2_link1" body2="panda_2_link6" />
        <exclude body1="panda_2_link1" body2="panda_2_link7" />

        <exclude body1="panda_2_link2" body2="panda_2_link3" />
        <exclude body1="panda_2_link2" body2="panda_2_link4" />
        <exclude body1="panda_2_link2" body2="panda_2_link5" />
        <exclude body1="panda_2_link2" body2="panda_2_link6" />
        <exclude body1="panda_2_link2" body2="panda_2_link7" />

        <exclude body1="panda_2_link3" body2="panda_2_link4" />
        <exclude body1="panda_2_link3" body2="panda_2_link5" />
        <exclude body1="panda_2_link3" body2="panda_2_link6" />
        <exclude body1="panda_2_link3" body2="panda_2_link7" />

        <exclude body1="panda_2_link4" body2="panda_2_link5" />
        <exclude body1="panda_2_link4" body2="panda_2_link6" />
        <exclude body1="panda_2_link4" body2="panda_2_link7" />

        <exclude body1="panda_2_link5" body2="panda_2_link6" />
        <exclude body1="panda_2_link5" body2="panda_2_link7" />

        <exclude body1="panda_2_link6" body2="panda_2_link7" />
    </contact>

</mujoco>