<?xml version="1.0" ?>
<!-- =================================================================================== -->
<!-- |    This document was autogenerated by xacro from /home/giang/Workspace/mujoco_ws/src/mujoco_robots/mir_system/mir_system_description/mir_system_description/urdf/mir_system.xacro | -->
<!-- |    EDITING THIS FILE BY HAND IS NOT RECOMMENDED                                 | -->
<!-- =================================================================================== -->
<robot name="mir_system">
  <joint name="camera_joint" type="fixed">
    <origin rpy="0 0 1.57" xyz="0.0 0.22 0.4"/>
    <parent link="base_link"/>
    <child link="camera_link"/>
  </joint>
  <link name="camera_link">
    <collision>
      <origin rpy="0 0 0" xyz="0.005 0.021 0.013"/>
      <geometry>
        <box size="0.015 0.030 0.027"/>
      </geometry>
    </collision>
  </link>
  <joint name="camera_rgb_joint" type="fixed">
    <origin rpy="0 0 0" xyz="0.003 0.021 0.009"/>
    <parent link="camera_link"/>
    <child link="camera_rgb_frame"/>
  </joint>
  <link name="camera_rgb_frame"/>
  <joint name="camera_rgb_optical_joint" type="fixed">
    <origin rpy="-1.57 0 -1.57" xyz="0 0 0"/>
    <parent link="camera_rgb_frame"/>
    <child link="camera_rgb_optical_frame"/>
  </joint>
  <link name="camera_rgb_optical_frame"/>
  <gazebo reference="camera_rgb_frame">
    <sensor name="Simple Camera" type="camera">
      <always_on>true</always_on>
      <visualize>true</visualize>
      <camera>
        <horizontal_fov>1.085595</horizontal_fov>
        <image>
          <width>640</width>
          <height>480</height>
          <format>R8G8B8</format>
        </image>
        <clip>
          <near>0.03</near>
          <far>100</far>
        </clip>
      </camera>
      <plugin filename="libgazebo_ros_camera.so" name="camera_controller">
        <alwaysOn>true</alwaysOn>
        <!-- modified (updateRate) to reduce computation effort, default : 30.0 -->
        <updateRate>30.0</updateRate>
        <cameraName>camera</cameraName>
        <frameName>camera_rgb_optical_frame</frameName>
        <imageTopicName>image</imageTopicName>
        <cameraInfoTopicName>camera_info</cameraInfoTopicName>
        <hackBaseline>0.07</hackBaseline>
        <distortionK1>0.0</distortionK1>
        <distortionK2>0.0</distortionK2>
        <distortionK3>0.0</distortionK3>
        <distortionT1>0.0</distortionT1>
        <distortionT2>0.0</distortionT2>
      </plugin>
    </sensor>
  </gazebo>
  <link name="base_footprint"/>
  <joint name="base_joint" type="fixed">
    <parent link="base_footprint"/>
    <child link="base_link"/>
    <origin rpy="0 0 0" xyz="0 0 0"/>
  </joint>
  <link name="base_link">
    <inertial>
      <mass value="58.0"/>
      <origin rpy="0 0 0" xyz="0.037646 0 0.20"/>
      <inertia ixx="2.0609325089599997" ixy="0.0" ixz="0.0" iyy="4.34999826" iyz="0.0" izz="5.54093111696"/>
    </inertial>
    <visual>
      <origin rpy="0 0 0" xyz="0.037646 0 0"/>
      <geometry>
        <mesh filename="package://mir_description/meshes/visual/mir_100_base.stl"/>
      </geometry>
      <material name="white">
        <color rgba="1 1 1 1"/>
      </material>
    </visual>
    <collision>
      <origin rpy="0 0 0" xyz="0.037646 0 0"/>
      <geometry>
        <mesh filename="package://mir_description/meshes/collision/mir_100_base.stl"/>
      </geometry>
    </collision>
  </link>
  <gazebo reference="base_link">
    <material>Gazebo/White</material>
  </gazebo>
  <!-- IMU -->
  <joint name="base_link_to_imu_joint" type="fixed">
    <parent link="base_link"/>
    <child link="imu_link"/>
    <origin rpy="0 0 0" xyz="0.0 0.0 0.25"/>
    <!-- same as real MiR -->
  </joint>
  <link name="imu_link"/>
  <gazebo reference="imu_link">
    <gravity>true</gravity>
    <sensor name="imu_sensor" type="imu">
      <always_on>true</always_on>
      <update_rate>100</update_rate>
      <!-- this is not the publish rate -->
      <visualize>true</visualize>
      <topic>__default_topic__</topic>
      <plugin filename="libgazebo_ros_imu_sensor.so" name="imu_plugin">
        <topicName>imu_data</topicName>
        <bodyName>imu_link</bodyName>
        <updateRateHZ>50.0</updateRateHZ>
        <!-- this is the publish rate -->
        <gaussianNoise>2.8900000000000004e-08</gaussianNoise>
        <xyzOffset>0 0 0</xyzOffset>
        <rpyOffset>0 0 0</rpyOffset>
        <frameName>imu_frame</frameName>
        <!-- from real MiR -->
      </plugin>
      <pose>0 0 0 0 0 0</pose>
    </sensor>
  </gazebo>
  <!-- Create an alias for imu_link. This is necessary because the real MiR's
         TF has imu_link, but the imu_data topic is published in the imu_frame
         frame. -->
  <joint name="imu_link_to_imu_frame_joint" type="fixed">
    <parent link="imu_link"/>
    <child link="imu_frame"/>
    <origin rpy="0 0 0" xyz="0 0 0"/>
  </joint>
  <link name="imu_frame"/>
  <!-- Laser scanners -->
  <joint name="base_link_to_front_laser_joint" type="fixed">
    <parent link="base_link"/>
    <child link="front_laser_link"/>
    <origin rpy="3.141592653589793 0.0 0.7853981633974483" xyz="0.4288 0.2358 0.1914"/>
    <!-- from visually matching up the meshes of the MiR and the laser scanner -->
  </joint>
  <link name="front_laser_link">
    <visual>
      <origin rpy="0 0 0" xyz="0.0 0.0 0.0"/>
      <geometry>
        <mesh filename="package://mir_description/meshes/visual/sick_lms-100.stl"/>
      </geometry>
      <!-- <xacro:insert_block name="material_yellow" /> -->
      <material name="black">
        <color rgba="0.1 0.1 0.1 1"/>
      </material>
    </visual>
    <collision>
      <origin rpy="0 0 0" xyz="0.0 0.0 0.0"/>
      <geometry>
        <mesh filename="package://mir_description/meshes/visual/sick_lms-100.stl"/>
      </geometry>
    </collision>
    <inertial>
      <mass value="2.0"/>
      <origin xyz="0 0 0"/>
      <inertia ixx="0.009708329449999999" ixy="0.0" ixz="0.0" iyy="0.0097601627626" iyz="0.0" izz="0.0080601634426"/>
    </inertial>
  </link>
  <gazebo reference="front_laser_link">
    <!-- <material value="Gazebo/Yellow" /> -->
    <material value="Gazebo/FlatBlack"/>
    <sensor name="front_laser_link" type="ray">
      <pose>0 0 0 0 0 0</pose>
      <visualize>false</visualize>
      <update_rate>12.5</update_rate>
      <ray>
        <scan>
          <horizontal>
            <samples>541</samples>
            <resolution>1</resolution>
            <!-- has to be 1; actual resolution will be computed from number of samples + min_angle/max_angle -->
            <min_angle>-2.35619449615</min_angle>
            <max_angle>2.35619449615</max_angle>
          </horizontal>
        </scan>
        <range>
          <min>0.05</min>
          <max>29.0</max>
          <resolution>0.01</resolution>
        </range>
        <noise>
          <type>gaussian</type>
          <!-- Noise parameters based on published spec for S300 achieving
                 "+-29mm" accuracy at range < 3m (~0.01 of the range) at
                 1 sigma. -->
          <mean>0.0</mean>
          <stddev>0.01</stddev>
        </noise>
      </ray>
      <plugin filename="libgazebo_ros_laser.so" name="gazebo_ros_front_laser_link_controller">
        <frameName>front_laser_link</frameName>
        <topicName>f_scan</topicName>
      </plugin>
    </sensor>
  </gazebo>
  <joint name="base_link_to_back_laser_joint" type="fixed">
    <parent link="base_link"/>
    <child link="back_laser_link"/>
    <origin rpy="3.141592653589793 0.0 -2.356194490192345" xyz="-0.3548 -0.2352 0.1914"/>
    <!-- from visually matching up the meshes of the MiR and the laser scanner -->
  </joint>
  <link name="back_laser_link">
    <visual>
      <origin rpy="0 0 0" xyz="0.0 0.0 0.0"/>
      <geometry>
        <mesh filename="package://mir_description/meshes/visual/sick_lms-100.stl"/>
      </geometry>
      <!-- <xacro:insert_block name="material_yellow" /> -->
      <material name="black">
        <color rgba="0.1 0.1 0.1 1"/>
      </material>
    </visual>
    <collision>
      <origin rpy="0 0 0" xyz="0.0 0.0 0.0"/>
      <geometry>
        <mesh filename="package://mir_description/meshes/visual/sick_lms-100.stl"/>
      </geometry>
    </collision>
    <inertial>
      <mass value="2.0"/>
      <origin xyz="0 0 0"/>
      <inertia ixx="0.009708329449999999" ixy="0.0" ixz="0.0" iyy="0.0097601627626" iyz="0.0" izz="0.0080601634426"/>
    </inertial>
  </link>
  <gazebo reference="back_laser_link">
    <!-- <material value="Gazebo/Yellow" /> -->
    <material value="Gazebo/FlatBlack"/>
    <sensor name="back_laser_link" type="ray">
      <pose>0 0 0 0 0 0</pose>
      <visualize>false</visualize>
      <update_rate>12.5</update_rate>
      <ray>
        <scan>
          <horizontal>
            <samples>541</samples>
            <resolution>1</resolution>
            <!-- has to be 1; actual resolution will be computed from number of samples + min_angle/max_angle -->
            <min_angle>-2.35619449615</min_angle>
            <max_angle>2.35619449615</max_angle>
          </horizontal>
        </scan>
        <range>
          <min>0.05</min>
          <max>29.0</max>
          <resolution>0.01</resolution>
        </range>
        <noise>
          <type>gaussian</type>
          <!-- Noise parameters based on published spec for S300 achieving
                 "+-29mm" accuracy at range < 3m (~0.01 of the range) at
                 1 sigma. -->
          <mean>0.0</mean>
          <stddev>0.01</stddev>
        </noise>
      </ray>
      <plugin filename="libgazebo_ros_laser.so" name="gazebo_ros_back_laser_link_controller">
        <frameName>back_laser_link</frameName>
        <topicName>b_scan</topicName>
      </plugin>
    </sensor>
  </gazebo>
  <!-- Ultrasound sensors -->
  <joint name="us_1_joint" type="fixed">
    <!-- right ultrasound -->
    <parent link="base_link"/>
    <child link="us_1_frame"/>
    <origin rpy="0 0 0" xyz="0.45 -0.12 0.16 "/>
    <!-- from visually matching to the mesh of the MiR -->
  </joint>
  <link name="us_1_frame"/>
  <joint name="us_2_joint" type="fixed">
    <!-- left ultrasound -->
    <parent link="base_link"/>
    <child link="us_2_frame"/>
    <origin rpy="0 0 0" xyz="0.45 0.12 0.16 "/>
    <!-- from visually matching to the mesh of the MiR -->
  </joint>
  <link name="us_2_frame"/>
  <joint name="left_wheel_joint" type="continuous">
    <origin rpy="0 0 0" xyz="0.0 0.222604 0.0625"/>
    <parent link="base_link"/>
    <child link="left_wheel_link"/>
    <axis xyz="0 1 0"/>
    <limit effort="100" velocity="20.0"/>
  </joint>
  <link name="left_wheel_link">
    <inertial>
      <mass value="1.0"/>
      <origin rpy="1.5707963267948966 0 0" xyz="0 0 0"/>
      <inertia ixx="0.001061895408575" ixy="0.0" ixz="0.0" iyy="0.001061895408575" iyz="0.0" izz="0.001953125"/>
    </inertial>
    <visual>
      <origin rpy="0 0 0" xyz="0 0 0"/>
      <geometry>
        <mesh filename="package://mir_description/meshes/visual/wheel.stl"/>
      </geometry>
      <material name="dark_grey">
        <color rgba="0.3 0.3 0.3 1"/>
      </material>
    </visual>
    <collision>
      <origin rpy="0 0 0" xyz="0 0 0"/>
      <geometry>
        <mesh filename="package://mir_description/meshes/visual/wheel.stl"/>
      </geometry>
    </collision>
  </link>
  <gazebo reference="left_wheel_link">
    <material>Gazebo/DarkGrey</material>
  </gazebo>
  <joint name="right_wheel_joint" type="continuous">
    <origin rpy="0 0 0" xyz="0.0 -0.222604 0.0625"/>
    <parent link="base_link"/>
    <child link="right_wheel_link"/>
    <axis xyz="0 1 0"/>
    <limit effort="100" velocity="20.0"/>
  </joint>
  <link name="right_wheel_link">
    <inertial>
      <mass value="1.0"/>
      <origin rpy="1.5707963267948966 0 0" xyz="0 0 0"/>
      <inertia ixx="0.001061895408575" ixy="0.0" ixz="0.0" iyy="0.001061895408575" iyz="0.0" izz="0.001953125"/>
    </inertial>
    <visual>
      <origin rpy="0 0 0" xyz="0 0 0"/>
      <geometry>
        <mesh filename="package://mir_description/meshes/visual/wheel.stl"/>
      </geometry>
      <material name="dark_grey">
        <color rgba="0.3 0.3 0.3 1"/>
      </material>
    </visual>
    <collision>
      <origin rpy="0 0 0" xyz="0 0 0"/>
      <geometry>
        <mesh filename="package://mir_description/meshes/visual/wheel.stl"/>
      </geometry>
    </collision>
  </link>
  <gazebo reference="right_wheel_link">
    <material>Gazebo/DarkGrey</material>
  </gazebo>
  <!-- caster hub -->
  <joint name="fl_caster_rotation_joint" type="continuous">
    <origin rpy="0 0 0" xyz="0.341346 0.203 0.1565"/>
    <parent link="base_link"/>
    <child link="fl_caster_rotation_link"/>
    <axis xyz="0 0 1"/>
    <dynamics damping="0.01" friction="0.0"/>
  </joint>
  <link name="fl_caster_rotation_link">
    <inertial>
      <!-- <origin xyz="0 0 -0.042500000044" rpy="${0.5 * pi} ${24 * deg_to_rad} ${1.5 * pi}" /> -->
      <origin rpy="0.41887903200000004 0 1.5707963267948966 " xyz="0 0 -0.042500000044"/>
      <mass value="0.3097539019"/>
      <inertia ixx="0.0005844517978" ixy="0" ixz="0" iyy="0.00052872551237" iyz="0" izz="0.00017923555074"/>
    </inertial>
    <visual>
      <origin rpy="0 0 0" xyz="0 0 0"/>
      <geometry>
        <mesh filename="package://mir_description/meshes/visual/caster_wheel_base.stl"/>
      </geometry>
      <material name="silver">
        <color rgba="0.79 0.82 0.93 1"/>
      </material>
    </visual>
    <collision>
      <origin rpy="0 0 0" xyz="0 0 0"/>
      <geometry>
        <mesh filename="package://mir_description/meshes/collision/caster_wheel_base.stl"/>
      </geometry>
    </collision>
  </link>
  <gazebo reference="fl_caster_rotation_link">
    <material>Gazebo/Grey</material>
  </gazebo>
  <!-- caster wheel -->
  <joint name="fl_caster_wheel_joint" type="continuous">
    <origin rpy="0 0 0" xyz="-0.0382 0 -0.094"/>
    <parent link="fl_caster_rotation_link"/>
    <child link="fl_caster_wheel_link"/>
    <axis xyz="0 1 0"/>
  </joint>
  <link name="fl_caster_wheel_link">
    <inertial>
      <mass value="1.0"/>
      <origin rpy="1.5707963267948966 0 0" xyz="0 0 0"/>
      <inertia ixx="0.001061895408575" ixy="0.0" ixz="0.0" iyy="0.001061895408575" iyz="0.0" izz="0.001953125"/>
    </inertial>
    <visual>
      <origin rpy="0 0 0" xyz="0 0 0"/>
      <geometry>
        <mesh filename="package://mir_description/meshes/visual/wheel.stl"/>
      </geometry>
      <material name="dark_grey">
        <color rgba="0.3 0.3 0.3 1"/>
      </material>
    </visual>
    <collision>
      <origin rpy="0 0 0" xyz="0 0 0"/>
      <geometry>
        <mesh filename="package://mir_description/meshes/visual/wheel.stl"/>
      </geometry>
    </collision>
  </link>
  <gazebo reference="fl_caster_wheel_link">
    <material>Gazebo/DarkGrey</material>
  </gazebo>
  <!-- caster hub -->
  <joint name="fr_caster_rotation_joint" type="continuous">
    <origin rpy="0 0 0" xyz="0.341346 -0.203 0.1565"/>
    <parent link="base_link"/>
    <child link="fr_caster_rotation_link"/>
    <axis xyz="0 0 1"/>
    <dynamics damping="0.01" friction="0.0"/>
  </joint>
  <link name="fr_caster_rotation_link">
    <inertial>
      <!-- <origin xyz="0 0 -0.042500000044" rpy="${0.5 * pi} ${24 * deg_to_rad} ${1.5 * pi}" /> -->
      <origin rpy="0.41887903200000004 0 1.5707963267948966 " xyz="0 0 -0.042500000044"/>
      <mass value="0.3097539019"/>
      <inertia ixx="0.0005844517978" ixy="0" ixz="0" iyy="0.00052872551237" iyz="0" izz="0.00017923555074"/>
    </inertial>
    <visual>
      <origin rpy="0 0 0" xyz="0 0 0"/>
      <geometry>
        <mesh filename="package://mir_description/meshes/visual/caster_wheel_base.stl"/>
      </geometry>
      <material name="silver">
        <color rgba="0.79 0.82 0.93 1"/>
      </material>
    </visual>
    <collision>
      <origin rpy="0 0 0" xyz="0 0 0"/>
      <geometry>
        <mesh filename="package://mir_description/meshes/collision/caster_wheel_base.stl"/>
      </geometry>
    </collision>
  </link>
  <gazebo reference="fr_caster_rotation_link">
    <material>Gazebo/Grey</material>
  </gazebo>
  <!-- caster wheel -->
  <joint name="fr_caster_wheel_joint" type="continuous">
    <origin rpy="0 0 0" xyz="-0.0382 0 -0.094"/>
    <parent link="fr_caster_rotation_link"/>
    <child link="fr_caster_wheel_link"/>
    <axis xyz="0 1 0"/>
  </joint>
  <link name="fr_caster_wheel_link">
    <inertial>
      <mass value="1.0"/>
      <origin rpy="1.5707963267948966 0 0" xyz="0 0 0"/>
      <inertia ixx="0.001061895408575" ixy="0.0" ixz="0.0" iyy="0.001061895408575" iyz="0.0" izz="0.001953125"/>
    </inertial>
    <visual>
      <origin rpy="0 0 0" xyz="0 0 0"/>
      <geometry>
        <mesh filename="package://mir_description/meshes/visual/wheel.stl"/>
      </geometry>
      <material name="dark_grey">
        <color rgba="0.3 0.3 0.3 1"/>
      </material>
    </visual>
    <collision>
      <origin rpy="0 0 0" xyz="0 0 0"/>
      <geometry>
        <mesh filename="package://mir_description/meshes/visual/wheel.stl"/>
      </geometry>
    </collision>
  </link>
  <gazebo reference="fr_caster_wheel_link">
    <material>Gazebo/DarkGrey</material>
  </gazebo>
  <!-- caster hub -->
  <joint name="bl_caster_rotation_joint" type="continuous">
    <origin rpy="0 0 0" xyz="-0.270154 0.203 0.1565"/>
    <parent link="base_link"/>
    <child link="bl_caster_rotation_link"/>
    <axis xyz="0 0 1"/>
    <dynamics damping="0.01" friction="0.0"/>
  </joint>
  <link name="bl_caster_rotation_link">
    <inertial>
      <!-- <origin xyz="0 0 -0.042500000044" rpy="${0.5 * pi} ${24 * deg_to_rad} ${1.5 * pi}" /> -->
      <origin rpy="0.41887903200000004 0 1.5707963267948966 " xyz="0 0 -0.042500000044"/>
      <mass value="0.3097539019"/>
      <inertia ixx="0.0005844517978" ixy="0" ixz="0" iyy="0.00052872551237" iyz="0" izz="0.00017923555074"/>
    </inertial>
    <visual>
      <origin rpy="0 0 0" xyz="0 0 0"/>
      <geometry>
        <mesh filename="package://mir_description/meshes/visual/caster_wheel_base.stl"/>
      </geometry>
      <material name="silver">
        <color rgba="0.79 0.82 0.93 1"/>
      </material>
    </visual>
    <collision>
      <origin rpy="0 0 0" xyz="0 0 0"/>
      <geometry>
        <mesh filename="package://mir_description/meshes/collision/caster_wheel_base.stl"/>
      </geometry>
    </collision>
  </link>
  <gazebo reference="bl_caster_rotation_link">
    <material>Gazebo/Grey</material>
  </gazebo>
  <!-- caster wheel -->
  <joint name="bl_caster_wheel_joint" type="continuous">
    <origin rpy="0 0 0" xyz="-0.0382 0 -0.094"/>
    <parent link="bl_caster_rotation_link"/>
    <child link="bl_caster_wheel_link"/>
    <axis xyz="0 1 0"/>
  </joint>
  <link name="bl_caster_wheel_link">
    <inertial>
      <mass value="1.0"/>
      <origin rpy="1.5707963267948966 0 0" xyz="0 0 0"/>
      <inertia ixx="0.001061895408575" ixy="0.0" ixz="0.0" iyy="0.001061895408575" iyz="0.0" izz="0.001953125"/>
    </inertial>
    <visual>
      <origin rpy="0 0 0" xyz="0 0 0"/>
      <geometry>
        <mesh filename="package://mir_description/meshes/visual/wheel.stl"/>
      </geometry>
      <material name="dark_grey">
        <color rgba="0.3 0.3 0.3 1"/>
      </material>
    </visual>
    <collision>
      <origin rpy="0 0 0" xyz="0 0 0"/>
      <geometry>
        <mesh filename="package://mir_description/meshes/visual/wheel.stl"/>
      </geometry>
    </collision>
  </link>
  <gazebo reference="bl_caster_wheel_link">
    <material>Gazebo/DarkGrey</material>
  </gazebo>
  <!-- caster hub -->
  <joint name="br_caster_rotation_joint" type="continuous">
    <origin rpy="0 0 0" xyz="-0.270154 -0.203 0.1565"/>
    <parent link="base_link"/>
    <child link="br_caster_rotation_link"/>
    <axis xyz="0 0 1"/>
    <dynamics damping="0.01" friction="0.0"/>
  </joint>
  <link name="br_caster_rotation_link">
    <inertial>
      <!-- <origin xyz="0 0 -0.042500000044" rpy="${0.5 * pi} ${24 * deg_to_rad} ${1.5 * pi}" /> -->
      <origin rpy="0.41887903200000004 0 1.5707963267948966 " xyz="0 0 -0.042500000044"/>
      <mass value="0.3097539019"/>
      <inertia ixx="0.0005844517978" ixy="0" ixz="0" iyy="0.00052872551237" iyz="0" izz="0.00017923555074"/>
    </inertial>
    <visual>
      <origin rpy="0 0 0" xyz="0 0 0"/>
      <geometry>
        <mesh filename="package://mir_description/meshes/visual/caster_wheel_base.stl"/>
      </geometry>
      <material name="silver">
        <color rgba="0.79 0.82 0.93 1"/>
      </material>
    </visual>
    <collision>
      <origin rpy="0 0 0" xyz="0 0 0"/>
      <geometry>
        <mesh filename="package://mir_description/meshes/collision/caster_wheel_base.stl"/>
      </geometry>
    </collision>
  </link>
  <gazebo reference="br_caster_rotation_link">
    <material>Gazebo/Grey</material>
  </gazebo>
  <!-- caster wheel -->
  <joint name="br_caster_wheel_joint" type="continuous">
    <origin rpy="0 0 0" xyz="-0.0382 0 -0.094"/>
    <parent link="br_caster_rotation_link"/>
    <child link="br_caster_wheel_link"/>
    <axis xyz="0 1 0"/>
  </joint>
  <link name="br_caster_wheel_link">
    <inertial>
      <mass value="1.0"/>
      <origin rpy="1.5707963267948966 0 0" xyz="0 0 0"/>
      <inertia ixx="0.001061895408575" ixy="0.0" ixz="0.0" iyy="0.001061895408575" iyz="0.0" izz="0.001953125"/>
    </inertial>
    <visual>
      <origin rpy="0 0 0" xyz="0 0 0"/>
      <geometry>
        <mesh filename="package://mir_description/meshes/visual/wheel.stl"/>
      </geometry>
      <material name="dark_grey">
        <color rgba="0.3 0.3 0.3 1"/>
      </material>
    </visual>
    <collision>
      <origin rpy="0 0 0" xyz="0 0 0"/>
      <geometry>
        <mesh filename="package://mir_description/meshes/visual/wheel.stl"/>
      </geometry>
    </collision>
  </link>
  <gazebo reference="br_caster_wheel_link">
    <material>Gazebo/DarkGrey</material>
  </gazebo>
  <joint name="base_link_surface_joint" type="fixed">
    <origin rpy="0 0 0" xyz="0.037646 0 0.352"/>
    <parent link="base_link"/>
    <child link="surface"/>
    <axis xyz="0 0 1"/>
  </joint>
  <link name="surface"/>
  <transmission name="left_wheel_trans">
    <type>transmission_interface/SimpleTransmission</type>
    <joint name="left_wheel_joint">
      <hardwareInterface>hardware_interface/VelocityJointInterface</hardwareInterface>
    </joint>
    <actuator name="left_wheel_motor">
      <hardwareInterface>hardware_interface/VelocityJointInterface</hardwareInterface>
      <mechanicalReduction>1</mechanicalReduction>
    </actuator>
  </transmission>
  <transmission name="right_wheel_trans">
    <type>transmission_interface/SimpleTransmission</type>
    <joint name="right_wheel_joint">
      <hardwareInterface>hardware_interface/VelocityJointInterface</hardwareInterface>
    </joint>
    <actuator name="right_wheel_motor">
      <hardwareInterface>hardware_interface/VelocityJointInterface</hardwareInterface>
      <mechanicalReduction>1</mechanicalReduction>
    </actuator>
  </transmission>
  <gazebo reference="left_wheel_link">
    <mu1 value="200"/>
    <mu2 value="200"/>
    <kp value="10000000.0"/>
    <kd value="1.0"/>
    <minDepth>0.01</minDepth>
  </gazebo>
  <gazebo reference="right_wheel_link">
    <mu1 value="200"/>
    <mu2 value="200"/>
    <kp value="10000000.0"/>
    <kd value="1.0"/>
    <minDepth>0.01</minDepth>
  </gazebo>
  <gazebo reference="fl_caster_wheel_link">
    <mu1 value="1"/>
    <mu2 value="1"/>
    <kp value="10000000.0"/>
    <kd value="1.0"/>
    <minDepth>0.01</minDepth>
  </gazebo>
  <gazebo reference="fr_caster_wheel_link">
    <mu1 value="1"/>
    <mu2 value="1"/>
    <kp value="10000000.0"/>
    <kd value="1.0"/>
    <minDepth>0.01</minDepth>
  </gazebo>
  <gazebo reference="bl_caster_wheel_link">
    <mu1 value="1"/>
    <mu2 value="1"/>
    <kp value="10000000.0"/>
    <kd value="1.0"/>
    <minDepth>0.01</minDepth>
  </gazebo>
  <gazebo reference="br_caster_wheel_link">
    <mu1 value="1"/>
    <mu2 value="1"/>
    <kp value="10000000.0"/>
    <kd value="1.0"/>
    <minDepth>0.01</minDepth>
  </gazebo>
  <gazebo>
    <plugin filename="libgazebo_ros_p3d.so" name="p3d_base_controller">
      <alwaysOn>true</alwaysOn>
      <updateRate>50.0</updateRate>
      <bodyName>base_footprint</bodyName>
      <topicName>base_pose_ground_truth</topicName>
      <gaussianNoise>0.01</gaussianNoise>
      <frameName>map</frameName>
      <xyzOffsets>0 0 0</xyzOffsets>
      <rpyOffsets>0 0 0</rpyOffsets>
    </plugin>
  </gazebo>
  <gazebo>
    <plugin filename="libgazebo_ros_control.so" name="gazebo_ros_control">
      <controlPeriod>0.001</controlPeriod>
      <legacyModeNS>false</legacyModeNS>
    </plugin>
  </gazebo>
  <!-- instead of the controller_plugin_gazebo, you can use the diffdrive controller like this:
    <xacro:diff_controller_plugin_gazebo prefix=""
      left_wheel_joint="left_wheel_joint"
      right_wheel_joint="right_wheel_joint"
      wheel_separation="${2*mir_100_act_wheel_dy}"
      wheel_radius="${mir_100_act_wheel_radius}"/>
  -->
  <link name="carriage">
    <inertial>
      <origin rpy="0 0 0" xyz="-0.0086191 0.0047125 0.0010376"/>
      <mass value="8.35"/>
      <inertia ixx="0.0102801" ixy="0.0005188" ixz="-0.0035496" iyy="0.0089798" iyz="-7.18e-05" izz="0.0049397"/>
    </inertial>
    <visual name="visual_carriage">
      <origin rpy="-1.5707964 0 0" xyz="-0.0345127 -0.0820147 3.1e-06"/>
      <geometry>
        <mesh filename="package://mir100_hook_description/meshes/stl/carriage.stl" scale="1.0 1.0 1.0"/>
      </geometry>
      <material name="carriage"/>
    </visual>
    <visual name="visual_container_crawler">
      <origin rpy="-1.5707964 0 0" xyz="-0.2067981 -0.2896011 3e-06"/>
      <geometry>
        <mesh filename="package://mir100_hook_description/meshes/stl/container_crawler.stl" scale="1.0 1.0 1.0"/>
      </geometry>
      <material name="crawler"/>
    </visual>
    <visual name="visual_container_lock">
      <origin rpy="-1.5707964 0 0" xyz="-0.1818805 -0.180375 -0.000269"/>
      <geometry>
        <mesh filename="package://mir100_hook_description/meshes/stl/container_lock.stl" scale="1.0 1.0 1.0"/>
      </geometry>
      <material name="lock"/>
    </visual>
    <visual name="visual_fork_base">
      <origin rpy="-1.5707964 0 0" xyz="-0.1448901 -0.2715 3.2e-06"/>
      <geometry>
        <mesh filename="package://mir100_hook_description/meshes/stl/fork_base.stl" scale="1.0 1.0 1.0"/>
      </geometry>
      <material name="fork"/>
    </visual>
    <visual name="visual_tilt_actuator_cylinder">
      <origin rpy="-1.5707964 0 0" xyz="-0.1676646 -0.1944744 0.0017018"/>
      <geometry>
        <mesh filename="package://mir100_hook_description/meshes/stl/Part__Feature079.stl" scale="1.0000001 1.0 1.0000001"/>
      </geometry>
      <material name="actuator_cylinder"/>
    </visual>
    <visual name="visual_tilt_actuator_motor">
      <origin rpy="-1.5707964 0 0" xyz="-0.1158853 -0.0953563 0.0017019"/>
      <geometry>
        <mesh filename="package://mir100_hook_description/meshes/stl/Part__Feature078.stl" scale="1.0000001 1.0 1.0000001"/>
      </geometry>
      <material name="actuator_motor"/>
    </visual>
    <visual name="visual_tilt_arm_lower">
      <origin rpy="-1.5707964 0 0" xyz="-0.13785 -0.3212596 3e-06"/>
      <geometry>
        <mesh filename="package://mir100_hook_description/meshes/stl/tilt_arm_lower.stl" scale="1.0 1.0 1.0"/>
      </geometry>
      <material name="tilt_arm_lower"/>
    </visual>
    <visual name="visual_tilt_arm_upper">
      <origin rpy="-1.5707964 0 0" xyz="-0.1404309 -0.2453349 3e-06"/>
      <geometry>
        <mesh filename="package://mir100_hook_description/meshes/stl/Part__Feature158.stl" scale="1.0 1.0 1.0"/>
      </geometry>
      <material name="tilt_arm_upper"/>
    </visual>
    <collision name="collision_carriage_1">
      <origin rpy="-1.5707964 0 -0.3490658" xyz="-0.0424136 0.089503 3.1e-06"/>
      <geometry>
        <box size="0.03052 0.13439 0.162844"/>
      </geometry>
    </collision>
    <collision name="collision_carriage_2">
      <origin rpy="-1.5707964 0 0" xyz="-0.0538089 -0.1362699 0"/>
      <geometry>
        <box size="0.0719401 0.139106 0.3969324"/>
      </geometry>
    </collision>
    <collision name="collision_carriage_4">
      <origin rpy="-1.5707964 0 0" xyz="-0.0216487 -0.2830374 3.1e-06"/>
      <geometry>
        <box size="0.00545 0.13741 0.0865109"/>
      </geometry>
    </collision>
    <collision name="collision_container_crawler_1">
      <origin rpy="-1.5707964 0 0" xyz="-0.1846113 -0.2807498 3e-06"/>
      <geometry>
        <box size="0.0243 0.272 0.03627"/>
      </geometry>
    </collision>
    <collision name="collision_container_crawler_2">
      <origin rpy="-1e-07 0 0.8045967" xyz="-0.2129726 -0.3028729 0.132826"/>
      <geometry>
        <cylinder length="0.00544" radius="0.05733"/>
      </geometry>
    </collision>
    <collision name="collision_container_crawler_3">
      <origin rpy="-1e-07 0 0.8045968" xyz="-0.212973 -0.3028729 -0.132826"/>
      <geometry>
        <cylinder length="0.00544" radius="0.05733"/>
      </geometry>
    </collision>
    <collision name="collision_container_crawler_4">
      <origin rpy="-1.5707964 0 0" xyz="-0.1921152 -0.278682 3e-06"/>
      <geometry>
        <box size="0.0027 0.05712 0.08424"/>
      </geometry>
    </collision>
    <collision name="collision_container_lock_1">
      <origin rpy="-1.5707964 0 0" xyz="-0.2414355 -0.3314246 -0.0002958"/>
      <geometry>
        <box size="0.08282 0.073393 0.033625"/>
      </geometry>
    </collision>
    <collision name="collision_container_lock_2">
      <origin rpy="-1e-07 0 -0.2478367" xyz="-0.271374 -0.3108148 -0.0002958"/>
      <geometry>
        <cylinder length="0.0055601" radius="0.0100875"/>
      </geometry>
    </collision>
    <collision name="collision_container_lock_3">
      <origin rpy="-1.5707964 0 0" xyz="-0.1819233 -0.3466128 -0.0002958"/>
      <geometry>
        <box size="0.19998 0.072281 0.0033625"/>
      </geometry>
    </collision>
    <collision name="collision_container_lock_4">
      <origin rpy="-1.5707964 0 0" xyz="-0.1067194 -0.181047 0.0360971"/>
      <geometry>
        <box size="0.03838 0.002224 0.33625"/>
      </geometry>
    </collision>
    <collision name="collision_container_lock_5">
      <origin rpy="-1.5707964 0 0" xyz="-0.106719 -0.1810469 -0.036097"/>
      <geometry>
        <box size="0.03838 0.002224 0.33625"/>
      </geometry>
    </collision>
    <collision name="collision_fork_base_1">
      <origin rpy="-1.5707964 0 0" xyz="-0.2164229 -0.3545153 3e-06"/>
      <geometry>
        <box size="0.05 0.12103 0.0034"/>
      </geometry>
    </collision>
    <collision name="collision_fork_base_2">
      <origin rpy="-1.5707964 0 0" xyz="-0.0612574 -0.3545149 0"/>
      <geometry>
        <box size="0.03 0.12103 0.0034"/>
      </geometry>
    </collision>
    <collision name="collision_fork_base_3">
      <origin rpy="-1.5707964 0 0" xyz="-0.1440597 -0.3550831 -0.053405"/>
      <geometry>
        <box size="0.194 0.01482 0.0034"/>
      </geometry>
    </collision>
    <collision name="collision_fork_base_4">
      <origin rpy="-1.5707964 0 0" xyz="-0.143986 -0.3545149 0.052922"/>
      <geometry>
        <box size="0.194 0.01482 0.0034"/>
      </geometry>
    </collision>
    <collision name="collision_fork_base_5">
      <origin rpy="-1.5707964 0 0" xyz="-0.0469099 -0.3151417 3e-06"/>
      <geometry>
        <box size="0.004 0.12103 0.0816001"/>
      </geometry>
    </collision>
    <collision name="collision_fork_base_6">
      <origin rpy="-1.5707964 0 0" xyz="-0.1453781 -0.3361342 0.0588561"/>
      <geometry>
        <box size="0.2 0.00247 0.0391"/>
      </geometry>
    </collision>
    <collision name="collision_fork_base_7">
      <origin rpy="-1.5707964 0 0" xyz="-0.145378 -0.3361339 -0.058856"/>
      <geometry>
        <box size="0.2 0.00247 0.0391"/>
      </geometry>
    </collision>
    <collision name="collision_tilt_actuator_cylinder">
      <origin rpy="-1.5707964 0 -0.3316126" xyz="-0.170188 -0.2015466 0.0017018"/>
      <geometry>
        <cylinder length="0.0686558" radius="0.0093432"/>
      </geometry>
    </collision>
    <collision name="collision_tilt_actuator_motor">
      <origin rpy="-1.5707964 0 -0.3316124" xyz="-0.1381059 -0.1018716 0.0017019"/>
      <geometry>
        <cylinder length="0.1360801" radius="0.0216029"/>
      </geometry>
    </collision>
    <collision name="collision_tilt_arm_lower">
      <origin rpy="-1.5707964 0 -0.3263766" xyz="-0.1390713 -0.3224227 3e-06"/>
      <geometry>
        <box size="0.0844065 0.056925 0.0137896"/>
      </geometry>
    </collision>
    <collision name="collision_tilt_arm_upper">
      <origin rpy="-1.5707964 0 -0.4974188" xyz="-0.1375349 -0.2483816 3e-06"/>
      <geometry>
        <box size="0.0759516 0.0368 0.0177953"/>
      </geometry>
    </collision>
  </link>
  <link name="lift_arm_lower">
    <inertial>
      <origin rpy="0 0 0" xyz="-0.2072146 0.1073697 3.3e-05"/>
      <mass value="1.0"/>
      <inertia ixx="0.0003373" ixy="-0.0006013" ixz="0" iyy="0.0014916" iyz="0" izz="0.0012083"/>
    </inertial>
    <visual name="visual_lift_arm_lower">
      <origin rpy="-1.5707964 0 0" xyz="-0.2092547 0.1067384 3.3e-05"/>
      <geometry>
        <mesh filename="package://mir100_hook_description/meshes/stl/lift_lower_arm.stl" scale="1.0 1.0 1.0"/>
      </geometry>
      <material name="alower_arm"/>
    </visual>
    <collision name="collision_lift_arm_lower">
      <origin rpy="-1.5707964 0 -0.4712389" xyz="-0.2093314 0.1067384 3.33e-05"/>
      <geometry>
        <box size="0.4483504 0.0915001 0.0243848"/>
      </geometry>
    </collision>
  </link>
  <link name="lift_arm_upper">
    <inertial>
      <origin rpy="0 0 0" xyz="-0.1397772 0.0769129 -9.87e-05"/>
      <mass value="2.2"/>
      <inertia ixx="0.0009413" ixy="-0.0006054" ixz="0.0005665" iyy="0.0032542" iyz="-1.06e-05" izz="0.0025802"/>
    </inertial>
    <visual name="visual_emergency_stop">
      <origin rpy="-1.5707964 0 0" xyz="-0.0732943 0.0745365 -5.57e-05"/>
      <geometry>
        <mesh filename="package://mir100_hook_description/meshes/stl/emergency_stop.stl" scale="1.0 1.0 1.0"/>
      </geometry>
      <material name="emergency"/>
    </visual>
    <visual name="visual_lift_arm_upper">
      <origin rpy="-1.5707964 0 0" xyz="-0.2092544 0.1027477 0"/>
      <geometry>
        <mesh filename="package://mir100_hook_description/meshes/stl/lift_arm_upper.stl" scale="1.0 1.0 1.0"/>
      </geometry>
      <material name="upper_arm"/>
    </visual>
    <collision name="collision_emergency_stop">
      <origin rpy="-1.5707964 0 -0.4712389" xyz="-0.0769995 0.0721075 -0.0002136"/>
      <geometry>
        <cylinder length="0.0454842" radius="0.0200511"/>
      </geometry>
    </collision>
    <collision name="collision_lift_arm_upper">
      <origin rpy="-1.5707964 0 -0.4712389" xyz="-0.2092544 0.1062098 0"/>
      <geometry>
        <box size="0.4483504 0.0915001 0.0251618"/>
      </geometry>
    </collision>
  </link>
  <link name="lift_motor_joint">
    <inertial>
      <origin rpy="0 0 0" xyz="-0.0288321 0.0338943 0.011049"/>
      <mass value="0.55"/>
      <inertia ixx="0.0001287" ixy="-3.9e-06" ixz="3.2e-05" iyy="0.0001894" iyz="4.65e-05" izz="8.17e-05"/>
    </inertial>
    <visual name="visual_lift_actuator_cylinder">
      <origin rpy="-1.5707964 0 0" xyz="-0.1810796 0.1424212 8.3e-06"/>
      <geometry>
        <mesh filename="package://mir100_hook_description/meshes/stl/Part__Feature063.stl" scale="1.0 1.0 1.0"/>
      </geometry>
      <material name="actuator_cylinder"/>
    </visual>
    <visual name="visual_lift_actuator_motor">
      <origin rpy="-1.5707964 0 0" xyz="-0.0706371 0.0612726 3.1e-06"/>
      <geometry>
        <mesh filename="package://mir100_hook_description/meshes/stl/Part__Feature062.stl" scale="1.0 1.0 1.0"/>
      </geometry>
      <material name="actuator_motor"/>
    </visual>
    <collision name="collision_lift_actuator_cylinder">
      <origin rpy="-1.5707963 0 -2.2375119" xyz="-0.1900736 0.1490457 3.1e-06"/>
      <geometry>
        <cylinder length="0.1076295" radius="0.0096713"/>
      </geometry>
    </collision>
    <collision name="collision_lift_actuator_motor">
      <origin rpy="-1.5707963 0 -2.2375116" xyz="-0.083919 0.0620954 3.1e-06"/>
      <geometry>
        <cylinder length="0.1873198" radius="0.0186919"/>
      </geometry>
    </collision>
  </link>
  <link name="pan_motor">
    <inertial>
      <origin rpy="0 0 0" xyz="-0.0205048 -2.86e-05 -0.0183847"/>
      <mass value="5.5"/>
      <inertia ixx="0.0013133" ixy="0.000168" ixz="5e-07" iyy="0.0014023" iyz="-1.4e-06" izz="0.000605"/>
    </inertial>
    <visual name="visual_pan_motor">
      <origin rpy="0 0 0" xyz="-0.0200243 -0.0003519 -0.0032138"/>
      <geometry>
        <mesh filename="package://mir100_hook_description/meshes/stl/pan_motor.stl" scale="1.0 1.0 1.0"/>
      </geometry>
      <material name="pan"/>
    </visual>
    <collision name="collision_pan_motor">
      <origin rpy="0 0 0" xyz="0 0 -0.0238775"/>
      <geometry>
        <cylinder length="0.2146374" radius="0.0589277"/>
      </geometry>
    </collision>
  </link>
  <link name="root">
    <inertial>
      <origin rpy="0 0 0" xyz="0.0410034 -0.000587 0.1077447"/>
      <mass value="10.3999996"/>
      <inertia ixx="0.0132281" ixy="-0.0003299" ixz="2.77e-05" iyy="0.0183048" iyz="-9.9e-06" izz="0.0244622"/>
    </inertial>
    <visual name="visual_frame">
      <origin rpy="0 0 0" xyz="-0.0690002 -2.2e-06 0.1547746"/>
      <geometry>
        <mesh filename="package://mir100_hook_description/meshes/stl/frame.stl" scale="1.0 1.0 1.0"/>
      </geometry>
      <material name="frame"/>
    </visual>
    <collision name="collision_frame_1">
      <origin rpy="0 0 0" xyz="-0.0690002 -0.1933002 0.0197549"/>
      <geometry>
        <box size="0.772 0.0687 0.03696"/>
      </geometry>
    </collision>
    <collision name="collision_frame_2">
      <origin rpy="0 0 0" xyz="-0.0690002 0.1933 0.019755"/>
      <geometry>
        <box size="0.772 0.0687 0.03696"/>
      </geometry>
    </collision>
    <collision name="collision_frame_3">
      <origin rpy="0 0 0" xyz="-0.0406363 -9.1e-06 0.2792808"/>
      <geometry>
        <cylinder length="0.05496" radius="0.1158"/>
      </geometry>
    </collision>
    <collision name="collision_frame_4">
      <origin rpy="0 0 0" xyz="0.1580628 -2.2e-06 0.041374"/>
      <geometry>
        <box size="0.31652 0.458 0.077"/>
      </geometry>
    </collision>
    <collision name="collision_frame_5">
      <origin rpy="1.5707964 0.7592182 0" xyz="0.1693561 0 0.1547746"/>
      <geometry>
        <cylinder length="0.23816" radius="0.18914"/>
      </geometry>
    </collision>
    <collision name="collision_frame_6">
      <origin rpy="1.5707964 0.6981317 1.5707964" xyz="0.1092483 -0.161247 0.1393904"/>
      <geometry>
        <cylinder length="0.19236" radius="0.03474"/>
      </geometry>
    </collision>
    <collision name="collision_frame_7">
      <origin rpy="1.5707963 -0.6981317 1.5707964" xyz="0.109248 0.161247 0.13939"/>
      <geometry>
        <cylinder length="0.19236" radius="0.03474"/>
      </geometry>
    </collision>
    <collision name="collision_frame_8">
      <origin rpy="1.6528268 0 1.5707964" xyz="0.038432 -2.2e-06 0.1246587"/>
      <geometry>
        <cylinder length="0.05496" radius="0.193"/>
      </geometry>
    </collision>
  </link>
  <joint name="carriage" type="revolute">
    <origin rpy="0 0 0" xyz="-0.418597 0.213663 3e-05"/>
    <parent link="lift_arm_lower"/>
    <child link="carriage"/>
    <axis xyz="0 0 1.0"/>
    <limit effort="0" lower="-0.5235988" upper="0" velocity="0"/>
  </joint>
  <joint name="lift_arm_lower" type="revolute">
    <origin rpy="1.5707964 0 0" xyz="-0.077511 3.3e-05 -0.0564022"/>
    <parent link="pan_motor"/>
    <child link="lift_arm_lower"/>
    <axis xyz="0 0 1.0"/>
    <limit effort="100.0" lower="0" upper="0.5235988" velocity="6.0"/>
  </joint>
  <!-- <joint name="lift_arm_upper" type="revolute">
      <mimic joint="lift_arm_lower" multiplier="1.0"/>
      <origin xyz="-0.0775113 0 0.0832461" rpy="1.5707964 0 0"/>
      <parent link="pan_motor"/>
      <child link="lift_arm_upper"/>
      <axis xyz="0 0 1.0"/>
      <limit lower="-1.5707964" upper="1.5707964" effort="100.0" velocity="6.0"/>
    </joint>

    <joint name="lift_motor_joint" type="revolute">
      <mimic joint="lift_arm_lower" multiplier="-0.5"/>
      <origin xyz="-0.1756014 0.1282467 3e-05" rpy="0 0 0"/>
      <parent link="lift_arm_lower"/>
      <child link="lift_motor_joint"/>
      <axis xyz="0 0 1.0"/>
      <limit lower="-0.5235988" upper="0.5235988" effort="100.0" velocity="6.0"/>
    </joint> -->
  <!-- <joint name="carriage" type="fixed">
      <origin xyz="-0.418597 0.213663 3e-05" rpy="0 0 -0.26"/>
      <parent link="lift_arm_lower"/>
      <child link="carriage"/>
    </joint> -->
  <!-- <joint name="lift_arm_lower" type="fixed">
      <origin xyz="-0.077511 3.3e-05 -0.0564022" rpy="1.5707964 -0.26 0"/>
      <parent link="pan_motor"/>
      <child link="lift_arm_lower"/>
    </joint> -->
  <joint name="lift_arm_upper" type="fixed">
    <origin rpy="1.5707964 -0.26 0" xyz="-0.0775113 0 0.0832461"/>
    <parent link="pan_motor"/>
    <child link="lift_arm_upper"/>
  </joint>
  <joint name="lift_motor_joint" type="fixed">
    <origin rpy="0 0 -0.13" xyz="-0.1756014 0.1282467 3e-05"/>
    <parent link="lift_arm_lower"/>
    <child link="lift_motor_joint"/>
  </joint>
  <joint name="pan_motor" type="revolute">
    <origin rpy="0 0 0" xyz="-0.067 -3e-06 0.1383631"/>
    <parent link="root"/>
    <child link="pan_motor"/>
    <axis xyz="0 0 1.0"/>
    <limit effort="100.0" lower="-1.5707964" upper="1.5707964" velocity="6.0"/>
  </joint>
  <material name="actuator_cylinder">
    <color rgba="0.2134007 0.2134007 0.2134007 1.0"/>
  </material>
  <material name="actuator_motor">
    <color rgba="0.037566 0.037566 0.037566 1.0"/>
  </material>
  <material name="alower_arm">
    <color rgba="0.7450982 0.2131856 0.3956822 1.0"/>
  </material>
  <material name="carriage">
    <color rgba="0.2054005 0.2053091 0.6400001 1.0"/>
  </material>
  <material name="crawler">
    <color rgba="0.7205863 0.6554337 0.7450982 1.0"/>
  </material>
  <material name="emergency">
    <color rgba="0.6980393 0 0 1.0"/>
  </material>
  <material name="fork">
    <color rgba="0.6400001 0.2983088 0.242304 1.0"/>
  </material>
  <material name="frame">
    <color rgba="1.0 1.0 1.0 1.0"/>
  </material>
  <material name="lock">
    <color rgba="0.5881902 0.6400001 0.1759095 1.0"/>
  </material>
  <material name="pan">
    <color rgba="0.2133705 0.491692 0.4237792 1.0"/>
  </material>
  <material name="tilt_arm_lower">
    <color rgba="0.2454659 0.6400001 0.2429259 1.0"/>
  </material>
  <material name="tilt_arm_upper">
    <color rgba="0.156151 0.2418648 0.6400001 1.0"/>
  </material>
  <material name="upper_arm">
    <color rgba="0.3999999 0.107354 0.054022 1.0"/>
  </material>
  <link name="back_stabilizer">
    <inertial>
      <origin rpy="0 0 0" xyz="0 0 0"/>
      <mass value="0.1"/>
      <inertia ixx="5e-05" ixy="0" ixz="0" iyy="0.00038" iyz="0" izz="0.00032"/>
    </inertial>
    <visual name="visual_back_stabilizer">
      <origin rpy="0 0 0" xyz="0 0 0"/>
      <geometry>
        <mesh filename="package://roll_container_description/meshes/stl/Part__Feature167.stl" scale="1.0 1.0 1.0"/>
      </geometry>
      <material name="back_stabilizer"/>
    </visual>
    <collision name="collision_back_stabilizer_1">
      <origin rpy="0 1.5708 0" xyz="0 0.00014 0.14752"/>
      <geometry>
        <cylinder length="0.64768" radius="0.01072"/>
      </geometry>
    </collision>
    <collision name="collision_back_stabilizer_2">
      <origin rpy="0 0 0" xyz="0.3151 -0.00054 -0.02707"/>
      <geometry>
        <cylinder length="0.35586" radius="0.01072"/>
      </geometry>
    </collision>
    <collision name="collision_back_stabilizer_3">
      <origin rpy="0 0 0" xyz="-0.3151 -0.00054 -0.02706"/>
      <geometry>
        <cylinder length="0.35586" radius="0.01072"/>
      </geometry>
    </collision>
  </link>
  <link name="castor_rigit_left">
    <inertial>
      <origin rpy="0 0 0" xyz="0 0 0"/>
      <mass value="0.05"/>
      <inertia ixx="2e-05" ixy="0" ixz="0" iyy="2e-05" iyz="0" izz="2e-05"/>
    </inertial>
    <visual name="visual_castor_rigit_left_fork">
      <origin rpy="0 0 0" xyz="0 0 0"/>
      <geometry>
        <mesh filename="package://roll_container_description/meshes/stl/Part__Feature082.stl" scale="1.0 1.0 1.0"/>
      </geometry>
      <material name="metal"/>
    </visual>
    <collision name="collision_castor_rigit_left_fork">
      <origin rpy="0 0 0" xyz="-0.00018 0 -0.01474"/>
      <geometry>
        <box size="0.086 0.1015 0.089"/>
      </geometry>
    </collision>
  </link>
  <link name="castor_rigit_left_wheel">
    <inertial>
      <origin rpy="0 0 0" xyz="0 0 0"/>
      <mass value="0.25"/>
      <inertia ixx="3e-05" ixy="0" ixz="0" iyy="2e-05" iyz="0" izz="2e-05"/>
    </inertial>
    <visual name="visual_castor_rigit_left_wheel">
      <origin rpy="0 -1.5708 0" xyz="0 0 0"/>
      <geometry>
        <mesh filename="package://roll_container_description/meshes/stl/Part__Feature066.stl" scale="1.0 1.0 1.0"/>
      </geometry>
      <material name="wheel"/>
    </visual>
    <collision name="collision_castor_rigit_left_wheel">
      <origin rpy="0 0 0" xyz="-5e-05 0 0"/>
      <geometry>
        <cylinder length="0.03989" radius="0.0495"/>
      </geometry>
    </collision>
  </link>
  <link name="castor_rigit_right">
    <inertial>
      <origin rpy="0 0 0" xyz="0 0 0"/>
      <mass value="0.05"/>
      <inertia ixx="2e-05" ixy="0" ixz="0" iyy="2e-05" iyz="0" izz="2e-05"/>
    </inertial>
    <visual name="visual_castor_rigit_right_fork">
      <origin rpy="0 0 0" xyz="0 0 0"/>
      <geometry>
        <mesh filename="package://roll_container_description/meshes/stl/Part__Feature099.stl" scale="1.0 1.0 1.0"/>
      </geometry>
      <material name="metal"/>
    </visual>
    <collision name="collision_castor_rigit_right_fork">
      <origin rpy="0 0 0" xyz="-0.00018 0 -0.01474"/>
      <geometry>
        <box size="0.086 0.1015 0.089"/>
      </geometry>
    </collision>
  </link>
  <link name="castor_rigit_right_wheel">
    <inertial>
      <origin rpy="0 0 0" xyz="0 0 0"/>
      <mass value="0.25"/>
      <inertia ixx="3e-05" ixy="0" ixz="0" iyy="2e-05" iyz="0" izz="2e-05"/>
    </inertial>
    <visual name="visual_castor_rigit_right_wheel">
      <origin rpy="0 -1.5708 0" xyz="0 0 0"/>
      <geometry>
        <mesh filename="package://roll_container_description/meshes/stl/Part__Feature083.stl" scale="1.0 1.0 1.0"/>
      </geometry>
      <material name="wheel"/>
    </visual>
    <collision name="collision_castor_rigit_right_wheel">
      <origin rpy="0 0 0" xyz="-5e-05 0 0"/>
      <geometry>
        <cylinder length="0.03989" radius="0.0495"/>
      </geometry>
    </collision>
  </link>
  <link name="castor_swivel_left">
    <inertial>
      <origin rpy="0 0 0" xyz="0 0 0"/>
      <mass value="0.05"/>
      <inertia ixx="2e-05" ixy="0" ixz="0" iyy="2e-05" iyz="0" izz="2e-05"/>
    </inertial>
    <visual name="visual_castor_swivel_left_top_plate">
      <origin rpy="0 0 0" xyz="0 0 0"/>
      <geometry>
        <mesh filename="package://roll_container_description/meshes/stl/Part__Feature021.stl" scale="1.0 1.0 1.0"/>
      </geometry>
      <material name="metal"/>
    </visual>
    <collision name="collision_castor_swivel_left_top_plate">
      <origin rpy="0 0 0" xyz="0 0 -0.00201"/>
      <geometry>
        <box size="0.08 0.105 0.0125"/>
      </geometry>
    </collision>
  </link>
  <link name="castor_swivel_left_fork">
    <inertial>
      <origin rpy="0 0 0" xyz="-0.00547 -0.01599 -0.02516"/>
      <mass value="0.05"/>
      <inertia ixx="2e-05" ixy="0" ixz="0" iyy="2e-05" iyz="0" izz="2e-05"/>
    </inertial>
    <visual name="visual_castor_swivel_left_fork">
      <origin rpy="0 0 0" xyz="-0.00547 -0.01599 -0.02516"/>
      <geometry>
        <mesh filename="package://roll_container_description/meshes/stl/Part__Feature022.stl" scale="1.0 1.0 1.0"/>
      </geometry>
      <material name="metal"/>
    </visual>
    <collision name="collision_castor_swivel_left_fork">
      <origin rpy="0 0 0" xyz="0.00029 -0.01005 -0.03671"/>
      <geometry>
        <box size="0.06794 0.086 0.07898"/>
      </geometry>
    </collision>
  </link>
  <link name="castor_swivel_left_wheel">
    <inertial>
      <origin rpy="0 0 0" xyz="0 0 -5e-05"/>
      <mass value="0.25"/>
      <inertia ixx="3e-05" ixy="0" ixz="0" iyy="2e-05" iyz="0" izz="2e-05"/>
    </inertial>
    <visual name="visual_castor_swivel_left_wheel">
      <origin rpy="0.50265 -1.5708 0" xyz="0 0 -5e-05"/>
      <geometry>
        <mesh filename="package://roll_container_description/meshes/stl/Part__Feature006.stl" scale="1.0 1.0 1.0"/>
      </geometry>
      <material name="wheel"/>
    </visual>
    <collision name="collision_castor_swivel_left_wheel">
      <origin rpy="0 0 0" xyz="0 0 0"/>
      <geometry>
        <cylinder length="0.03989" radius="0.0495"/>
      </geometry>
    </collision>
  </link>
  <link name="castor_swivel_right_wheel">
    <inertial>
      <origin rpy="0 0 0" xyz="0 0 -5e-05"/>
      <mass value="0.25"/>
      <inertia ixx="3e-05" ixy="0" ixz="0" iyy="2e-05" iyz="0" izz="2e-05"/>
    </inertial>
    <visual name="visual_castor_swivel_right_wheel">
      <origin rpy="0.50265 -1.5708 0" xyz="0 0 -5e-05"/>
      <geometry>
        <mesh filename="package://roll_container_description/meshes/stl/Part__Feature006.stl" scale="1.0 1.0 1.0"/>
      </geometry>
      <material name="wheel"/>
    </visual>
    <collision name="collision_castor_swivel_right_wheel">
      <origin rpy="0 0 0" xyz="0 0 0"/>
      <geometry>
        <cylinder length="0.03989" radius="0.0495"/>
      </geometry>
    </collision>
  </link>
  <link name="castor_swivel_right_fork">
    <inertial>
      <origin rpy="0 0 0" xyz="-0.00589 -0.01692 -0.02589"/>
      <mass value="0.05"/>
      <inertia ixx="2e-05" ixy="0" ixz="0" iyy="2e-05" iyz="0" izz="2e-05"/>
    </inertial>
    <visual name="visual_castor_swivel_right_fork">
      <origin rpy="0 0 0" xyz="-0.00589 -0.01692 -0.02589"/>
      <geometry>
        <mesh filename="package://roll_container_description/meshes/stl/Part__Feature117.stl" scale="1.0 1.0 1.0"/>
      </geometry>
      <material name="metal"/>
    </visual>
    <collision name="collision_castor_swivel_right_fork">
      <origin rpy="0 0 0" xyz="0.00107 -0.00955 -0.03667"/>
      <geometry>
        <box size="0.06794 0.086 0.07898"/>
      </geometry>
    </collision>
  </link>
  <link name="handle_left">
    <inertial>
      <origin rpy="0 0 0" xyz="0 0 0"/>
      <mass value="0.1"/>
      <inertia ixx="0.00011" ixy="0" ixz="0" iyy="0.00011" iyz="0" izz="2e-05"/>
    </inertial>
    <visual name="visual_handle_left">
      <origin rpy="0 0 0" xyz="-0.00659 0.00693 0"/>
      <geometry>
        <mesh filename="package://roll_container_description/meshes/stl/Part__Feature163.stl" scale="1.0 1.0 1.0"/>
      </geometry>
      <material name="handle"/>
    </visual>
    <collision name="collision_handle_left">
      <origin rpy="0 0 0" xyz="0.00434 -0.00751 -4e-05"/>
      <geometry>
        <cylinder length="0.27591" radius="0.00973"/>
      </geometry>
    </collision>
    <collision name="collision_handle_left_2">
      <origin rpy="1.5708 0 0.5236" xyz="-0.01033 0.01723 -0.13067"/>
      <geometry>
        <cylinder length="0.05394" radius="0.00973"/>
      </geometry>
    </collision>
    <collision name="collision_handle_left_3">
      <origin rpy="1.5708 0 0.5236" xyz="-0.01033 0.01723 0.12873"/>
      <geometry>
        <cylinder length="0.05394" radius="0.00973"/>
      </geometry>
    </collision>
  </link>
  <link name="handle_right">
    <inertial>
      <origin rpy="0 0 0" xyz="0.00433 0.00751 4e-05"/>
      <mass value="0.1"/>
      <inertia ixx="0.00011" ixy="0" ixz="0" iyy="0.00011" iyz="0" izz="2e-05"/>
    </inertial>
    <visual name="visual_handle_right">
      <origin rpy="0 0 0" xyz="0.00433 0.00751 4e-05"/>
      <geometry>
        <mesh filename="package://roll_container_description/meshes/stl/Part__Feature166.stl" scale="1.0 1.0 1.0"/>
      </geometry>
      <material name="handle"/>
    </visual>
    <collision name="collision_handle_right">
      <origin rpy="0 0 0" xyz="0 0 0"/>
      <geometry>
        <cylinder length="0.27591" radius="0.00973"/>
      </geometry>
    </collision>
    <collision name="collision_handle_right_000">
      <origin rpy="1.5708 0 -0.5236" xyz="0.01477 0.02494 0.12877"/>
      <geometry>
        <cylinder length="0.05394" radius="0.00973"/>
      </geometry>
    </collision>
    <collision name="collision_handle_right_000_001">
      <origin rpy="1.5708 0 -0.5236" xyz="0.01477 0.02494 -0.13063"/>
      <geometry>
        <cylinder length="0.05394" radius="0.00973"/>
      </geometry>
    </collision>
  </link>
  <link name="castor_swivel_right">
    <inertial>
      <origin rpy="0 0 0" xyz="0 0 0"/>
      <mass value="0.05"/>
      <inertia ixx="2e-05" ixy="0" ixz="0" iyy="2e-05" iyz="0" izz="2e-05"/>
    </inertial>
    <visual name="visual_castor_swivel_right_top_plate">
      <origin rpy="0 0 0" xyz="0 0 0"/>
      <geometry>
        <mesh filename="package://roll_container_description/meshes/stl/Part__Feature021.stl" scale="1.0 1.0 1.0"/>
      </geometry>
      <material name="metal"/>
    </visual>
    <collision name="collision_castor_swivel_right_top_plate">
      <origin rpy="0 0 0" xyz="0 0 -0.00201"/>
      <geometry>
        <box size="0.08 0.105 0.0125"/>
      </geometry>
    </collision>
  </link>
  <link name="roll_container_root">
    <inertial>
      <origin rpy="0 0 0" xyz="0 0 0"/>
      <mass value="2.0"/>
      <inertia ixx="0.00605" ixy="0" ixz="0" iyy="0.00465" iyz="0" izz="0.01065"/>
    </inertial>
    <visual name="visual_container_base">
      <origin rpy="0 0 0" xyz="-0.00111 0 0"/>
      <geometry>
        <mesh filename="package://roll_container_description/meshes/stl/Part__Feature.stl" scale="1.01559 1.0 1.0"/>
      </geometry>
      <material name="plate"/>
    </visual>
    <collision name="collision_container_base">
      <origin rpy="0 0 0" xyz="0.00017 0.00201 -0.00708"/>
      <geometry>
        <box size="0.724 0.815 0.06371"/>
      </geometry>
    </collision>
  </link>
  <link name="wire_lattice_left">
    <inertial>
      <origin rpy="0 0 0" xyz="0 0 0"/>
      <mass value="2.0"/>
      <inertia ixx="0.02993" ixy="1e-05" ixz="0" iyy="0.02364" iyz="0" izz="0.0063"/>
    </inertial>
    <visual name="visual_wire_lattice_left">
      <origin rpy="0 0 0" xyz="0 0 0"/>
      <geometry>
        <mesh filename="package://roll_container_description/meshes/stl/Part__Feature162.stl" scale="1.0 1.0 1.0"/>
      </geometry>
      <material name="lattice"/>
    </visual>
    <collision name="collision_wire_lattice_left">
      <origin rpy="0 0 0" xyz="-0.00376 -2e-05 0.04164"/>
      <geometry>
        <box size="0.01972 0.79 1.43781"/>
      </geometry>
    </collision>
  </link>
  <link name="wire_lattice_right">
    <inertial>
      <origin rpy="0 0 0" xyz="0 0 0"/>
      <mass value="2.0"/>
      <inertia ixx="0.02993" ixy="-1e-05" ixz="0" iyy="0.02364" iyz="0" izz="0.0063"/>
    </inertial>
    <visual name="visual_wire_lattice_right">
      <origin rpy="0 0 0" xyz="0 0 0"/>
      <geometry>
        <mesh filename="package://roll_container_description/meshes/stl/Part__Feature165.stl" scale="1.0 1.0 1.0"/>
      </geometry>
      <material name="lattice"/>
    </visual>
    <collision name="collision_wire_lattice_right">
      <origin rpy="0 0 0" xyz="0.00378 -0.00039 0.04163"/>
      <geometry>
        <box size="0.01977 0.79 1.43701"/>
      </geometry>
    </collision>
  </link>
  <joint name="back_stabilizer" type="fixed">
    <origin rpy="0 0 0" xyz="0.00017 0.38637 1.06389"/>
    <parent link="roll_container_root"/>
    <child link="back_stabilizer"/>
  </joint>
  <joint name="castor_rigit_left" type="fixed">
    <origin rpy="0 0 0" xyz="-0.28116 0.33151 -0.06865"/>
    <parent link="roll_container_root"/>
    <child link="castor_rigit_left"/>
  </joint>
  <joint name="castor_rigit_left_wheel" type="continuous">
    <origin rpy="0 1.5708 0" xyz="-0.00012 0 -0.04824"/>
    <parent link="castor_rigit_left"/>
    <child link="castor_rigit_left_wheel"/>
    <axis xyz="0 0 1.0"/>
    <limit effort="0" velocity="0"/>
  </joint>
  <joint name="castor_rigit_right" type="fixed">
    <origin rpy="0 0 0" xyz="0.28116 0.33151 -0.06865"/>
    <parent link="roll_container_root"/>
    <child link="castor_rigit_right"/>
  </joint>
  <joint name="castor_rigit_right_wheel" type="continuous">
    <origin rpy="0 1.5708 0" xyz="-0.00012 0 -0.04824"/>
    <parent link="castor_rigit_right"/>
    <child link="castor_rigit_right_wheel"/>
    <axis xyz="0 0 1.0"/>
    <limit effort="0" velocity="0"/>
  </joint>
  <joint name="castor_swivel_left" type="fixed">
    <origin rpy="0 0 0" xyz="-0.28133 -0.32949 -0.04313"/>
    <parent link="roll_container_root"/>
    <child link="castor_swivel_left"/>
  </joint>
  <joint name="castor_swivel_left_fork" type="continuous">
    <origin rpy="0 0 0" xyz="-0.0003 0.00105 -0.00905"/>
    <parent link="castor_swivel_left"/>
    <child link="castor_swivel_left_fork"/>
    <axis xyz="0 0 1.0"/>
    <limit effort="0" velocity="0"/>
  </joint>
  <joint name="castor_swivel_left_wheel" type="continuous">
    <origin rpy="0 1.5708 0" xyz="0.0003 -0.04105 -0.06471"/>
    <parent link="castor_swivel_left_fork"/>
    <child link="castor_swivel_left_wheel"/>
    <axis xyz="0 0 1.0"/>
    <limit effort="0" velocity="0"/>
  </joint>
  <joint name="castor_swivel_right" type="fixed">
    <origin rpy="0 0 0" xyz="0.28133 -0.32949 -0.04313"/>
    <parent link="roll_container_root"/>
    <child link="castor_swivel_right"/>
  </joint>
  <joint name="castor_swivel_right_fork" type="continuous">
    <origin rpy="0 0 0" xyz="-0.00108 -0.00045 -0.01333"/>
    <parent link="castor_swivel_right"/>
    <child link="castor_swivel_right_fork"/>
    <axis xyz="0 0 1.0"/>
    <limit effort="0" velocity="0"/>
  </joint>
  <joint name="castor_swivel_right_wheel" type="continuous">
    <origin rpy="0 1.5708 0" xyz="0.00108 -0.04055 -0.06467"/>
    <parent link="castor_swivel_right_fork"/>
    <child link="castor_swivel_right_wheel"/>
    <axis xyz="0 0 1.0"/>
    <limit effort="0" velocity="0"/>
  </joint>
  <joint name="handle_left" type="fixed">
    <origin rpy="0 0 0" xyz="0.0335 -0.44534 0.20148"/>
    <parent link="wire_lattice_left"/>
    <child link="handle_left"/>
  </joint>
  <joint name="handle_right" type="fixed">
    <origin rpy="0 0 0" xyz="-0.03349 -0.44571 0.20147"/>
    <parent link="wire_lattice_right"/>
    <child link="handle_right"/>
  </joint>
  <joint name="wire_lattice_left" type="fixed">
    <origin rpy="0 0 0" xyz="-0.3407 0.00254 0.70262"/>
    <parent link="roll_container_root"/>
    <child link="wire_lattice_left"/>
  </joint>
  <joint name="wire_lattice_right" type="fixed">
    <origin rpy="0 0 0" xyz="0.34102 0.00291 0.70264"/>
    <parent link="roll_container_root"/>
    <child link="wire_lattice_right"/>
  </joint>
  <material name="back_stabilizer">
    <color rgba="0.64 0 0.00462 1.0"/>
  </material>
  <material name="handle">
    <color rgba="0.54902 0.06118 0.01087 1.0"/>
  </material>
  <material name="lattice">
    <color rgba="0.04 0.23976 0.8 1.0"/>
  </material>
  <material name="metal">
    <color rgba="0.37158 0.38592 0.39753 1.0"/>
  </material>
  <material name="plate">
    <color rgba="0.00779 0.02086 0.74902 1.0"/>
  </material>
  <material name="wheel">
    <color rgba="0.93333 0.76027 0.01116 1.0"/>
  </material>
  <joint name="mir_hook_joint" type="fixed">
    <origin rpy="0 0 0" xyz="0.106 0.0 0.35"/>
    <parent link="base_link"/>
    <child link="root"/>
  </joint>
  <joint name="hook_point_joint" type="fixed">
    <origin rpy="-1.5708 0 0" xyz="-0.2 -0.36 0.0"/>
    <parent link="carriage"/>
    <child link="hook_point"/>
  </joint>
  <link name="hook_point"/>
  <joint name="roll_container_joint" type="fixed">
    <origin rpy="0 0 1.5708" xyz="-0.25 0.0 0.0"/>
    <parent link="hook_point"/>
    <child link="roll_container_root"/>
  </joint>
</robot>

