<mujoco model="pr2">
    <compiler angle="radian" meshdir="/home/giang/mujoco_ws/src/mujoco_robots/my_robot/robot/my_robot/stl/" autolimits="true" balanceinertia="true" discardvisual="true" boundmass="0.000001" boundinertia="0.000001"/>
    <asset>
        <mesh name="base_L" file="base_L.stl"/>
        <mesh name="caster_L" file="caster_L.stl"/>
        <mesh name="torso_lift_L" file="torso_lift_L.stl"/>
        <mesh name="head_pan_L" file="head_pan_L.stl"/>
        <mesh name="head_tilt_L" file="head_tilt_L.stl"/>
        <mesh name="tilting_hokuyo_L" file="tilting_hokuyo_L.stl"/>
        <mesh name="shoulder_pan" file="shoulder_pan.stl"/>
        <mesh name="shoulder_lift" file="shoulder_lift.stl"/>
        <mesh name="upper_arm_roll_L" file="upper_arm_roll_L.stl"/>
        <mesh name="upper_arm" file="upper_arm.stl"/>
        <mesh name="forearm_roll_L" file="forearm_roll_L.stl"/>
        <mesh name="elbow_flex" file="elbow_flex.stl"/>
        <mesh name="forearm" file="forearm.stl"/>
        <mesh name="wrist_flex" file="wrist_flex.stl"/>
        <mesh name="wrist_roll_L" file="wrist_roll_L.stl"/>
        <mesh name="gripper_palm" file="gripper_palm.stl"/>
        <mesh name="l_finger" file="l_finger.stl"/>
        <mesh name="l_finger_tip" file="l_finger_tip.stl"/>
    </asset>
    <worldbody>
        <body name="pr2">
            <geom size="0.0005 0.0005 0.0005" pos="0 0 0.071" type="box" rgba="1 1 1 1"/>
            <geom pos="0 0 0.051" type="mesh" rgba="1 1 1 1" mesh="base_L"/>
            <geom size="0.025 0.185 0.15" pos="-0.29 0 0.851" type="box" rgba="0.1 0.1 0.1 1"/>
            <body name="fl_caster_rotation_link" pos="0.2246 0.2246 0.0792">
                <inertial pos="0 0 0.07" quat="0.589921 -0.182261 -0.205712 0.759247" mass="3.47308" diaginertia="0.0153925 0.0125446 0.0114568"/>
                <joint name="fl_caster_rotation_joint" pos="0 0 0" axis="0 0 1" damping="1"/>
                <geom type="mesh" mesh="caster_L"/>
                <body name="fl_caster_l_wheel_link" pos="0 0.049 0">
                    <inertial pos="0 0 0" quat="0.589921 -0.182261 -0.205712 0.759247" mass="0.44036" diaginertia="0.0153925 0.0125446 0.0114568"/>
                    <joint name="fl_caster_l_wheel_joint" pos="0 0 0" axis="0 1 0" damping="1"/>
                    <geom size="0.074792 0.017" quat="0.707107 0.707107 0 0" type="cylinder"/>
                </body>
                <body name="fl_caster_r_wheel_link" pos="0 -0.049 0">
                    <inertial pos="0 0 0" quat="0.589921 -0.182261 -0.205712 0.759247" mass="0.44036" diaginertia="0.0153925 0.0125446 0.0114568"/>
                    <joint name="fl_caster_r_wheel_joint" pos="0 0 0" axis="0 1 0" damping="1"/>
                    <geom size="0.074792 0.017" quat="0.707107 0.707107 0 0" type="cylinder"/>
                </body>
            </body>
            <body name="fr_caster_rotation_link" pos="0.2246 -0.2246 0.0792">
                <inertial pos="0 0 0.07" quat="0.589921 -0.182261 -0.205712 0.759247" mass="3.47308" diaginertia="0.0153925 0.0125446 0.0114568"/>
                <joint name="fr_caster_rotation_joint" pos="0 0 0" axis="0 0 1" damping="1"/>
                <geom type="mesh" mesh="caster_L"/>
                <body name="fr_caster_l_wheel_link" pos="0 0.049 0">
                    <inertial pos="0 0 0" quat="0.589921 -0.182261 -0.205712 0.759247" mass="0.44036" diaginertia="0.0153925 0.0125446 0.0114568"/>
                    <joint name="fr_caster_l_wheel_joint" pos="0 0 0" axis="0 1 0" damping="1"/>
                    <geom size="0.074792 0.017" quat="0.707107 0.707107 0 0" type="cylinder"/>
                </body>
                <body name="fr_caster_r_wheel_link" pos="0 -0.049 0">
                    <inertial pos="0 0 0" quat="0.589921 -0.182261 -0.205712 0.759247" mass="0.44036" diaginertia="0.0153925 0.0125446 0.0114568"/>
                    <joint name="fr_caster_r_wheel_joint" pos="0 0 0" axis="0 1 0" damping="1"/>
                    <geom size="0.074792 0.017" quat="0.707107 0.707107 0 0" type="cylinder"/>
                </body>
            </body>
            <body name="bl_caster_rotation_link" pos="-0.2246 0.2246 0.0792">
                <inertial pos="0 0 0.07" quat="0.589921 -0.182261 -0.205712 0.759247" mass="3.47308" diaginertia="0.0153925 0.0125446 0.0114568"/>
                <joint name="bl_caster_rotation_joint" pos="0 0 0" axis="0 0 1" damping="1"/>
                <geom type="mesh" mesh="caster_L"/>
                <body name="bl_caster_l_wheel_link" pos="0 0.049 0">
                    <inertial pos="0 0 0" quat="0.589921 -0.182261 -0.205712 0.759247" mass="0.44036" diaginertia="0.0153925 0.0125446 0.0114568"/>
                    <joint name="bl_caster_l_wheel_joint" pos="0 0 0" axis="0 1 0" damping="1"/>
                    <geom size="0.074792 0.017" quat="0.707107 0.707107 0 0" type="cylinder"/>
                </body>
                <body name="bl_caster_r_wheel_link" pos="0 -0.049 0">
                    <inertial pos="0 0 0" quat="0.589921 -0.182261 -0.205712 0.759247" mass="0.44036" diaginertia="0.0153925 0.0125446 0.0114568"/>
                    <joint name="bl_caster_r_wheel_joint" pos="0 0 0" axis="0 1 0" damping="1"/>
                    <geom size="0.074792 0.017" quat="0.707107 0.707107 0 0" type="cylinder"/>
                </body>
            </body>
            <body name="br_caster_rotation_link" pos="-0.2246 -0.2246 0.0792">
                <inertial pos="0 0 0.07" quat="0.589921 -0.182261 -0.205712 0.759247" mass="3.47308" diaginertia="0.0153925 0.0125446 0.0114568"/>
                <joint name="br_caster_rotation_joint" pos="0 0 0" axis="0 0 1" damping="1"/>
                <geom type="mesh" mesh="caster_L"/>
                <body name="br_caster_l_wheel_link" pos="0 0.049 0">
                    <inertial pos="0 0 0" quat="0.589921 -0.182261 -0.205712 0.759247" mass="0.44036" diaginertia="0.0153925 0.0125446 0.0114568"/>
                    <joint name="br_caster_l_wheel_joint" pos="0 0 0" axis="0 1 0" damping="1"/>
                    <geom size="0.074792 0.017" quat="0.707107 0.707107 0 0" type="cylinder"/>
                </body>
                <body name="br_caster_r_wheel_link" pos="0 -0.049 0">
                    <inertial pos="0 0 0" quat="0.589921 -0.182261 -0.205712 0.759247" mass="0.44036" diaginertia="0.0153925 0.0125446 0.0114568"/>
                    <joint name="br_caster_r_wheel_joint" pos="0 0 0" axis="0 1 0" damping="1"/>
                    <geom size="0.074792 0.017" quat="0.707107 0.707107 0 0" type="cylinder"/>
                </body>
            </body>
            <body name="torso_lift_link" pos="-0.05 0 0.790675">
                <inertial pos="-0.0994987 -4.1071e-06 -0.0867639" quat="0.999302 0.00758941 0.0364107 0.00350465" mass="36.449" diaginertia="2.8145 2.53392 0.52639"/>
                <joint name="torso_lift_joint" pos="0 0 0" axis="0 0 1" type="slide" range="0 0.33" damping="20000"/>
                <geom name="torso_lift_collision" type="mesh" rgba="0.9 0.9 0.9 1" mesh="torso_lift_L"/>
                <body name="head_pan_link" pos="-0.01707 0 0.38145">
                    <inertial pos="0.010907 0.031693 0.090507" quat="-0.0432724 0.73785 -0.0944754 0.666918" mass="6.339" diaginertia="0.0583935 0.0461226 0.0321798"/>
                    <joint name="head_pan_joint" pos="0 0 0" axis="0 0 1" range="-3.007 3.007" damping="0.5"/>
                    <geom type="mesh" rgba="0 0 0.8 1" mesh="head_pan_L"/>
                    <body name="head_tilt_link" pos="0.068 0 0">
                        <inertial pos="0.00602226 -0.0159771 0.05874" quat="0.050298 0.696025 0.0528056 0.714304" mass="4.91901" diaginertia="0.107257 0.0935478 0.0636434"/>
                        <joint name="head_tilt_joint" pos="0 0 0" axis="0 1 0" range="-0.471238 1.39626" damping="10"/>
                        <geom type="mesh" rgba="0 0.8 0 1" mesh="head_tilt_L"/>
                        <geom size="0.005 0.005 0.005" pos="0.0232 0 0.0645" type="box" rgba="0 0 0.8 1"/>
                    </body>
                </body>
                <body name="laser_tilt_mount_link" pos="0.09893 0 0.227">
                    <inertial pos="-0.00113408 0.00166718 -0.00706728" quat="0.993743 0.078799 -0.0456419 0.0646704" mass="0.592" diaginertia="0.00130331 0.00108852 0.000886175"/>
                    <joint name="laser_tilt_mount_joint" pos="0 0 0" axis="0 1 0" range="-0.7854 1.48353" damping="0.008"/>
                    <geom type="mesh" rgba="0.8 0 0 1" mesh="tilting_hokuyo_L"/>
                </body>
                <body name="r_shoulder_pan_link" pos="0 -0.188 0">
                    <inertial pos="-0.001201 0.024513 -0.098231" quat="0.927482 -0.0876561 0.0740595 -0.355821" mass="25.7993" diaginertia="0.934201 0.837701 0.242033"/>
                    <joint name="r_shoulder_pan_joint" pos="0 0 0" axis="0 0 1" range="-2.2854 0.714602" damping="10"/>
                    <geom type="mesh" rgba="0 0 0.8 1" mesh="shoulder_pan"/>
                    <body name="r_shoulder_lift_link" pos="0.1 0 0">
                        <inertial pos="0.02195 -0.02664 -0.03127" quat="0.791779 0.478014 0.238985 0.295762" mass="2.74988" diaginertia="0.0261874 0.0207302 0.0151681"/>
                        <joint name="r_shoulder_lift_joint" pos="0 0 0" axis="0 1 0" range="-0.5236 1.3963" damping="10"/>
                        <geom type="mesh" rgba="0.7 0.7 0.7 1" mesh="shoulder_lift"/>
                        <body name="r_upper_arm_roll_link">
                            <inertial pos="0.210482 -0.015945 -0.000196731" quat="-0.0448642 0.697702 -0.0890666 0.709413" mass="6.11769" diaginertia="0.0906678 0.0894595 0.025134"/>
                            <joint name="r_upper_arm_roll_joint" pos="0 0 0" axis="1 0 0" range="-3.9 0.8" damping="0.1"/>
                            <geom type="mesh" mesh="upper_arm_roll_L"/>
                            <geom type="mesh" rgba="0 0.8 0 1" mesh="upper_arm"/>
                            <body name="r_elbow_flex_link" pos="0.4 0 0">
                                <inertial pos="0.01014 0.00032 -0.01211" quat="0.308784 0.646797 0.639077 0.279083" mass="1.90327" diaginertia="0.00441852 0.00396477 0.00308977"/>
                                <joint name="r_elbow_flex_joint" pos="0 0 0" axis="0 1 0" range="-2.3213 0" damping="1"/>
                                <geom type="mesh" rgba="0.7 0.7 0.7 1" mesh="elbow_flex"/>
                                <body name="r_forearm_roll_link">
                                    <inertial pos="0.180727 -0.000163047 -0.00858341" quat="-0.000943818 0.72633 -0.00372954 0.687335" mass="2.68968" diaginertia="0.0310644 0.0295345 0.0146352"/>
                                    <joint name="r_forearm_roll_joint" pos="0 0 0" axis="1 0 0" damping="0.1"/>
                                    <geom type="mesh" mesh="forearm_roll_L"/>
                                    <geom type="mesh" rgba="0.7 0.7 0.7 1" mesh="forearm"/>
                                    <body name="r_wrist_flex_link" pos="0.321 0 0">
                                        <inertial pos="-0.00157 0 -0.00075" quat="0.695976 0.696411 -0.12356 0.123942" mass="0.61402" diaginertia="0.000652771 0.000643391 0.000198244"/>
                                        <joint name="r_wrist_flex_joint" pos="0 0 0" axis="0 1 0" range="-2.18 0" damping="0.1"/>
                                        <geom type="mesh" rgba="0.7 0.7 0.7 1" mesh="wrist_flex"/>
                                        <body name="r_wrist_roll_link">
                                            <inertial pos="0.0564089 0.000451402 -0.00101345" quat="-0.0107405 0.709374 0.00817312 0.704703" mass="0.681072" diaginertia="0.0122451 0.0120575 0.0113538"/>
                                            <joint name="r_wrist_roll_joint" pos="0 0 0" axis="1 0 0" damping="0.1"/>
                                            <geom type="mesh" mesh="wrist_roll_L"/>
                                            <geom type="mesh" rgba="0.8 0 0 1" mesh="gripper_palm"/>
                                            <geom size="0.0005 0.0005 0.0005" type="box"/>
                                            <body name="r_gripper_motor_slider_link" pos="0.16828 0 0">
                                                <inertial pos="0 0 0" mass="0.01" diaginertia="0.001 0.001 0.001"/>
                                                <joint name="r_gripper_motor_slider_joint" pos="0 0 0" axis="1 0 0" type="slide" range="-0.1 0.1"/>
                                                <body name="r_gripper_motor_screw_link">
                                                    <inertial pos="0 0 0" mass="0.01" diaginertia="0.0001 0.0001 0.0001"/>
                                                    <joint name="r_gripper_motor_screw_joint" pos="0 0 0" axis="0 1 0" damping="0.0001"/>
                                                </body>
                                            </body>
                                            <body name="r_gripper_l_finger_link" pos="0.07691 0.01 0">
                                                <inertial pos="0.03598 0.0173 -0.00164" quat="0.57444 0.429111 0.518782 0.465562" mass="0.17126" diaginertia="0.00019774 0.000181336 7.66239e-05"/>
                                                <joint name="r_gripper_l_finger_joint" pos="0 0 0" axis="0 0 1" range="0 0.548" damping="0.02"/>
                                                <geom type="mesh" rgba="0.7 0.7 0.7 1" mesh="l_finger"/>
                                                <body name="r_gripper_l_finger_tip_link" pos="0.09137 0.00495 0">
                                                    <inertial pos="0.00423 0.00284 0" quat="0.249588 0.661594 -0.249588 0.661594" mass="0.04419" diaginertia="1.54177e-05 1.50049e-05 3.23624e-06"/>
                                                    <joint name="r_gripper_l_finger_tip_joint" pos="0 0 0" axis="0 0 -1" range="0 0.548" damping="0.001"/>
                                                    <geom type="mesh" rgba="0 0.8 0 1" mesh="l_finger_tip"/>
                                                </body>
                                            </body>
                                            <body name="r_gripper_r_finger_link" pos="0.07691 -0.01 0">
                                                <inertial pos="0.03576 -0.01736 -0.00095" quat="0.474684 0.510909 0.446353 0.560727" mass="0.17389" diaginertia="0.000198903 0.00018134 7.66847e-05"/>
                                                <joint name="r_gripper_r_finger_joint" pos="0 0 0" axis="0 0 -1" range="0 0.548" damping="0.02"/>
                                                <geom quat="0 1 0 0" type="mesh" rgba="0.7 0.7 0.7 1" mesh="l_finger"/>
                                                <body name="r_gripper_r_finger_tip_link" pos="0.09137 -0.00495 0">
                                                    <inertial pos="0.00423 -0.00284 0" quat="-0.249588 0.661594 0.249588 0.661594" mass="0.04419" diaginertia="1.54177e-05 1.50049e-05 3.23624e-06"/>
                                                    <joint name="r_gripper_r_finger_tip_joint" pos="0 0 0" axis="0 0 1" range="0 0.548" damping="0.001"/>
                                                    <geom quat="0 1 0 0" type="mesh" rgba="0 0.8 0 1" mesh="l_finger_tip"/>
                                                    <body name="r_gripper_l_finger_tip_frame">
                                                        <joint name="r_gripper_joint" pos="0 0 0" axis="0 1 0" type="slide" range="0 0.09" damping="10"/>
                                                    </body>
                                                </body>
                                            </body>
                                        </body>
                                    </body>
                                </body>
                            </body>
                        </body>
                    </body>
                </body>
                <body name="l_shoulder_pan_link" pos="0 0.188 0">
                    <inertial pos="-0.001201 0.024513 -0.098231" quat="0.927482 -0.0876561 0.0740595 -0.355821" mass="25.7993" diaginertia="0.934201 0.837701 0.242033"/>
                    <joint name="l_shoulder_pan_joint" pos="0 0 0" axis="0 0 1" range="-0.714602 2.2854" damping="10"/>
                    <geom type="mesh" rgba="0 0 0.8 1" mesh="shoulder_pan"/>
                    <body name="l_shoulder_lift_link" pos="0.1 0 0">
                        <inertial pos="0.02195 -0.02664 -0.03127" quat="0.791779 0.478014 0.238985 0.295762" mass="2.74988" diaginertia="0.0261874 0.0207302 0.0151681"/>
                        <joint name="l_shoulder_lift_joint" pos="0 0 0" axis="0 1 0" range="-0.5236 1.3963" damping="10"/>
                        <geom type="mesh" rgba="0.7 0.7 0.7 1" mesh="shoulder_lift"/>
                        <body name="l_upper_arm_roll_link">
                            <inertial pos="0.210551 0.016309 -0.000560683" quat="-0.091509 0.708532 -0.0511954 0.697845" mass="6.11769" diaginertia="0.0906036 0.0894141 0.0251091"/>
                            <joint name="l_upper_arm_roll_joint" pos="0 0 0" axis="1 0 0" range="-0.8 3.9" damping="0.1"/>
                            <geom type="mesh" mesh="upper_arm_roll_L"/>
                            <geom type="mesh" rgba="0 0.8 0 1" mesh="upper_arm"/>
                            <body name="l_elbow_flex_link" pos="0.4 0 0">
                                <inertial pos="0.01014 0.00032 -0.01211" quat="0.308784 0.646797 0.639077 0.279083" mass="1.90327" diaginertia="0.00441852 0.00396477 0.00308977"/>
                                <joint name="l_elbow_flex_joint" pos="0 0 0" axis="0 1 0" range="-2.3213 0" damping="1"/>
                                <geom type="mesh" rgba="0.7 0.7 0.7 1" mesh="elbow_flex"/>
                                <body name="l_forearm_roll_link">
                                    <inertial pos="0.180727 -0.000163047 -0.00858341" quat="-0.000943818 0.72633 -0.00372954 0.687335" mass="2.68968" diaginertia="0.0310644 0.0295345 0.0146352"/>
                                    <joint name="l_forearm_roll_joint" pos="0 0 0" axis="1 0 0" damping="0.1"/>
                                    <geom type="mesh" mesh="forearm_roll_L"/>
                                    <geom type="mesh" rgba="0.7 0.7 0.7 1" mesh="forearm"/>
                                    <body name="l_wrist_flex_link" pos="0.321 0 0">
                                        <inertial pos="-0.00157 0 -0.00075" quat="0.695976 0.696411 -0.12356 0.123942" mass="0.61402" diaginertia="0.000652771 0.000643391 0.000198244"/>
                                        <joint name="l_wrist_flex_joint" pos="0 0 0" axis="0 1 0" range="-2.18 0" damping="0.1"/>
                                        <geom type="mesh" rgba="0.7 0.7 0.7 1" mesh="wrist_flex"/>
                                        <body name="l_wrist_roll_link">
                                            <inertial pos="0.0564089 0.000451402 -0.00101345" quat="-0.0107405 0.709374 0.00817312 0.704703" mass="0.681072" diaginertia="0.0122451 0.0120575 0.0113538"/>
                                            <joint name="l_wrist_roll_joint" pos="0 0 0" axis="1 0 0" damping="0.1"/>
                                            <geom type="mesh" mesh="wrist_roll_L"/>
                                            <geom type="mesh" rgba="0.8 0 0 1" mesh="gripper_palm"/>
                                            <geom size="0.0005 0.0005 0.0005" type="box"/>
                                            <body name="l_gripper_motor_slider_link" pos="0.16828 0 0">
                                                <inertial pos="0 0 0" mass="0.01" diaginertia="0.001 0.001 0.001"/>
                                                <joint name="l_gripper_motor_slider_joint" pos="0 0 0" axis="1 0 0" type="slide" range="-0.1 0.1"/>
                                                <body name="l_gripper_motor_screw_link">
                                                    <inertial pos="0 0 0" mass="0.01" diaginertia="0.0001 0.0001 0.0001"/>
                                                    <joint name="l_gripper_motor_screw_joint" pos="0 0 0" axis="0 1 0" damping="0.0001"/>
                                                </body>
                                            </body>
                                            <body name="l_gripper_l_finger_link" pos="0.07691 0.01 0">
                                                <inertial pos="0.03598 0.0173 -0.00164" quat="0.57444 0.429111 0.518782 0.465562" mass="0.17126" diaginertia="0.00019774 0.000181336 7.66239e-05"/>
                                                <joint name="l_gripper_l_finger_joint" pos="0 0 0" axis="0 0 1" range="0 0.548" damping="0.02"/>
                                                <geom type="mesh" rgba="0.7 0.7 0.7 1" mesh="l_finger"/>
                                                <body name="l_gripper_l_finger_tip_link" pos="0.09137 0.00495 0">
                                                    <inertial pos="0.00423 0.00284 0" quat="0.249588 0.661594 -0.249588 0.661594" mass="0.04419" diaginertia="1.54177e-05 1.50049e-05 3.23624e-06"/>
                                                    <joint name="l_gripper_l_finger_tip_joint" pos="0 0 0" axis="0 0 -1" range="0 0.548" damping="0.001"/>
                                                    <geom type="mesh" rgba="0 0.8 0 1" mesh="l_finger_tip"/>
                                                </body>
                                            </body>
                                            <body name="l_gripper_r_finger_link" pos="0.07691 -0.01 0">
                                                <inertial pos="0.03576 -0.01736 -0.00095" quat="0.474684 0.510909 0.446353 0.560727" mass="0.17389" diaginertia="0.000198903 0.00018134 7.66847e-05"/>
                                                <joint name="l_gripper_r_finger_joint" pos="0 0 0" axis="0 0 -1" range="0 0.548" damping="0.02"/>
                                                <geom quat="0 1 0 0" type="mesh" rgba="0.7 0.7 0.7 1" mesh="l_finger"/>
                                                <body name="l_gripper_r_finger_tip_link" pos="0.09137 -0.00495 0">
                                                    <inertial pos="0.00423 -0.00284 0" quat="-0.249588 0.661594 0.249588 0.661594" mass="0.04419" diaginertia="1.54177e-05 1.50049e-05 3.23624e-06"/>
                                                    <joint name="l_gripper_r_finger_tip_joint" pos="0 0 0" axis="0 0 1" range="0 0.548" damping="0.001"/>
                                                    <geom quat="0 1 0 0" type="mesh" rgba="0 0.8 0 1" mesh="l_finger_tip"/>
                                                    <body name="l_gripper_l_finger_tip_frame">
                                                        <joint name="l_gripper_joint" pos="0 0 0" axis="0 1 0" type="slide" range="0 0.09" damping="10"/>
                                                    </body>
                                                </body>
                                            </body>
                                        </body>
                                    </body>
                                </body>
                            </body>
                        </body>
                    </body>
                </body>
            </body>
            <body name="torso_lift_motor_screw_link" pos="-0.15 0 0.751">
                <inertial pos="0 0 0" mass="1" diaginertia="0.001 0.001 0.001"/>
                <joint name="torso_lift_motor_screw_joint" pos="0 0 0" axis="0 0 1" damping="0.0001"/>
            </body>
        </body>
    </worldbody>
    <equality>
        <joint joint1="l_gripper_l_finger_tip_joint" joint2="l_gripper_l_finger_joint" polycoef="0.000000 1.000000  0 0 0"/>
        <joint joint1="l_gripper_r_finger_joint" joint2="l_gripper_l_finger_joint" polycoef="0.000000 1.000000  0 0 0"/>
        <joint joint1="l_gripper_r_finger_tip_joint" joint2="l_gripper_l_finger_joint" polycoef="0.000000 1.000000  0 0 0"/>
        <joint joint1="r_gripper_l_finger_tip_joint" joint2="r_gripper_l_finger_joint" polycoef="0.000000 1.000000  0 0 0"/>
        <joint joint1="r_gripper_r_finger_joint" joint2="r_gripper_l_finger_joint" polycoef="0.000000 1.000000  0 0 0"/>
        <joint joint1="r_gripper_r_finger_tip_joint" joint2="r_gripper_l_finger_joint" polycoef="0.000000 1.000000  0 0 0"/>
    </equality>
    <contact>
        <exclude body1="pr2" body2="fl_caster_rotation_link"/>
        <exclude body1="fl_caster_rotation_link" body2="fl_caster_l_wheel_link"/>
        <exclude body1="fl_caster_rotation_link" body2="fl_caster_r_wheel_link"/>
        <exclude body1="pr2" body2="fr_caster_rotation_link"/>
        <exclude body1="fr_caster_rotation_link" body2="fr_caster_l_wheel_link"/>
        <exclude body1="fr_caster_rotation_link" body2="fr_caster_r_wheel_link"/>
        <exclude body1="pr2" body2="bl_caster_rotation_link"/>
        <exclude body1="bl_caster_rotation_link" body2="bl_caster_l_wheel_link"/>
        <exclude body1="bl_caster_rotation_link" body2="bl_caster_r_wheel_link"/>
        <exclude body1="pr2" body2="br_caster_rotation_link"/>
        <exclude body1="br_caster_rotation_link" body2="br_caster_l_wheel_link"/>
        <exclude body1="br_caster_rotation_link" body2="br_caster_r_wheel_link"/>
        <exclude body1="pr2" body2="torso_lift_link"/>
        <exclude body1="torso_lift_link" body2="head_pan_link"/>
        <exclude body1="head_pan_link" body2="head_tilt_link"/>
        <exclude body1="torso_lift_link" body2="laser_tilt_mount_link"/>
        <exclude body1="torso_lift_link" body2="r_shoulder_pan_link"/>
        <exclude body1="r_shoulder_pan_link" body2="r_shoulder_lift_link"/>
        <exclude body1="r_shoulder_lift_link" body2="r_upper_arm_roll_link"/>
        <exclude body1="r_upper_arm_roll_link" body2="r_elbow_flex_link"/>
        <exclude body1="r_elbow_flex_link" body2="r_forearm_roll_link"/>
        <exclude body1="r_forearm_roll_link" body2="r_wrist_flex_link"/>
        <exclude body1="r_wrist_flex_link" body2="r_wrist_roll_link"/>
        <exclude body1="r_wrist_roll_link" body2="r_gripper_motor_slider_link"/>
        <exclude body1="r_gripper_motor_slider_link" body2="r_gripper_motor_screw_link"/>
        <exclude body1="r_wrist_roll_link" body2="r_gripper_l_finger_link"/>
        <exclude body1="r_gripper_l_finger_link" body2="r_gripper_l_finger_tip_link"/>
        <exclude body1="r_wrist_roll_link" body2="r_gripper_r_finger_link"/>
        <exclude body1="r_gripper_r_finger_link" body2="r_gripper_r_finger_tip_link"/>
        <exclude body1="r_gripper_r_finger_tip_link" body2="r_gripper_l_finger_tip_frame"/>
        <exclude body1="torso_lift_link" body2="l_shoulder_pan_link"/>
        <exclude body1="l_shoulder_pan_link" body2="l_shoulder_lift_link"/>
        <exclude body1="l_shoulder_lift_link" body2="l_upper_arm_roll_link"/>
        <exclude body1="l_upper_arm_roll_link" body2="l_elbow_flex_link"/>
        <exclude body1="l_elbow_flex_link" body2="l_forearm_roll_link"/>
        <exclude body1="l_forearm_roll_link" body2="l_wrist_flex_link"/>
        <exclude body1="l_wrist_flex_link" body2="l_wrist_roll_link"/>
        <exclude body1="l_wrist_roll_link" body2="l_gripper_motor_slider_link"/>
        <exclude body1="l_gripper_motor_slider_link" body2="l_gripper_motor_screw_link"/>
        <exclude body1="l_wrist_roll_link" body2="l_gripper_l_finger_link"/>
        <exclude body1="l_gripper_l_finger_link" body2="l_gripper_l_finger_tip_link"/>
        <exclude body1="l_wrist_roll_link" body2="l_gripper_r_finger_link"/>
        <exclude body1="l_gripper_r_finger_link" body2="l_gripper_r_finger_tip_link"/>
        <exclude body1="l_gripper_r_finger_tip_link" body2="l_gripper_l_finger_tip_frame"/>
        <exclude body1="pr2" body2="torso_lift_motor_screw_link"/>
    </contact>
</mujoco>
