<sdf version="1.6">
  <model name="mir_100">
    <link name="base_footprint">
      <pose frame="">0 0 0 0 -0 0</pose>
      <inertial>
        <pose frame="">0.037604 1.9e-05 0.199445 0 -0 0</pose>
        <mass>62</mass>
        <inertia>
          <ixx>2.30252</ixx>
          <ixy>-0.369127</ixy>
          <ixz>-2.07887e-05</ixz>
          <iyy>4.98377</iyy>
          <iyz>9.65419e-06</iyz>
          <izz>6.39292</izz>
        </inertia>
      </inertial>
      <collision name="base_footprint_fixed_joint_lump__base_link_collision">
        <pose frame="">0.037646 0 0 0 -0 0</pose>
        <geometry>
          <mesh>
            <scale>1 1 1</scale>
            <uri>model://meshes/collision/mir_100_base.fbx</uri>
          </mesh>
        </geometry>
        <surface>
          <contact>
            <ode/>
          </contact>
          <friction>
            <ode/>
          </friction>
        </surface>
      </collision>
      <collision name="base_footprint_fixed_joint_lump__back_laser_link_collision_1">
        <pose frame="">-0.3548 -0.2352 0.1914 -3.14159 -0 -2.35619</pose>
        <geometry>
          <mesh>
            <scale>1 1 1</scale>
            <uri>model://meshes/visual/sick_lms-100.fbx</uri>
          </mesh>
        </geometry>
        <surface>
          <contact>
            <ode/>
          </contact>
          <friction>
            <ode/>
          </friction>
        </surface>
      </collision>
      <collision name="base_footprint_fixed_joint_lump__front_laser_link_collision_2">
        <pose frame="">0.4288 0.2358 0.1914 -3.14159 -0 0.785398</pose>
        <geometry>
          <mesh>
            <scale>1 1 1</scale>
            <uri>model://meshes/visual/sick_lms-100.fbx</uri>
          </mesh>
        </geometry>
        <surface>
          <contact>
            <ode/>
          </contact>
          <friction>
            <ode/>
          </friction>
        </surface>
      </collision>
      <collision name="base_footprint_fixed_joint_lump__camera_link_collision_3">
        <pose frame="">-0.020996 0.225017 0.413 0 -0 1.57</pose>
        <geometry>
          <box>
            <size>0.015 0.03 0.027</size>
          </box>
        </geometry>
      </collision>
      <visual name="base_footprint_fixed_joint_lump__base_link_visual">
        <pose frame="">0.037646 0 0 0 -0 0</pose>
        <geometry>
          <mesh>
            <scale>1 1 1</scale>
            <uri>model://meshes/visual/mir_100_base.fbx</uri>
          </mesh>
        </geometry>
        <material>
          <script>
            <name>Gazebo/White</name>
            <uri>file://media/materials/scripts/gazebo.material</uri>
          </script>
        </material>
      </visual>
      <visual name="base_footprint_fixed_joint_lump__back_laser_link_visual_1">
        <pose frame="">-0.3548 -0.2352 0.1914 -3.14159 -0 -2.35619</pose>
        <geometry>
          <mesh>
            <scale>1 1 1</scale>
            <uri>model://meshes/visual/sick_lms-100.fbx</uri>
          </mesh>
        </geometry>
        <material>
          <script>
            <name>Gazebo/FlatBlack</name>
            <uri>file://media/materials/scripts/gazebo.material</uri>
          </script>
        </material>
      </visual>
      <visual name="base_footprint_fixed_joint_lump__front_laser_link_visual_2">
        <pose frame="">0.4288 0.2358 0.1914 -3.14159 -0 0.785398</pose>
        <geometry>
          <mesh>
            <scale>1 1 1</scale>
            <uri>model://meshes/visual/sick_lms-100.fbx</uri>
          </mesh>
        </geometry>
        <material>
          <script>
            <name>Gazebo/FlatBlack</name>
            <uri>file://media/materials/scripts/gazebo.material</uri>
          </script>
        </material>
      </visual>
      <velocity_decay/>
      <velocity_decay/>
      <sensor name="back_laser_link" type="ray">
        <visualize>0</visualize>
        <update_rate>12.5</update_rate>
        <ray>
          <scan>
            <horizontal>
              <samples>541</samples>
              <resolution>1</resolution>
              <min_angle>-2.35619</min_angle>
              <max_angle>2.35619</max_angle>
            </horizontal>
          </scan>
          <range>
            <min>0.05</min>
            <max>29</max>
            <resolution>0.01</resolution>
          </range>
          <noise>
            <type>gaussian</type>
            <mean>0</mean>
            <stddev>0.01</stddev>
          </noise>
        </ray>
        <plugin name="gazebo_ros_back_laser_link_controller" filename="libgazebo_ros_laser.so">
          <frameName>back_laser_link</frameName>
          <topicName>b_scan</topicName>
        </plugin>
        <pose frame="">-0.3548 -0.2352 0.1914 -3.14159 -0 -2.35619</pose>
      </sensor>
      <velocity_decay/>
      <sensor name="front_laser_link" type="ray">
        <visualize>0</visualize>
        <update_rate>12.5</update_rate>
        <ray>
          <scan>
            <horizontal>
              <samples>541</samples>
              <resolution>1</resolution>
              <min_angle>-2.35619</min_angle>
              <max_angle>2.35619</max_angle>
            </horizontal>
          </scan>
          <range>
            <min>0.05</min>
            <max>29</max>
            <resolution>0.01</resolution>
          </range>
          <noise>
            <type>gaussian</type>
            <mean>0</mean>
            <stddev>0.01</stddev>
          </noise>
        </ray>
        <plugin name="gazebo_ros_front_laser_link_controller" filename="libgazebo_ros_laser.so">
          <frameName>front_laser_link</frameName>
          <topicName>f_scan</topicName>
        </plugin>
        <pose frame="">0.4288 0.2358 0.1914 -3.14159 -0 0.785398</pose>
      </sensor>
      <velocity_decay/>
      <gravity>1</gravity>
      <sensor name="imu_sensor" type="imu">
        <always_on>1</always_on>
        <update_rate>100</update_rate>
        <visualize>1</visualize>
        <topic>__default_topic__</topic>
        <plugin name="imu_plugin" filename="libgazebo_ros_imu_sensor.so">
          <topicName>imu_data</topicName>
          <bodyName>imu_link</bodyName>
          <updateRateHZ>50.0</updateRateHZ>
          <gaussianNoise>2.89e-08</gaussianNoise>
          <xyzOffset>0 0 0</xyzOffset>
          <rpyOffset>0 0 0</rpyOffset>
          <frameName>imu_frame</frameName>
        </plugin>
        <pose frame="">0 0 0.25 0 -0 0</pose>
      </sensor>
      <gravity>1</gravity>
      <velocity_decay/>
      <sensor name="Simple Camera" type="camera">
        <always_on>1</always_on>
        <visualize>1</visualize>
        <camera name="__default__">
          <horizontal_fov>1.0856</horizontal_fov>
          <image>
            <width>640</width>
            <height>480</height>
            <format>R8G8B8</format>
          </image>
          <clip>
            <near>0.03</near>
            <far>100</far>
          </clip>
        </camera>
        <plugin name="camera_controller" filename="libgazebo_ros_camera.so">
          <alwaysOn>1</alwaysOn>
          <updateRate>30.0</updateRate>
          <cameraName>camera</cameraName>
          <frameName>camera_rgb_optical_frame</frameName>
          <imageTopicName>image</imageTopicName>
          <cameraInfoTopicName>camera_info</cameraInfoTopicName>
          <hackBaseline>0.07</hackBaseline>
          <distortionK1>0.0</distortionK1>
          <distortionK2>0.0</distortionK2>
          <distortionK3>0.0</distortionK3>
          <distortionT1>0.0</distortionT1>
          <distortionT2>0.0</distortionT2>
        </plugin>
        <pose frame="">-0.020998 0.223017 0.409 0 -0 1.57</pose>
      </sensor>
    </link>
    <link name="bl_caster_rotation_link">
      <pose frame="">-0.270154 0.203 0.1565 0 -0 0</pose>
      <inertial>
        <pose frame="">0 0 -0.0425 0.418879 0 1.5708</pose>
        <mass>0.309754</mass>
        <inertia>
          <ixx>0.000584452</ixx>
          <ixy>0</ixy>
          <ixz>0</ixz>
          <iyy>0.000528726</iyy>
          <iyz>0</iyz>
          <izz>0.000179236</izz>
        </inertia>
      </inertial>
      <collision name="bl_caster_rotation_link_collision">
        <pose frame="">0 0 0 0 -0 0</pose>
        <geometry>
          <mesh>
            <scale>1 1 1</scale>
            <uri>model://meshes/collision/caster_wheel_base.fbx</uri>
          </mesh>
        </geometry>
        <surface>
          <contact>
            <ode/>
          </contact>
          <friction>
            <ode/>
          </friction>
        </surface>
      </collision>
      <visual name="bl_caster_rotation_link_visual">
        <pose frame="">0 0 0 0 -0 0</pose>
        <geometry>
          <mesh>
            <scale>1 1 1</scale>
            <uri>model://meshes/visual/caster_wheel_base.fbx</uri>
          </mesh>
        </geometry>
        <material>
          <script>
            <name>Gazebo/Grey</name>
            <uri>file://media/materials/scripts/gazebo.material</uri>
          </script>
        </material>
      </visual>
      <gravity>1</gravity>
      <velocity_decay/>
    </link>
    <joint name="bl_caster_rotation_joint" type="revolute">
      <child>bl_caster_rotation_link</child>
      <parent>base_footprint</parent>
      <axis>
        <xyz>0 0 1</xyz>
        <limit>
          <lower>-1e+16</lower>
          <upper>1e+16</upper>
        </limit>
        <dynamics>
          <damping>0.01</damping>
          <friction>0</friction>
          <spring_reference>0</spring_reference>
          <spring_stiffness>0</spring_stiffness>
        </dynamics>
        <use_parent_model_frame>1</use_parent_model_frame>
      </axis>
    </joint>
    <link name="bl_caster_wheel_link">
      <pose frame="">-0.308354 0.203 0.0625 0 -0 0</pose>
      <inertial>
        <pose frame="">0 0 0 1.5708 -0 0</pose>
        <mass>1</mass>
        <inertia>
          <ixx>0.0010619</ixx>
          <ixy>0</ixy>
          <ixz>0</ixz>
          <iyy>0.0010619</iyy>
          <iyz>0</iyz>
          <izz>0.00195312</izz>
        </inertia>
      </inertial>
      <collision name="bl_caster_wheel_link_collision">
        <pose frame="">0 0 0 0 -0 0</pose>
        <geometry>
          <mesh>
            <scale>1 1 1</scale>
            <uri>model://meshes/visual/wheel.fbx</uri>
          </mesh>
        </geometry>
        <surface>
          <contact>
            <ode>
              <kp>1e+07</kp>
              <kd>1</kd>
              <min_depth>0.01</min_depth>
            </ode>
          </contact>
          <friction>
            <ode>
              <mu>1</mu>
              <mu2>1</mu2>
            </ode>
          </friction>
        </surface>
      </collision>
      <visual name="bl_caster_wheel_link_visual">
        <pose frame="">0 0 0 0 -0 0</pose>
        <geometry>
          <mesh>
            <scale>1 1 1</scale>
            <uri>model://meshes/visual/wheel.fbx</uri>
          </mesh>
        </geometry>
        <material>
          <script>
            <name>Gazebo/DarkGrey</name>
            <uri>file://media/materials/scripts/gazebo.material</uri>
          </script>
        </material>
      </visual>
      <velocity_decay/>
      <gravity>1</gravity>
      <velocity_decay/>
    </link>
    <joint name="bl_caster_wheel_joint" type="revolute">
      <child>bl_caster_wheel_link</child>
      <parent>bl_caster_rotation_link</parent>
      <axis>
        <xyz>0 1 0</xyz>
        <limit>
          <lower>-1e+16</lower>
          <upper>1e+16</upper>
        </limit>
        <dynamics>
          <spring_reference>0</spring_reference>
          <spring_stiffness>0</spring_stiffness>
        </dynamics>
        <use_parent_model_frame>1</use_parent_model_frame>
      </axis>
    </joint>
    <link name="br_caster_rotation_link">
      <pose frame="">-0.270154 -0.203 0.1565 0 -0 0</pose>
      <inertial>
        <pose frame="">0 0 -0.0425 0.418879 0 1.5708</pose>
        <mass>0.309754</mass>
        <inertia>
          <ixx>0.000584452</ixx>
          <ixy>0</ixy>
          <ixz>0</ixz>
          <iyy>0.000528726</iyy>
          <iyz>0</iyz>
          <izz>0.000179236</izz>
        </inertia>
      </inertial>
      <collision name="br_caster_rotation_link_collision">
        <pose frame="">0 0 0 0 -0 0</pose>
        <geometry>
          <mesh>
            <scale>1 1 1</scale>
            <uri>model://meshes/collision/caster_wheel_base.fbx</uri>
          </mesh>
        </geometry>
        <surface>
          <contact>
            <ode/>
          </contact>
          <friction>
            <ode/>
          </friction>
        </surface>
      </collision>
      <visual name="br_caster_rotation_link_visual">
        <pose frame="">0 0 0 0 -0 0</pose>
        <geometry>
          <mesh>
            <scale>1 1 1</scale>
            <uri>model://meshes/visual/caster_wheel_base.fbx</uri>
          </mesh>
        </geometry>
        <material>
          <script>
            <name>Gazebo/Grey</name>
            <uri>file://media/materials/scripts/gazebo.material</uri>
          </script>
        </material>
      </visual>
      <gravity>1</gravity>
      <velocity_decay/>
    </link>
    <joint name="br_caster_rotation_joint" type="revolute">
      <child>br_caster_rotation_link</child>
      <parent>base_footprint</parent>
      <axis>
        <xyz>0 0 1</xyz>
        <limit>
          <lower>-1e+16</lower>
          <upper>1e+16</upper>
        </limit>
        <dynamics>
          <damping>0.01</damping>
          <friction>0</friction>
          <spring_reference>0</spring_reference>
          <spring_stiffness>0</spring_stiffness>
        </dynamics>
        <use_parent_model_frame>1</use_parent_model_frame>
      </axis>
    </joint>
    <link name="br_caster_wheel_link">
      <pose frame="">-0.308354 -0.203 0.0625 0 -0 0</pose>
      <inertial>
        <pose frame="">0 0 0 1.5708 -0 0</pose>
        <mass>1</mass>
        <inertia>
          <ixx>0.0010619</ixx>
          <ixy>0</ixy>
          <ixz>0</ixz>
          <iyy>0.0010619</iyy>
          <iyz>0</iyz>
          <izz>0.00195312</izz>
        </inertia>
      </inertial>
      <collision name="br_caster_wheel_link_collision">
        <pose frame="">0 0 0 0 -0 0</pose>
        <geometry>
          <mesh>
            <scale>1 1 1</scale>
            <uri>model://meshes/visual/wheel.fbx</uri>
          </mesh>
        </geometry>
        <surface>
          <contact>
            <ode>
              <kp>1e+07</kp>
              <kd>1</kd>
              <min_depth>0.01</min_depth>
            </ode>
          </contact>
          <friction>
            <ode>
              <mu>1</mu>
              <mu2>1</mu2>
            </ode>
          </friction>
        </surface>
      </collision>
      <visual name="br_caster_wheel_link_visual">
        <pose frame="">0 0 0 0 -0 0</pose>
        <geometry>
          <mesh>
            <scale>1 1 1</scale>
            <uri>model://meshes/visual/wheel.fbx</uri>
          </mesh>
        </geometry>
        <material>
          <script>
            <name>Gazebo/DarkGrey</name>
            <uri>file://media/materials/scripts/gazebo.material</uri>
          </script>
        </material>
      </visual>
      <velocity_decay/>
      <gravity>1</gravity>
      <velocity_decay/>
    </link>
    <joint name="br_caster_wheel_joint" type="revolute">
      <child>br_caster_wheel_link</child>
      <parent>br_caster_rotation_link</parent>
      <axis>
        <xyz>0 1 0</xyz>
        <limit>
          <lower>-1e+16</lower>
          <upper>1e+16</upper>
        </limit>
        <dynamics>
          <spring_reference>0</spring_reference>
          <spring_stiffness>0</spring_stiffness>
        </dynamics>
        <use_parent_model_frame>1</use_parent_model_frame>
      </axis>
    </joint>
    <link name="fl_caster_rotation_link">
      <pose frame="">0.341346 0.203 0.1565 0 -0 0</pose>
      <inertial>
        <pose frame="">0 0 -0.0425 0.418879 0 1.5708</pose>
        <mass>0.309754</mass>
        <inertia>
          <ixx>0.000584452</ixx>
          <ixy>0</ixy>
          <ixz>0</ixz>
          <iyy>0.000528726</iyy>
          <iyz>0</iyz>
          <izz>0.000179236</izz>
        </inertia>
      </inertial>
      <collision name="fl_caster_rotation_link_collision">
        <pose frame="">0 0 0 0 -0 0</pose>
        <geometry>
          <mesh>
            <scale>1 1 1</scale>
            <uri>model://meshes/collision/caster_wheel_base.fbx</uri>
          </mesh>
        </geometry>
        <surface>
          <contact>
            <ode/>
          </contact>
          <friction>
            <ode/>
          </friction>
        </surface>
      </collision>
      <visual name="fl_caster_rotation_link_visual">
        <pose frame="">0 0 0 0 -0 0</pose>
        <geometry>
          <mesh>
            <scale>1 1 1</scale>
            <uri>model://meshes/visual/caster_wheel_base.fbx</uri>
          </mesh>
        </geometry>
        <material>
          <script>
            <name>Gazebo/Grey</name>
            <uri>file://media/materials/scripts/gazebo.material</uri>
          </script>
        </material>
      </visual>
      <gravity>1</gravity>
      <velocity_decay/>
    </link>
    <joint name="fl_caster_rotation_joint" type="revolute">
      <child>fl_caster_rotation_link</child>
      <parent>base_footprint</parent>
      <axis>
        <xyz>0 0 1</xyz>
        <limit>
          <lower>-1e+16</lower>
          <upper>1e+16</upper>
        </limit>
        <dynamics>
          <damping>0.01</damping>
          <friction>0</friction>
          <spring_reference>0</spring_reference>
          <spring_stiffness>0</spring_stiffness>
        </dynamics>
        <use_parent_model_frame>1</use_parent_model_frame>
      </axis>
    </joint>
    <link name="fl_caster_wheel_link">
      <pose frame="">0.303146 0.203 0.0625 0 -0 0</pose>
      <inertial>
        <pose frame="">0 0 0 1.5708 -0 0</pose>
        <mass>1</mass>
        <inertia>
          <ixx>0.0010619</ixx>
          <ixy>0</ixy>
          <ixz>0</ixz>
          <iyy>0.0010619</iyy>
          <iyz>0</iyz>
          <izz>0.00195312</izz>
        </inertia>
      </inertial>
      <collision name="fl_caster_wheel_link_collision">
        <pose frame="">0 0 0 0 -0 0</pose>
        <geometry>
          <mesh>
            <scale>1 1 1</scale>
            <uri>model://meshes/visual/wheel.fbx</uri>
          </mesh>
        </geometry>
        <surface>
          <contact>
            <ode>
              <kp>1e+07</kp>
              <kd>1</kd>
              <min_depth>0.01</min_depth>
            </ode>
          </contact>
          <friction>
            <ode>
              <mu>1</mu>
              <mu2>1</mu2>
            </ode>
          </friction>
        </surface>
      </collision>
      <visual name="fl_caster_wheel_link_visual">
        <pose frame="">0 0 0 0 -0 0</pose>
        <geometry>
          <mesh>
            <scale>1 1 1</scale>
            <uri>model://meshes/visual/wheel.fbx</uri>
          </mesh>
        </geometry>
        <material>
          <script>
            <name>Gazebo/DarkGrey</name>
            <uri>file://media/materials/scripts/gazebo.material</uri>
          </script>
        </material>
      </visual>
      <velocity_decay/>
      <gravity>1</gravity>
      <velocity_decay/>
    </link>
    <joint name="fl_caster_wheel_joint" type="revolute">
      <child>fl_caster_wheel_link</child>
      <parent>fl_caster_rotation_link</parent>
      <axis>
        <xyz>0 1 0</xyz>
        <limit>
          <lower>-1e+16</lower>
          <upper>1e+16</upper>
        </limit>
        <dynamics>
          <spring_reference>0</spring_reference>
          <spring_stiffness>0</spring_stiffness>
        </dynamics>
        <use_parent_model_frame>1</use_parent_model_frame>
      </axis>
    </joint>
    <link name="fr_caster_rotation_link">
      <pose frame="">0.341346 -0.203 0.1565 0 -0 0</pose>
      <inertial>
        <pose frame="">0 0 -0.0425 0.418879 0 1.5708</pose>
        <mass>0.309754</mass>
        <inertia>
          <ixx>0.000584452</ixx>
          <ixy>0</ixy>
          <ixz>0</ixz>
          <iyy>0.000528726</iyy>
          <iyz>0</iyz>
          <izz>0.000179236</izz>
        </inertia>
      </inertial>
      <collision name="fr_caster_rotation_link_collision">
        <pose frame="">0 0 0 0 -0 0</pose>
        <geometry>
          <mesh>
            <scale>1 1 1</scale>
            <uri>model://meshes/collision/caster_wheel_base.fbx</uri>
          </mesh>
        </geometry>
        <surface>
          <contact>
            <ode/>
          </contact>
          <friction>
            <ode/>
          </friction>
        </surface>
      </collision>
      <visual name="fr_caster_rotation_link_visual">
        <pose frame="">0 0 0 0 -0 0</pose>
        <geometry>
          <mesh>
            <scale>1 1 1</scale>
            <uri>model://meshes/visual/caster_wheel_base.fbx</uri>
          </mesh>
        </geometry>
        <material>
          <script>
            <name>Gazebo/Grey</name>
            <uri>file://media/materials/scripts/gazebo.material</uri>
          </script>
        </material>
      </visual>
      <gravity>1</gravity>
      <velocity_decay/>
    </link>
    <joint name="fr_caster_rotation_joint" type="revolute">
      <child>fr_caster_rotation_link</child>
      <parent>base_footprint</parent>
      <axis>
        <xyz>0 0 1</xyz>
        <limit>
          <lower>-1e+16</lower>
          <upper>1e+16</upper>
        </limit>
        <dynamics>
          <damping>0.01</damping>
          <friction>0</friction>
          <spring_reference>0</spring_reference>
          <spring_stiffness>0</spring_stiffness>
        </dynamics>
        <use_parent_model_frame>1</use_parent_model_frame>
      </axis>
    </joint>
    <link name="fr_caster_wheel_link">
      <pose frame="">0.303146 -0.203 0.0625 0 -0 0</pose>
      <inertial>
        <pose frame="">0 0 0 1.5708 -0 0</pose>
        <mass>1</mass>
        <inertia>
          <ixx>0.0010619</ixx>
          <ixy>0</ixy>
          <ixz>0</ixz>
          <iyy>0.0010619</iyy>
          <iyz>0</iyz>
          <izz>0.00195312</izz>
        </inertia>
      </inertial>
      <collision name="fr_caster_wheel_link_collision">
        <pose frame="">0 0 0 0 -0 0</pose>
        <geometry>
          <mesh>
            <scale>1 1 1</scale>
            <uri>model://meshes/visual/wheel.fbx</uri>
          </mesh>
        </geometry>
        <surface>
          <contact>
            <ode>
              <kp>1e+07</kp>
              <kd>1</kd>
              <min_depth>0.01</min_depth>
            </ode>
          </contact>
          <friction>
            <ode>
              <mu>1</mu>
              <mu2>1</mu2>
            </ode>
          </friction>
        </surface>
      </collision>
      <visual name="fr_caster_wheel_link_visual">
        <pose frame="">0 0 0 0 -0 0</pose>
        <geometry>
          <mesh>
            <scale>1 1 1</scale>
            <uri>model://meshes/visual/wheel.fbx</uri>
          </mesh>
        </geometry>
        <material>
          <script>
            <name>Gazebo/DarkGrey</name>
            <uri>file://media/materials/scripts/gazebo.material</uri>
          </script>
        </material>
      </visual>
      <velocity_decay/>
      <gravity>1</gravity>
      <velocity_decay/>
    </link>
    <joint name="fr_caster_wheel_joint" type="revolute">
      <child>fr_caster_wheel_link</child>
      <parent>fr_caster_rotation_link</parent>
      <axis>
        <xyz>0 1 0</xyz>
        <limit>
          <lower>-1e+16</lower>
          <upper>1e+16</upper>
        </limit>
        <dynamics>
          <spring_reference>0</spring_reference>
          <spring_stiffness>0</spring_stiffness>
        </dynamics>
        <use_parent_model_frame>1</use_parent_model_frame>
      </axis>
    </joint>
    <link name="left_wheel_link">
      <pose frame="">0 0.222604 0.0625 0 -0 0</pose>
      <inertial>
        <pose frame="">0 0 0 1.5708 -0 0</pose>
        <mass>1</mass>
        <inertia>
          <ixx>0.0010619</ixx>
          <ixy>0</ixy>
          <ixz>0</ixz>
          <iyy>0.0010619</iyy>
          <iyz>0</iyz>
          <izz>0.00195312</izz>
        </inertia>
      </inertial>
      <collision name="left_wheel_link_collision">
        <pose frame="">0 0 0 0 -0 0</pose>
        <geometry>
          <mesh>
            <scale>1 1 1</scale>
            <uri>model://meshes/visual/wheel.fbx</uri>
          </mesh>
        </geometry>
        <surface>
          <contact>
            <ode>
              <kp>1e+07</kp>
              <kd>1</kd>
              <min_depth>0.01</min_depth>
            </ode>
          </contact>
          <friction>
            <ode>
              <mu>200</mu>
              <mu2>200</mu2>
            </ode>
          </friction>
        </surface>
      </collision>
      <visual name="left_wheel_link_visual">
        <pose frame="">0 0 0 0 -0 0</pose>
        <geometry>
          <mesh>
            <scale>1 1 1</scale>
            <uri>model://meshes/visual/wheel.fbx</uri>
          </mesh>
        </geometry>
        <material>
          <script>
            <name>Gazebo/DarkGrey</name>
            <uri>file://media/materials/scripts/gazebo.material</uri>
          </script>
        </material>
      </visual>
      <velocity_decay/>
      <gravity>1</gravity>
      <velocity_decay/>
    </link>
    <joint name="left_wheel_joint" type="revolute">
      <child>left_wheel_link</child>
      <parent>base_footprint</parent>
      <axis>
        <xyz>0 1 0</xyz>
        <limit>
          <lower>-1e+16</lower>
          <upper>1e+16</upper>
        </limit>
        <dynamics>
          <spring_reference>0</spring_reference>
          <spring_stiffness>0</spring_stiffness>
        </dynamics>
        <use_parent_model_frame>1</use_parent_model_frame>
      </axis>
    </joint>
    <link name="right_wheel_link">
      <pose frame="">0 -0.222604 0.0625 0 -0 0</pose>
      <inertial>
        <pose frame="">0 0 0 1.5708 -0 0</pose>
        <mass>1</mass>
        <inertia>
          <ixx>0.0010619</ixx>
          <ixy>0</ixy>
          <ixz>0</ixz>
          <iyy>0.0010619</iyy>
          <iyz>0</iyz>
          <izz>0.00195312</izz>
        </inertia>
      </inertial>
      <collision name="right_wheel_link_collision">
        <pose frame="">0 0 0 0 -0 0</pose>
        <geometry>
          <mesh>
            <scale>1 1 1</scale>
            <uri>model://meshes/visual/wheel.fbx</uri>
          </mesh>
        </geometry>
        <surface>
          <contact>
            <ode>
              <kp>1e+07</kp>
              <kd>1</kd>
              <min_depth>0.01</min_depth>
            </ode>
          </contact>
          <friction>
            <ode>
              <mu>200</mu>
              <mu2>200</mu2>
            </ode>
          </friction>
        </surface>
      </collision>
      <visual name="right_wheel_link_visual">
        <pose frame="">0 0 0 0 -0 0</pose>
        <geometry>
          <mesh>
            <scale>1 1 1</scale>
            <uri>model://meshes/visual/wheel.fbx</uri>
          </mesh>
        </geometry>
        <material>
          <script>
            <name>Gazebo/DarkGrey</name>
            <uri>file://media/materials/scripts/gazebo.material</uri>
          </script>
        </material>
      </visual>
      <velocity_decay/>
      <gravity>1</gravity>
      <velocity_decay/>
    </link>
    <joint name="right_wheel_joint" type="revolute">
      <child>right_wheel_link</child>
      <parent>base_footprint</parent>
      <axis>
        <xyz>0 1 0</xyz>
        <limit>
          <lower>-1e+16</lower>
          <upper>1e+16</upper>
        </limit>
        <dynamics>
          <spring_reference>0</spring_reference>
          <spring_stiffness>0</spring_stiffness>
        </dynamics>
        <use_parent_model_frame>1</use_parent_model_frame>
      </axis>
    </joint>
    <plugin name="p3d_base_controller" filename="libgazebo_ros_p3d.so">
      <alwaysOn>1</alwaysOn>
      <updateRate>50.0</updateRate>
      <bodyName>base_footprint</bodyName>
      <topicName>base_pose_ground_truth</topicName>
      <gaussianNoise>0.01</gaussianNoise>
      <frameName>map</frameName>
      <xyzOffsets>0 0 0</xyzOffsets>
      <rpyOffsets>0 0 0</rpyOffsets>
    </plugin>
    <static>0</static>
    <plugin name="gazebo_ros_control" filename="libgazebo_ros_control.so">
      <controlPeriod>0.001</controlPeriod>
      <legacyModeNS>0</legacyModeNS>
    </plugin>
  </model>
</sdf>
