<?xml version="1.0"?>
<!-- created with Phobos 1.0.1 "Capricious Choutengan" -->
  <robot name="roll_container">

    <link name="back_stabilizer">
      <inertial>
        <origin xyz="0 0 0" rpy="0 0 0"/>
        <mass value="0.1"/>
        <inertia ixx="5e-05" ixy="0" ixz="0" iyy="0.00038" iyz="0" izz="0.00032"/>
      </inertial>
      <visual name="visual_back_stabilizer">
        <origin xyz="0 0 0" rpy="0 0 0"/>
        <geometry>
          <mesh filename="package://roll_container_description/meshes/stl/Part__Feature167.stl" scale="1.0 1.0 1.0"/>
        </geometry>
        <material name="back_stabilizer"/>
      </visual>
      <collision name="collision_back_stabilizer_1">
        <origin xyz="0 0.00014 0.14752" rpy="0 1.5708 0"/>
        <geometry>
          <cylinder radius="0.01072" length="0.64768"/>
        </geometry>
      </collision>
      <collision name="collision_back_stabilizer_2">
        <origin xyz="0.3151 -0.00054 -0.02707" rpy="0 0 0"/>
        <geometry>
          <cylinder radius="0.01072" length="0.35586"/>
        </geometry>
      </collision>
      <collision name="collision_back_stabilizer_3">
        <origin xyz="-0.3151 -0.00054 -0.02706" rpy="0 0 0"/>
        <geometry>
          <cylinder radius="0.01072" length="0.35586"/>
        </geometry>
      </collision>
    </link>

    <link name="castor_rigit_left">
      <inertial>
        <origin xyz="0 0 0" rpy="0 0 0"/>
        <mass value="0.05"/>
        <inertia ixx="2e-05" ixy="0" ixz="0" iyy="2e-05" iyz="0" izz="2e-05"/>
      </inertial>
      <visual name="visual_castor_rigit_left_fork">
        <origin xyz="0 0 0" rpy="0 0 0"/>
        <geometry>
          <mesh filename="package://roll_container_description/meshes/stl/Part__Feature082.stl" scale="1.0 1.0 1.0"/>
        </geometry>
        <material name="metal"/>
      </visual>
      <collision name="collision_castor_rigit_left_fork">
        <origin xyz="-0.00018 0 -0.01474" rpy="0 0 0"/>
        <geometry>
          <box size="0.086 0.1015 0.089"/>
        </geometry>
      </collision>
    </link>

    <link name="castor_rigit_left_wheel">
      <inertial>
        <origin xyz="0 0 0" rpy="0 0 0"/>
        <mass value="0.25"/>
        <inertia ixx="3e-05" ixy="0" ixz="0" iyy="2e-05" iyz="0" izz="2e-05"/>
      </inertial>
      <visual name="visual_castor_rigit_left_wheel">
        <origin xyz="0 0 0" rpy="0 -1.5708 0"/>
        <geometry>
          <mesh filename="package://roll_container_description/meshes/stl/Part__Feature066.stl" scale="1.0 1.0 1.0"/>
        </geometry>
        <material name="wheel"/>
      </visual>
      <collision name="collision_castor_rigit_left_wheel">
        <origin xyz="-5e-05 0 0" rpy="0 0 0"/>
        <geometry>
          <cylinder radius="0.0495" length="0.03989"/>
        </geometry>
      </collision>
    </link>

    <link name="castor_rigit_right">
      <inertial>
        <origin xyz="0 0 0" rpy="0 0 0"/>
        <mass value="0.05"/>
        <inertia ixx="2e-05" ixy="0" ixz="0" iyy="2e-05" iyz="0" izz="2e-05"/>
      </inertial>
      <visual name="visual_castor_rigit_right_fork">
        <origin xyz="0 0 0" rpy="0 0 0"/>
        <geometry>
          <mesh filename="package://roll_container_description/meshes/stl/Part__Feature099.stl" scale="1.0 1.0 1.0"/>
        </geometry>
        <material name="metal"/>
      </visual>
      <collision name="collision_castor_rigit_right_fork">
        <origin xyz="-0.00018 0 -0.01474" rpy="0 0 0"/>
        <geometry>
          <box size="0.086 0.1015 0.089"/>
        </geometry>
      </collision>
    </link>

    <link name="castor_rigit_right_wheel">
      <inertial>
        <origin xyz="0 0 0" rpy="0 0 0"/>
        <mass value="0.25"/>
        <inertia ixx="3e-05" ixy="0" ixz="0" iyy="2e-05" iyz="0" izz="2e-05"/>
      </inertial>
      <visual name="visual_castor_rigit_right_wheel">
        <origin xyz="0 0 0" rpy="0 -1.5708 0"/>
        <geometry>
          <mesh filename="package://roll_container_description/meshes/stl/Part__Feature083.stl" scale="1.0 1.0 1.0"/>
        </geometry>
        <material name="wheel"/>
      </visual>
      <collision name="collision_castor_rigit_right_wheel">
        <origin xyz="-5e-05 0 0" rpy="0 0 0"/>
        <geometry>
          <cylinder radius="0.0495" length="0.03989"/>
        </geometry>
      </collision>
    </link>

    <link name="castor_swivel_left">
      <inertial>
        <origin xyz="0 0 0" rpy="0 0 0"/>
        <mass value="0.05"/>
        <inertia ixx="2e-05" ixy="0" ixz="0" iyy="2e-05" iyz="0" izz="2e-05"/>
      </inertial>
      <visual name="visual_castor_swivel_left_top_plate">
        <origin xyz="0 0 0" rpy="0 0 0"/>
        <geometry>
          <mesh filename="package://roll_container_description/meshes/stl/Part__Feature021.stl" scale="1.0 1.0 1.0"/>
        </geometry>
        <material name="metal"/>
      </visual>
      <collision name="collision_castor_swivel_left_top_plate">
        <origin xyz="0 0 -0.00201" rpy="0 0 0"/>
        <geometry>
          <box size="0.08 0.105 0.0125"/>
        </geometry>
      </collision>
    </link>

    <link name="castor_swivel_left_fork">
      <inertial>
        <origin xyz="-0.00547 -0.01599 -0.02516" rpy="0 0 0"/>
        <mass value="0.05"/>
        <inertia ixx="2e-05" ixy="0" ixz="0" iyy="2e-05" iyz="0" izz="2e-05"/>
      </inertial>
      <visual name="visual_castor_swivel_left_fork">
        <origin xyz="-0.00547 -0.01599 -0.02516" rpy="0 0 0"/>
        <geometry>
          <mesh filename="package://roll_container_description/meshes/stl/Part__Feature022.stl" scale="1.0 1.0 1.0"/>
        </geometry>
        <material name="metal"/>
      </visual>
      <collision name="collision_castor_swivel_left_fork">
        <origin xyz="0.00029 -0.01005 -0.03671" rpy="0 0 0"/>
        <geometry>
          <box size="0.06794 0.086 0.07898"/>
        </geometry>
      </collision>
    </link>

    <link name="castor_swivel_left_wheel">
      <inertial>
        <origin xyz="0 0 -5e-05" rpy="0 0 0"/>
        <mass value="0.25"/>
        <inertia ixx="3e-05" ixy="0" ixz="0" iyy="2e-05" iyz="0" izz="2e-05"/>
      </inertial>
      <visual name="visual_castor_swivel_left_wheel">
        <origin xyz="0 0 -5e-05" rpy="0.50265 -1.5708 0"/>
        <geometry>
          <mesh filename="package://roll_container_description/meshes/stl/Part__Feature006.stl" scale="1.0 1.0 1.0"/>
        </geometry>
        <material name="wheel"/>
      </visual>
      <collision name="collision_castor_swivel_left_wheel">
        <origin xyz="0 0 0" rpy="0 0 0"/>
        <geometry>
          <cylinder radius="0.0495" length="0.03989"/>
        </geometry>
      </collision>
    </link>

    <link name="castor_swivel_right_wheel">
      <inertial>
        <origin xyz="0 0 -5e-05" rpy="0 0 0"/>
        <mass value="0.25"/>
        <inertia ixx="3e-05" ixy="0" ixz="0" iyy="2e-05" iyz="0" izz="2e-05"/>
      </inertial>
      <visual name="visual_castor_swivel_right_wheel">
        <origin xyz="0 0 -5e-05" rpy="0.50265 -1.5708 0"/>
        <geometry>
          <mesh filename="package://roll_container_description/meshes/stl/Part__Feature006.stl" scale="1.0 1.0 1.0"/>
        </geometry>
        <material name="wheel"/>
      </visual>
      <collision name="collision_castor_swivel_right_wheel">
        <origin xyz="0 0 0" rpy="0 0 0"/>
        <geometry>
          <cylinder radius="0.0495" length="0.03989"/>
        </geometry>
      </collision>
    </link>

    <link name="castor_swivel_right_fork">
      <inertial>
        <origin xyz="-0.00589 -0.01692 -0.02589" rpy="0 0 0"/>
        <mass value="0.05"/>
        <inertia ixx="2e-05" ixy="0" ixz="0" iyy="2e-05" iyz="0" izz="2e-05"/>
      </inertial>
      <visual name="visual_castor_swivel_right_fork">
        <origin xyz="-0.00589 -0.01692 -0.02589" rpy="0 0 0"/>
        <geometry>
          <mesh filename="package://roll_container_description/meshes/stl/Part__Feature117.stl" scale="1.0 1.0 1.0"/>
        </geometry>
        <material name="metal"/>
      </visual>
      <collision name="collision_castor_swivel_right_fork">
        <origin xyz="0.00107 -0.00955 -0.03667" rpy="0 0 0"/>
        <geometry>
          <box size="0.06794 0.086 0.07898"/>
        </geometry>
      </collision>
    </link>

    <link name="handle_left">
      <inertial>
        <origin xyz="0 0 0" rpy="0 0 0"/>
        <mass value="0.1"/>
        <inertia ixx="0.00011" ixy="0" ixz="0" iyy="0.00011" iyz="0" izz="2e-05"/>
      </inertial>
      <visual name="visual_handle_left">
        <origin xyz="-0.00659 0.00693 0" rpy="0 0 0"/>
        <geometry>
          <mesh filename="package://roll_container_description/meshes/stl/Part__Feature163.stl" scale="1.0 1.0 1.0"/>
        </geometry>
        <material name="handle"/>
      </visual>
      <collision name="collision_handle_left">
        <origin xyz="0.00434 -0.00751 -4e-05" rpy="0 0 0"/>
        <geometry>
          <cylinder radius="0.00973" length="0.27591"/>
        </geometry>
      </collision>
      <collision name="collision_handle_left_2">
        <origin xyz="-0.01033 0.01723 -0.13067" rpy="1.5708 0 0.5236"/>
        <geometry>
          <cylinder radius="0.00973" length="0.05394"/>
        </geometry>
      </collision>
      <collision name="collision_handle_left_3">
        <origin xyz="-0.01033 0.01723 0.12873" rpy="1.5708 0 0.5236"/>
        <geometry>
          <cylinder radius="0.00973" length="0.05394"/>
        </geometry>
      </collision>
    </link>

    <link name="handle_right">
      <inertial>
        <origin xyz="0.00433 0.00751 4e-05" rpy="0 0 0"/>
        <mass value="0.1"/>
        <inertia ixx="0.00011" ixy="0" ixz="0" iyy="0.00011" iyz="0" izz="2e-05"/>
      </inertial>
      <visual name="visual_handle_right">
        <origin xyz="0.00433 0.00751 4e-05" rpy="0 0 0"/>
        <geometry>
          <mesh filename="package://roll_container_description/meshes/stl/Part__Feature166.stl" scale="1.0 1.0 1.0"/>
        </geometry>
        <material name="handle"/>
      </visual>
      <collision name="collision_handle_right">
        <origin xyz="0 0 0" rpy="0 0 0"/>
        <geometry>
          <cylinder radius="0.00973" length="0.27591"/>
        </geometry>
      </collision>
      <collision name="collision_handle_right_000">
        <origin xyz="0.01477 0.02494 0.12877" rpy="1.5708 0 -0.5236"/>
        <geometry>
          <cylinder radius="0.00973" length="0.05394"/>
        </geometry>
      </collision>
      <collision name="collision_handle_right_000_001">
        <origin xyz="0.01477 0.02494 -0.13063" rpy="1.5708 0 -0.5236"/>
        <geometry>
          <cylinder radius="0.00973" length="0.05394"/>
        </geometry>
      </collision>
    </link>

    <link name="castor_swivel_right">
      <inertial>
        <origin xyz="0 0 0" rpy="0 0 0"/>
        <mass value="0.05"/>
        <inertia ixx="2e-05" ixy="0" ixz="0" iyy="2e-05" iyz="0" izz="2e-05"/>
      </inertial>
      <visual name="visual_castor_swivel_right_top_plate">
        <origin xyz="0 0 0" rpy="0 0 0"/>
        <geometry>
          <mesh filename="package://roll_container_description/meshes/stl/Part__Feature021.stl" scale="1.0 1.0 1.0"/>
        </geometry>
        <material name="metal"/>
      </visual>
      <collision name="collision_castor_swivel_right_top_plate">
        <origin xyz="0 0 -0.00201" rpy="0 0 0"/>
        <geometry>
          <box size="0.08 0.105 0.0125"/>
        </geometry>
      </collision>
    </link>

    <link name="roll_container_root">
      <inertial>
        <origin xyz="0 0 0" rpy="0 0 0"/>
        <mass value="2.0"/>
        <inertia ixx="0.00605" ixy="0" ixz="0" iyy="0.00465" iyz="0" izz="0.01065"/>
      </inertial>
      <visual name="visual_container_base">
        <origin xyz="-0.00111 0 0" rpy="0 0 0"/>
        <geometry>
          <mesh filename="package://roll_container_description/meshes/stl/Part__Feature.stl" scale="1.01559 1.0 1.0"/>
        </geometry>
        <material name="plate"/>
      </visual>
      <collision name="collision_container_base">
        <origin xyz="0.00017 0.00201 -0.00708" rpy="0 0 0"/>
        <geometry>
          <box size="0.724 0.815 0.06371"/>
        </geometry>
      </collision>
    </link>

    <link name="wire_lattice_left">
      <inertial>
        <origin xyz="0 0 0" rpy="0 0 0"/>
        <mass value="2.0"/>
        <inertia ixx="0.02993" ixy="1e-05" ixz="0" iyy="0.02364" iyz="0" izz="0.0063"/>
      </inertial>
      <visual name="visual_wire_lattice_left">
        <origin xyz="0 0 0" rpy="0 0 0"/>
        <geometry>
          <mesh filename="package://roll_container_description/meshes/stl/Part__Feature162.stl" scale="1.0 1.0 1.0"/>
        </geometry>
        <material name="lattice"/>
      </visual>
      <collision name="collision_wire_lattice_left">
        <origin xyz="-0.00376 -2e-05 0.04164" rpy="0 0 0"/>
        <geometry>
          <box size="0.01972 0.79 1.43781"/>
        </geometry>
      </collision>
    </link>

    <link name="wire_lattice_right">
      <inertial>
        <origin xyz="0 0 0" rpy="0 0 0"/>
        <mass value="2.0"/>
        <inertia ixx="0.02993" ixy="-1e-05" ixz="0" iyy="0.02364" iyz="0" izz="0.0063"/>
      </inertial>
      <visual name="visual_wire_lattice_right">
        <origin xyz="0 0 0" rpy="0 0 0"/>
        <geometry>
          <mesh filename="package://roll_container_description/meshes/stl/Part__Feature165.stl" scale="1.0 1.0 1.0"/>
        </geometry>
        <material name="lattice"/>
      </visual>
      <collision name="collision_wire_lattice_right">
        <origin xyz="0.00378 -0.00039 0.04163" rpy="0 0 0"/>
        <geometry>
          <box size="0.01977 0.79 1.43701"/>
        </geometry>
      </collision>
    </link>

    <joint name="back_stabilizer" type="fixed">
      <origin xyz="0.00017 0.38637 1.06389" rpy="0 0 0"/>
      <parent link="roll_container_root"/>
      <child link="back_stabilizer"/>
    </joint>

    <joint name="castor_rigit_left" type="fixed">
      <origin xyz="-0.28116 0.33151 -0.06865" rpy="0 0 0"/>
      <parent link="roll_container_root"/>
      <child link="castor_rigit_left"/>
    </joint>

    <joint name="castor_rigit_left_wheel" type="continuous">
      <origin xyz="-0.00012 0 -0.04824" rpy="0 1.5708 0"/>
      <parent link="castor_rigit_left"/>
      <child link="castor_rigit_left_wheel"/>
      <axis xyz="0 0 1.0"/>
      <limit effort="0" velocity="0"/>
    </joint>

    <joint name="castor_rigit_right" type="fixed">
      <origin xyz="0.28116 0.33151 -0.06865" rpy="0 0 0"/>
      <parent link="roll_container_root"/>
      <child link="castor_rigit_right"/>
    </joint>

    <joint name="castor_rigit_right_wheel" type="continuous">
      <origin xyz="-0.00012 0 -0.04824" rpy="0 1.5708 0"/>
      <parent link="castor_rigit_right"/>
      <child link="castor_rigit_right_wheel"/>
      <axis xyz="0 0 1.0"/>
      <limit effort="0" velocity="0"/>
    </joint>

    <joint name="castor_swivel_left" type="fixed">
      <origin xyz="-0.28133 -0.32949 -0.04313" rpy="0 0 0"/>
      <parent link="roll_container_root"/>
      <child link="castor_swivel_left"/>
    </joint>

    <joint name="castor_swivel_left_fork" type="continuous">
      <origin xyz="-0.0003 0.00105 -0.00905" rpy="0 0 0"/>
      <parent link="castor_swivel_left"/>
      <child link="castor_swivel_left_fork"/>
      <axis xyz="0 0 1.0"/>
      <limit effort="0" velocity="0"/>
    </joint>

    <joint name="castor_swivel_left_wheel" type="continuous">
      <origin xyz="0.0003 -0.04105 -0.06471" rpy="0 1.5708 0"/>
      <parent link="castor_swivel_left_fork"/>
      <child link="castor_swivel_left_wheel"/>
      <axis xyz="0 0 1.0"/>
      <limit effort="0" velocity="0"/>
    </joint>

    <joint name="castor_swivel_right" type="fixed">
      <origin xyz="0.28133 -0.32949 -0.04313" rpy="0 0 0"/>
      <parent link="roll_container_root"/>
      <child link="castor_swivel_right"/>
    </joint>

    <joint name="castor_swivel_right_fork" type="continuous">
      <origin xyz="-0.00108 -0.00045 -0.01333" rpy="0 0 0"/>
      <parent link="castor_swivel_right"/>
      <child link="castor_swivel_right_fork"/>
      <axis xyz="0 0 1.0"/>
      <limit effort="0" velocity="0"/>
    </joint>

    <joint name="castor_swivel_right_wheel" type="continuous">
      <origin xyz="0.00108 -0.04055 -0.06467" rpy="0 1.5708 0"/>
      <parent link="castor_swivel_right_fork"/>
      <child link="castor_swivel_right_wheel"/>
      <axis xyz="0 0 1.0"/>
      <limit effort="0" velocity="0"/>
    </joint>

    <joint name="handle_left" type="fixed">
      <origin xyz="0.0335 -0.44534 0.20148" rpy="0 0 0"/>
      <parent link="wire_lattice_left"/>
      <child link="handle_left"/>
    </joint>

    <joint name="handle_right" type="fixed">
      <origin xyz="-0.03349 -0.44571 0.20147" rpy="0 0 0"/>
      <parent link="wire_lattice_right"/>
      <child link="handle_right"/>
    </joint>

    <joint name="wire_lattice_left" type="fixed">
      <origin xyz="-0.3407 0.00254 0.70262" rpy="0 0 0"/>
      <parent link="roll_container_root"/>
      <child link="wire_lattice_left"/>
    </joint>

    <joint name="wire_lattice_right" type="fixed">
      <origin xyz="0.34102 0.00291 0.70264" rpy="0 0 0"/>
      <parent link="roll_container_root"/>
      <child link="wire_lattice_right"/>
    </joint>

    <material name="back_stabilizer">
      <color rgba="0.64 0 0.00462 1.0"/>
    </material>

    <material name="handle">
      <color rgba="0.54902 0.06118 0.01087 1.0"/>
    </material>

    <material name="lattice">
      <color rgba="0.04 0.23976 0.8 1.0"/>
    </material>

    <material name="metal">
      <color rgba="0.37158 0.38592 0.39753 1.0"/>
    </material>

    <material name="plate">
      <color rgba="0.00779 0.02086 0.74902 1.0"/>
    </material>

    <material name="wheel">
      <color rgba="0.93333 0.76027 0.01116 1.0"/>
    </material>

  </robot>
