<sdf version="1.6">
  <model name="roll_container">
    <link name="root">
      <pose frame="">0 0 0 0 -0 0</pose>
      <inertial>
        <pose frame="">0.000173 -0.005857 0.474855 0 -0 0</pose>
        <mass>6.5</mass>
        <inertia>
          <ixx>0.927818</ixx>
          <ixy>-0.000294988</ixy>
          <ixz>-0.000371012</ixz>
          <iyy>1.33876</iyy>
          <iyz>0.0134031</iyz>
          <izz>0.598551</izz>
        </inertia>
      </inertial>
      <collision name="root_fixed_joint_lump__collision_container_base_collision">
        <pose frame="">0.00017 0.00201 -0.00708 0 -0 0</pose>
        <geometry>
          <box>
            <size>0.724 0.815 0.06371</size>
          </box>
        </geometry>
      </collision>
      <collision name="root_fixed_joint_lump__collision_back_stabilizer_1_collision_1">
        <pose frame="">0.00017 0.38651 1.21141 3.14159 1.57079 3.14159</pose>
        <geometry>
          <cylinder>
            <length>0.64768</length>
            <radius>0.01072</radius>
          </cylinder>
        </geometry>
      </collision>
      <collision name="root_fixed_joint_lump__collision_back_stabilizer_2_collision_2">
        <pose frame="">0.31527 0.38583 1.03682 0 -0 0</pose>
        <geometry>
          <cylinder>
            <length>0.35586</length>
            <radius>0.01072</radius>
          </cylinder>
        </geometry>
      </collision>
      <collision name="root_fixed_joint_lump__collision_back_stabilizer_3_collision_3">
        <pose frame="">-0.31493 0.38583 1.03683 0 -0 0</pose>
        <geometry>
          <cylinder>
            <length>0.35586</length>
            <radius>0.01072</radius>
          </cylinder>
        </geometry>
      </collision>
      <collision name="root_fixed_joint_lump__collision_castor_rigit_left_fork_collision_4">
        <pose frame="">-0.28134 0.33151 -0.08339 0 -0 0</pose>
        <geometry>
          <box>
            <size>0.086 0.1015 0.089</size>
          </box>
        </geometry>
      </collision>
      <collision name="root_fixed_joint_lump__collision_castor_rigit_right_fork_collision_5">
        <pose frame="">0.28098 0.33151 -0.08339 0 -0 0</pose>
        <geometry>
          <box>
            <size>0.086 0.1015 0.089</size>
          </box>
        </geometry>
      </collision>
      <collision name="root_fixed_joint_lump__collision_castor_swivel_left_top_plate_collision_6">
        <pose frame="">-0.28133 -0.32949 -0.04514 0 -0 0</pose>
        <geometry>
          <box>
            <size>0.08 0.105 0.0125</size>
          </box>
        </geometry>
      </collision>
      <collision name="root_fixed_joint_lump__collision_castor_swivel_right_top_plate_collision_7">
        <pose frame="">0.28133 -0.32949 -0.04514 0 -0 0</pose>
        <geometry>
          <box>
            <size>0.08 0.105 0.0125</size>
          </box>
        </geometry>
      </collision>
      <collision name="root_fixed_joint_lump__collision_wire_lattice_left_collision_8">
        <pose frame="">-0.34446 0.00252 0.74426 0 -0 0</pose>
        <geometry>
          <box>
            <size>0.01972 0.79 1.43781</size>
          </box>
        </geometry>
      </collision>
      <collision name="root_fixed_joint_lump__collision_handle_left_collision_9">
        <pose frame="">-0.30286 -0.45031 0.90406 0 -0 0</pose>
        <geometry>
          <cylinder>
            <length>0.27591</length>
            <radius>0.00973</radius>
          </cylinder>
        </geometry>
      </collision>
      <collision name="root_fixed_joint_lump__collision_handle_left_2_collision_10">
        <pose frame="">-0.31753 -0.42557 0.77343 1.5708 0 0.5236</pose>
        <geometry>
          <cylinder>
            <length>0.05394</length>
            <radius>0.00973</radius>
          </cylinder>
        </geometry>
      </collision>
      <collision name="root_fixed_joint_lump__collision_handle_left_3_collision_11">
        <pose frame="">-0.31753 -0.42557 1.03283 1.5708 0 0.5236</pose>
        <geometry>
          <cylinder>
            <length>0.05394</length>
            <radius>0.00973</radius>
          </cylinder>
        </geometry>
      </collision>
      <collision name="root_fixed_joint_lump__collision_wire_lattice_right_collision_12">
        <pose frame="">0.3448 0.00252 0.74427 0 -0 0</pose>
        <geometry>
          <box>
            <size>0.01977 0.79 1.43701</size>
          </box>
        </geometry>
      </collision>
      <collision name="root_fixed_joint_lump__collision_handle_right_collision_13">
        <pose frame="">0.30753 -0.4428 0.90411 0 -0 0</pose>
        <geometry>
          <cylinder>
            <length>0.27591</length>
            <radius>0.00973</radius>
          </cylinder>
        </geometry>
      </collision>
      <collision name="root_fixed_joint_lump__collision_handle_right_000_collision_14">
        <pose frame="">0.3223 -0.41786 1.03288 1.5708 -0 -0.5236</pose>
        <geometry>
          <cylinder>
            <length>0.05394</length>
            <radius>0.00973</radius>
          </cylinder>
        </geometry>
      </collision>
      <collision name="root_fixed_joint_lump__collision_handle_right_000_001_collision_15">
        <pose frame="">0.3223 -0.41786 0.77348 1.5708 -0 -0.5236</pose>
        <geometry>
          <cylinder>
            <length>0.05394</length>
            <radius>0.00973</radius>
          </cylinder>
        </geometry>
      </collision>
      <visual name="root_fixed_joint_lump__visual_container_base_visual">
        <pose frame="">-0.00111 0 0 0 -0 0</pose>
        <geometry>
          <mesh>
            <scale>1.01559 1 1</scale>
            <uri>model://meshes/fbx/Part__Feature.fbx</uri>
          </mesh>
        </geometry>
      </visual>
      <visual name="root_fixed_joint_lump__visual_back_stabilizer_visual_1">
        <pose frame="">0.00017 0.38637 1.06389 0 -0 0</pose>
        <geometry>
          <mesh>
            <scale>1 1 1</scale>
            <uri>model://meshes/fbx/Part__Feature167.fbx</uri>
          </mesh>
        </geometry>
      </visual>
      <visual name="root_fixed_joint_lump__visual_castor_rigit_left_fork_visual_2">
        <pose frame="">-0.28116 0.33151 -0.06865 0 -0 0</pose>
        <geometry>
          <mesh>
            <scale>1 1 1</scale>
            <uri>model://meshes/fbx/Part__Feature082.fbx</uri>
          </mesh>
        </geometry>
      </visual>
      <visual name="root_fixed_joint_lump__visual_castor_rigit_right_fork_visual_3">
        <pose frame="">0.28116 0.33151 -0.06865 0 -0 0</pose>
        <geometry>
          <mesh>
            <scale>1 1 1</scale>
            <uri>model://meshes/fbx/Part__Feature099.fbx</uri>
          </mesh>
        </geometry>
      </visual>
      <visual name="root_fixed_joint_lump__visual_castor_swivel_left_top_plate_visual_4">
        <pose frame="">-0.28133 -0.32949 -0.04313 0 -0 0</pose>
        <geometry>
          <mesh>
            <scale>1 1 1</scale>
            <uri>model://meshes/fbx/Part__Feature021.fbx</uri>
          </mesh>
        </geometry>
      </visual>
      <visual name="root_fixed_joint_lump__visual_castor_swivel_right_top_plate_visual_5">
        <pose frame="">0.28133 -0.32949 -0.04313 0 -0 0</pose>
        <geometry>
          <mesh>
            <scale>1 1 1</scale>
            <uri>model://meshes/fbx/Part__Feature021.fbx</uri>
          </mesh>
        </geometry>
      </visual>
      <visual name="root_fixed_joint_lump__visual_wire_lattice_left_visual_6">
        <pose frame="">-0.3407 0.00254 0.70262 0 -0 0</pose>
        <geometry>
          <mesh>
            <scale>1 1 1</scale>
            <uri>model://meshes/fbx/Part__Feature162.fbx</uri>
          </mesh>
        </geometry>
      </visual>
      <visual name="root_fixed_joint_lump__visual_handle_left_visual_7">
        <pose frame="">-0.31379 -0.43587 0.9041 0 -0 0</pose>
        <geometry>
          <mesh>
            <scale>1 1 1</scale>
            <uri>model://meshes/fbx/Part__Feature163.fbx</uri>
          </mesh>
        </geometry>
      </visual>
      <visual name="root_fixed_joint_lump__visual_wire_lattice_right_visual_8">
        <pose frame="">0.34102 0.00291 0.70264 0 -0 0</pose>
        <geometry>
          <mesh>
            <scale>1 1 1</scale>
            <uri>model://meshes/fbx/Part__Feature165.fbx</uri>
          </mesh>
        </geometry>
      </visual>
      <visual name="root_fixed_joint_lump__visual_handle_right_visual_9">
        <pose frame="">0.31186 -0.43529 0.90415 0 -0 0</pose>
        <geometry>
          <mesh>
            <scale>1 1 1</scale>
            <uri>model://meshes/fbx/Part__Feature166.fbx</uri>
          </mesh>
        </geometry>
      </visual>
    </link>
    <link name="castor_rigit_left_wheel">
      <pose frame="">-0.28128 0.33151 -0.11689 3.14159 1.57079 3.14159</pose>
      <inertial>
        <pose frame="">0 0 0 0 -0 0</pose>
        <mass>0.25</mass>
        <inertia>
          <ixx>3e-05</ixx>
          <ixy>0</ixy>
          <ixz>0</ixz>
          <iyy>2e-05</iyy>
          <iyz>0</iyz>
          <izz>2e-05</izz>
        </inertia>
      </inertial>
      <collision name="castor_rigit_left_wheel_fixed_joint_lump__collision_castor_rigit_left_wheel_collision">
        <pose frame="">-5e-05 0 0 0 -0 0</pose>
        <geometry>
          <cylinder>
            <length>0.03989</length>
            <radius>0.0495</radius>
          </cylinder>
        </geometry>
      </collision>
      <visual name="castor_rigit_left_wheel_fixed_joint_lump__visual_castor_rigit_left_wheel_visual">
        <pose frame="">0 0 0 3.14159 -1.57079 3.14159</pose>
        <geometry>
          <mesh>
            <scale>1 1 1</scale>
            <uri>model://meshes/fbx/Part__Feature066.fbx</uri>
          </mesh>
        </geometry>
      </visual>
    </link>
    <joint name="castor_rigit_left_wheel_joint" type="revolute">
      <child>castor_rigit_left_wheel</child>
      <parent>root</parent>
      <axis>
        <xyz>1 0 -4e-06</xyz>
        <limit>
          <lower>-1e+16</lower>
          <upper>1e+16</upper>
        </limit>
        <dynamics>
          <spring_reference>0</spring_reference>
          <spring_stiffness>0</spring_stiffness>
        </dynamics>
        <use_parent_model_frame>1</use_parent_model_frame>
      </axis>
    </joint>
    <link name="castor_rigit_right_wheel">
      <pose frame="">0.28104 0.33151 -0.11689 3.14159 1.57079 3.14159</pose>
      <inertial>
        <pose frame="">0 0 0 0 -0 0</pose>
        <mass>0.25</mass>
        <inertia>
          <ixx>3e-05</ixx>
          <ixy>0</ixy>
          <ixz>0</ixz>
          <iyy>2e-05</iyy>
          <iyz>0</iyz>
          <izz>2e-05</izz>
        </inertia>
      </inertial>
      <collision name="castor_rigit_right_wheel_fixed_joint_lump__collision_castor_rigit_right_wheel_collision">
        <pose frame="">-5e-05 0 0 0 -0 0</pose>
        <geometry>
          <cylinder>
            <length>0.03989</length>
            <radius>0.0495</radius>
          </cylinder>
        </geometry>
      </collision>
      <visual name="castor_rigit_right_wheel_fixed_joint_lump__visual_castor_rigit_right_wheel_visual">
        <pose frame="">0 0 0 3.14159 -1.57079 3.14159</pose>
        <geometry>
          <mesh>
            <scale>1 1 1</scale>
            <uri>model://meshes/fbx/Part__Feature083.fbx</uri>
          </mesh>
        </geometry>
      </visual>
    </link>
    <joint name="castor_rigit_right_wheel_joint" type="revolute">
      <child>castor_rigit_right_wheel</child>
      <parent>root</parent>
      <axis>
        <xyz>1 0 -4e-06</xyz>
        <limit>
          <lower>-1e+16</lower>
          <upper>1e+16</upper>
        </limit>
        <dynamics>
          <spring_reference>0</spring_reference>
          <spring_stiffness>0</spring_stiffness>
        </dynamics>
        <use_parent_model_frame>1</use_parent_model_frame>
      </axis>
    </joint>
    <link name="castor_swivel_left_fork">
      <pose frame="">-0.28163 -0.32844 -0.05218 0 -0 0</pose>
      <inertial>
        <pose frame="">-0.00547 -0.01599 -0.02516 0 -0 0</pose>
        <mass>0.05</mass>
        <inertia>
          <ixx>2e-05</ixx>
          <ixy>0</ixy>
          <ixz>0</ixz>
          <iyy>2e-05</iyy>
          <iyz>0</iyz>
          <izz>2e-05</izz>
        </inertia>
      </inertial>
      <collision name="castor_swivel_left_fork_fixed_joint_lump__collision_castor_swivel_left_fork_collision">
        <pose frame="">0.00029 -0.01005 -0.03671 0 -0 0</pose>
        <geometry>
          <box>
            <size>0.06794 0.086 0.07898</size>
          </box>
        </geometry>
      </collision>
      <visual name="castor_swivel_left_fork_fixed_joint_lump__visual_castor_swivel_left_fork_visual">
        <pose frame="">-0.00547 -0.01599 -0.02516 0 -0 0</pose>
        <geometry>
          <mesh>
            <scale>1 1 1</scale>
            <uri>model://meshes/fbx/Part__Feature022.fbx</uri>
          </mesh>
        </geometry>
      </visual>
    </link>
    <joint name="castor_swivel_left_fork_joint" type="revolute">
      <child>castor_swivel_left_fork</child>
      <parent>root</parent>
      <axis>
        <xyz>0 0 1</xyz>
        <limit>
          <lower>-1e+16</lower>
          <upper>1e+16</upper>
        </limit>
        <dynamics>
          <spring_reference>0</spring_reference>
          <spring_stiffness>0</spring_stiffness>
        </dynamics>
        <use_parent_model_frame>1</use_parent_model_frame>
      </axis>
    </joint>
    <link name="castor_swivel_left_wheel">
      <pose frame="">-0.28133 -0.36949 -0.11689 3.14159 1.57079 3.14159</pose>
      <inertial>
        <pose frame="">0 0 -5e-05 0 -0 0</pose>
        <mass>0.25</mass>
        <inertia>
          <ixx>3e-05</ixx>
          <ixy>0</ixy>
          <ixz>0</ixz>
          <iyy>2e-05</iyy>
          <iyz>0</iyz>
          <izz>2e-05</izz>
        </inertia>
      </inertial>
      <collision name="castor_swivel_left_wheel_fixed_joint_lump__collision_castor_swivel_left_wheel_collision">
        <pose frame="">0 0 0 0 -0 0</pose>
        <geometry>
          <cylinder>
            <length>0.03989</length>
            <radius>0.0495</radius>
          </cylinder>
        </geometry>
      </collision>
      <visual name="castor_swivel_left_wheel_fixed_joint_lump__visual_castor_swivel_left_wheel_visual">
        <pose frame="">0 0 -5e-05 3.14159 -1.57079 -2.63895</pose>
        <geometry>
          <mesh>
            <scale>1 1 1</scale>
            <uri>model://meshes/fbx/Part__Feature006.fbx</uri>
          </mesh>
        </geometry>
      </visual>
    </link>
    <joint name="castor_swivel_left_wheel_joint" type="revolute">
      <child>castor_swivel_left_wheel</child>
      <parent>castor_swivel_left_fork</parent>
      <axis>
        <xyz>1 0 -4e-06</xyz>
        <limit>
          <lower>-1e+16</lower>
          <upper>1e+16</upper>
        </limit>
        <dynamics>
          <spring_reference>0</spring_reference>
          <spring_stiffness>0</spring_stiffness>
        </dynamics>
        <use_parent_model_frame>1</use_parent_model_frame>
      </axis>
    </joint>
    <link name="castor_swivel_right_fork">
      <pose frame="">0.28025 -0.32994 -0.05646 0 -0 0</pose>
      <inertial>
        <pose frame="">-0.00589 -0.01692 -0.02589 0 -0 0</pose>
        <mass>0.05</mass>
        <inertia>
          <ixx>2e-05</ixx>
          <ixy>0</ixy>
          <ixz>0</ixz>
          <iyy>2e-05</iyy>
          <iyz>0</iyz>
          <izz>2e-05</izz>
        </inertia>
      </inertial>
      <collision name="castor_swivel_right_fork_fixed_joint_lump__collision_castor_swivel_right_fork_collision">
        <pose frame="">0.00107 -0.00955 -0.03667 0 -0 0</pose>
        <geometry>
          <box>
            <size>0.06794 0.086 0.07898</size>
          </box>
        </geometry>
      </collision>
      <visual name="castor_swivel_right_fork_fixed_joint_lump__visual_castor_swivel_right_fork_visual">
        <pose frame="">-0.00589 -0.01692 -0.02589 0 -0 0</pose>
        <geometry>
          <mesh>
            <scale>1 1 1</scale>
            <uri>model://meshes/fbx/Part__Feature117.fbx</uri>
          </mesh>
        </geometry>
      </visual>
    </link>
    <joint name="castor_swivel_right_fork_joint" type="revolute">
      <child>castor_swivel_right_fork</child>
      <parent>root</parent>
      <axis>
        <xyz>0 0 1</xyz>
        <limit>
          <lower>-1e+16</lower>
          <upper>1e+16</upper>
        </limit>
        <dynamics>
          <spring_reference>0</spring_reference>
          <spring_stiffness>0</spring_stiffness>
        </dynamics>
        <use_parent_model_frame>1</use_parent_model_frame>
      </axis>
    </joint>
    <link name="castor_swivel_right_wheel">
      <pose frame="">0.28133 -0.37049 -0.12113 3.14159 1.57079 3.14159</pose>
      <inertial>
        <pose frame="">0 0 -5e-05 0 -0 0</pose>
        <mass>0.25</mass>
        <inertia>
          <ixx>3e-05</ixx>
          <ixy>0</ixy>
          <ixz>0</ixz>
          <iyy>2e-05</iyy>
          <iyz>0</iyz>
          <izz>2e-05</izz>
        </inertia>
      </inertial>
      <collision name="castor_swivel_right_wheel_fixed_joint_lump__collision_castor_swivel_right_wheel_collision">
        <pose frame="">0 0 0 0 -0 0</pose>
        <geometry>
          <cylinder>
            <length>0.03989</length>
            <radius>0.0495</radius>
          </cylinder>
        </geometry>
      </collision>
      <visual name="castor_swivel_right_wheel_fixed_joint_lump__visual_castor_swivel_right_wheel_visual">
        <pose frame="">0 0 -5e-05 3.14159 -1.57079 -2.63895</pose>
        <geometry>
          <mesh>
            <scale>1 1 1</scale>
            <uri>model://meshes/fbx/Part__Feature006.fbx</uri>
          </mesh>
        </geometry>
      </visual>
    </link>
    <joint name="castor_swivel_right_wheel_joint" type="revolute">
      <child>castor_swivel_right_wheel</child>
      <parent>castor_swivel_right_fork</parent>
      <axis>
        <xyz>1 0 -4e-06</xyz>
        <limit>
          <lower>-1e+16</lower>
          <upper>1e+16</upper>
        </limit>
        <dynamics>
          <spring_reference>0</spring_reference>
          <spring_stiffness>0</spring_stiffness>
        </dynamics>
        <use_parent_model_frame>1</use_parent_model_frame>
      </axis>
    </joint>
  </model>
</sdf>
