<mujoco model="tiago">
    <compiler angle="radian" />
    <size njmax="500" nconmax="100" />
    <asset>
        <mesh name="sick_tim551" file="tiago/meshes/sick_tim551.stl" />
        <mesh name="srf05" file="tiago/meshes/srf05.stl" />
        <mesh name="base" file="tiago/meshes/base.stl" />
        <mesh name="base_ring" file="tiago/meshes/base_ring.stl" />
        <mesh name="antenna" file="tiago/meshes/antenna.stl" />
        <mesh name="wheel" file="tiago/meshes/wheel.stl" />
        <mesh name="caster_1" file="tiago/meshes/caster_1.stl" />
        <mesh name="caster_2" file="tiago/meshes/caster_2.stl" />
        <mesh name="torso_fix" file="tiago/meshes/torso_fix.stl" />
        <mesh name="torso_lift_with_arm" file="tiago/meshes/torso_lift_with_arm.stl" />
        <mesh name="head_1" file="tiago/meshes/head_1.stl" />
        <mesh name="head_2" file="tiago/meshes/head_2.stl" />
        <mesh name="arm_1" file="tiago/meshes/arm_1.stl" />
        <mesh name="arm_2" file="tiago/meshes/arm_2.stl" />
        <mesh name="arm_3" file="tiago/meshes/arm_3.stl" />
        <mesh name="arm_4" file="tiago/meshes/arm_4.stl" />
        <mesh name="arm_5-wrist-2010" file="tiago/meshes/arm_5-wrist-2010.stl" />
        <mesh name="arm_6-wrist-2010" file="tiago/meshes/arm_6-wrist-2010.stl" />
        <mesh name="palm" file="tiago/meshes/palm.stl" />
        <mesh name="thumb_abd_collision" file="tiago/meshes/thumb_abd_collision.stl" />
        <mesh name="finger_flex_collision" file="tiago/meshes/finger_flex_collision.stl" />
        <mesh name="finger_flex_tip_collision" file="tiago/meshes/finger_flex_tip_collision.stl" />
        <mesh name="finger_abd_collision" file="tiago/meshes/finger_abd_collision.stl" />
    </asset>
    <worldbody>
        <geom pos="0 0 0.0985" type="mesh" mesh="base" />
        <geom pos="0.202 0 0.0945" type="mesh" mesh="sick_tim551" />
        <geom pos="-0.183 0.183 0.2715" quat="0.382683 0 0 0.92388" type="mesh" mesh="srf05" />
        <geom pos="-0.259 0 0.2715" quat="0 0 0 1" type="mesh" mesh="srf05" />
        <geom pos="-0.183 -0.183 0.2715" quat="-0.382683 0 0 0.92388" type="mesh" mesh="srf05" />
        <geom pos="-0.201 0.1062 0.2935" type="mesh" mesh="antenna" />
        <geom pos="-0.201 -0.1062 0.2935" type="mesh" mesh="antenna" />
        <geom pos="-0.062 0 0.2915" type="mesh" mesh="torso_fix" />
        <geom size="0.09 0.1 0.275" pos="-0.062 0 0.5685" type="box" />
        <geom pos="0 0 0.13" type="mesh" mesh="base_ring" />
        <body name="suspension_right_link" pos="0 0 0.0985">
            <inertial pos="0 0 -0.02" mass="10" diaginertia="1 1 1" />
            <joint name="suspension_right_joint" pos="0 0 0" axis="0 0 1" type="slide" limited="true" range="-0.005 0.005" damping="100" />
            <body name="wheel_right_link" pos="0 -0.2022 0" quat="0.707107 -0.707107 0 0">
                <inertial pos="0 0 -0.00207" quat="0.296456 0.641958 -0.296458 0.641963" mass="1.82362" diaginertia="0.0083924 0.00499747 0.00499738" />
                <joint name="wheel_right_joint" pos="0 0 0" axis="0 0 1" />
                <geom type="mesh" mesh="wheel" />
            </body>
        </body>
        <body name="suspension_left_link" pos="0 0 0.0985">
            <inertial pos="0 0 -0.02" mass="10" diaginertia="1 1 1" />
            <joint name="suspension_left_joint" pos="0 0 0" axis="0 0 1" type="slide" limited="true" range="-0.005 0.005" damping="100" />
            <body name="wheel_left_link" pos="0 0.2022 0" quat="0.707107 -0.707107 0 0">
                <inertial pos="0 0 0.00207" quat="0.641958 0.296456 -0.641963 0.296458" mass="1.82362" diaginertia="0.0083924 0.00499747 0.00499738" />
                <joint name="wheel_left_joint" pos="0 0 0" axis="0 0 1" />
                <geom quat="0 -1 0 0" type="mesh" mesh="wheel" />
            </body>
        </body>
        <body name="caster_front_right_1_link" pos="0.1695 -0.102 0.065">
            <inertial pos="-0.00634599 5.347e-05 -0.0203752" quat="0.966491 -0.00340536 -0.256544 -0.00828025" mass="0.0514476" diaginertia="1.66556e-05 1.30896e-05 1.04548e-05" />
            <joint name="caster_front_right_1_joint" pos="0 0 0" axis="0 0 1" damping="0.005" />
            <geom type="mesh" mesh="caster_1" />
            <body name="caster_front_right_2_link" pos="-0.016 0 -0.04" quat="0.707107 -0.707107 0 0">
                <inertial pos="0 0 0" quat="0.707107 0 0 0.707107" mass="0.0885578" diaginertia="1.541e-05 1.075e-05 1.075e-05" />
                <joint name="caster_front_right_2_joint" pos="0 0 0" axis="0 0 1" />
                <geom type="mesh" mesh="caster_2" />
            </body>
        </body>
        <body name="caster_front_left_1_link" pos="0.1695 0.102 0.065">
            <inertial pos="-0.00634599 5.347e-05 -0.0203752" quat="0.966491 -0.00340536 -0.256544 -0.00828025" mass="0.0514476" diaginertia="1.66556e-05 1.30896e-05 1.04548e-05" />
            <joint name="caster_front_left_1_joint" pos="0 0 0" axis="0 0 1" damping="0.005" />
            <geom type="mesh" mesh="caster_1" />
            <body name="caster_front_left_2_link" pos="-0.016 0 -0.04" quat="0.707107 -0.707107 0 0">
                <inertial pos="0 0 0" quat="0.707107 0 0 0.707107" mass="0.0885578" diaginertia="1.541e-05 1.075e-05 1.075e-05" />
                <joint name="caster_front_left_2_joint" pos="0 0 0" axis="0 0 1" />
                <geom type="mesh" mesh="caster_2" />
            </body>
        </body>
        <body name="caster_back_right_1_link" pos="-0.1735 -0.102 0.065">
            <inertial pos="-0.00634599 5.347e-05 -0.0203752" quat="0.966491 -0.00340536 -0.256544 -0.00828025" mass="0.0514476" diaginertia="1.66556e-05 1.30896e-05 1.04548e-05" />
            <joint name="caster_back_right_1_joint" pos="0 0 0" axis="0 0 1" damping="0.005" />
            <geom type="mesh" mesh="caster_1" />
            <body name="caster_back_right_2_link" pos="-0.016 0 -0.04" quat="0.707107 -0.707107 0 0">
                <inertial pos="0 0 0" quat="0.707107 0 0 0.707107" mass="0.0885578" diaginertia="1.541e-05 1.075e-05 1.075e-05" />
                <joint name="caster_back_right_2_joint" pos="0 0 0" axis="0 0 1" />
                <geom type="mesh" mesh="caster_2" />
            </body>
        </body>
        <body name="caster_back_left_1_link" pos="-0.1735 0.102 0.065">
            <inertial pos="-0.00634599 5.347e-05 -0.0203752" quat="0.966491 -0.00340536 -0.256544 -0.00828025" mass="0.0514476" diaginertia="1.66556e-05 1.30896e-05 1.04548e-05" />
            <joint name="caster_back_left_1_joint" pos="0 0 0" axis="0 0 1" damping="0.005" />
            <geom type="mesh" mesh="caster_1" />
            <body name="caster_back_left_2_link" pos="-0.016 0 -0.04" quat="0.707107 -0.707107 0 0">
                <inertial pos="0 0 0" quat="0.707107 0 0 0.707107" mass="0.0885578" diaginertia="1.541e-05 1.075e-05 1.075e-05" />
                <joint name="caster_back_left_2_joint" pos="0 0 0" axis="0 0 1" />
                <geom type="mesh" mesh="caster_2" />
            </body>
        </body>
        <body name="torso_lift_link" pos="-0.062 0 0.8885">
            <inertial pos="0.04361 -0.00116 -0.17334" quat="0.562536 0.0400112 -0.00365739 0.825796" mass="6.93198" diaginertia="0.250465 0.244703 0.0893652" />
            <joint name="torso_lift_joint" pos="0 0 0" axis="0 0 1" type="slide" limited="true" range="0 0.35" damping="1000" />
            <geom type="mesh" mesh="torso_lift_with_arm" />
            <body name="head_1_link" pos="0.182 0 0">
                <inertial pos="-0.00508 0.00237 0.07229" quat="0.688669 -0.0973979 -0.101834 0.711251" mass="0.6222" diaginertia="0.00140223 0.00121968 0.000861083" />
                <joint name="head_1_joint" pos="0 0 0" axis="0 0 1" limited="true" range="-1.309 1.309" damping="0.5" frictionloss="1" />
                <geom type="mesh" mesh="head_1" />
                <body name="head_2_link" pos="0.005 0 0.098" quat="0.707107 0.707107 0 0">
                    <inertial pos="0.0558274 0.0609987 1.58542e-05" quat="0.89114 -0.000495756 -0.00420876 0.453708" mass="0.88693" diaginertia="0.00554181 0.00436261 0.00347586" />
                    <joint name="head_2_joint" pos="0 0 0" axis="0 0 1" limited="true" range="-1.0472 0.785398" damping="0.5" frictionloss="1" />
                    <geom type="mesh" mesh="head_2" />
                </body>
            </body>
            <body name="arm_1_link" pos="0.15505 0.014 -0.151" quat="0.707107 0 0 -0.707107">
                <inertial pos="0.061191 -0.022397 -0.012835" mass="1.56343" diaginertia="0.01 0.01 0.01" />
                <joint name="arm_1_joint" pos="0 0 0" axis="0 0 1" limited="true" range="0 2.74889" damping="1" frictionloss="1" />
                <geom type="mesh" mesh="arm_1" />
                <body name="arm_2_link" pos="0.125 0.0195 -0.031" quat="0.707107 0.707107 0 0">
                    <inertial pos="0.030432 0.000229 -0.005942" quat="0.126897 0.72859 0.136233 0.659161" mass="1.8004" diaginertia="0.00437229 0.00432701 0.0017837" />
                    <joint name="arm_2_joint" pos="0 0 0" axis="0 0 1" limited="true" range="-1.5708 1.09083" damping="1" frictionloss="1" />
                    <geom type="mesh" mesh="arm_2" />
                    <body name="arm_3_link" pos="0.0895 0 -0.0015" quat="0.5 -0.5 -0.5 0.5">
                        <inertial pos="0.007418 -0.004361 -0.134194" quat="0.516615 0.0556881 0.00536911 0.854388" mass="1.8" diaginertia="0.0200771 0.0196154 0.00264853" />
                        <joint name="arm_3_joint" pos="0 0 0" axis="0 0 1" limited="true" range="-3.53429 1.5708" damping="1" frictionloss="1" />
                        <geom type="mesh" mesh="arm_3" />
                        <body name="arm_4_link" pos="-0.02 -0.027 -0.222" quat="0.5 -0.5 -0.5 -0.5">
                            <inertial pos="-0.095658 0.014666 0.018133" quat="-0.161572 0.615556 -0.202229 0.744371" mass="1.4327" diaginertia="0.00906004 0.00831328 0.00177669" />
                            <joint name="arm_4_joint" pos="0 0 0" axis="0 0 1" limited="true" range="-0.392699 2.35619" damping="1" frictionloss="1" />
                            <geom type="mesh" mesh="arm_4" />
                            <body name="arm_5_link" pos="-0.162 0.02 0.027" quat="0.707107 0 -0.707107 0">
                                <inertial pos="0.001078 -0.000151 -0.077173" quat="0.99983 0.00293151 -0.0179292 -0.00313391" mass="1.65582" diaginertia="0.00614362 0.00564011 0.00179127" />
                                <joint name="arm_5_joint" pos="0 0 0" axis="0 0 1" limited="true" range="-2.0944 2.0944" damping="1" frictionloss="1" />
                                <geom type="mesh" mesh="arm_5-wrist-2010" />
                                <body name="arm_6_link" pos="0 0 0.15" quat="0.5 -0.5 -0.5 -0.5">
                                    <inertial pos="-0.000153 -0.003122 0.000183" quat="0.83147 0.55557 0 0" mass="0.370063" diaginertia="0.000215 0.000174828 0.000169172" />
                                    <joint name="arm_6_joint" pos="0 0 0" axis="0 0 1" limited="true" range="-1.41372 1.41372" damping="1" frictionloss="1" />
                                    <geom type="mesh" mesh="arm_6-wrist-2010" />
                                    <body name="arm_7_link" pos="0 0 0" quat="0.5 0.5 0.5 0.5">
                                        <inertial pos="-0.000937081 0.000900311 0.0718226" quat="0.999796 -0.005229 -0.00790158 0.017817" mass="0.934452" diaginertia="0.00407153 0.00390085 0.000512277" />
                                        <joint name="arm_7_joint" pos="0 0 0" axis="0 0 1" limited="true" range="-2.0944 2.0944" damping="1" frictionloss="1" />
                                        <geom size="0.005 0.0025" pos="0 0 0.047" quat="-0.707107 0 0 0.707107" type="cylinder" />
                                        <geom size="0.0225 0.00785" pos="0 0 0.05385" quat="-1 0 0 0" type="cylinder" />
                                        <geom size="0.025 0.004875" pos="0 0 0.066575" quat="-0.707107 0 0 0.707107" type="cylinder" />
                                        <geom pos="0 0 0.066575" quat="-0.5 0.5 0.5 0.5" type="mesh" mesh="palm" />
                                        <!-- <body name="hand_thumb_link" pos="0 0 0.066575" quat="-0.5 0.5 0.5 0.5">
                                            <inertial pos="0 0 0" mass="0.05" diaginertia="0.001 0.001 0.001"/>
                                            <joint name="hand_thumb_joint" pos="0 0 0" axis="0 0 1" limited="true" range="-2.61799 6.28319" damping="0.5"/>
                                            <geom size="0.001"/>
                                        </body>
                                        <body name="hand_index_link" pos="0 0 0.066575" quat="-0.5 0.5 0.5 0.5">
                                            <inertial pos="0 0 0" mass="0.05" diaginertia="0.001 0.001 0.001"/>
                                            <joint name="hand_index_joint" pos="0 0 0" axis="0 0 1" limited="true" range="-3.05433 6.80678" damping="0.5"/>
                                            <geom size="0.001"/>
                                        </body>
                                        <body name="hand_mrl_link" pos="0 0 0.066575" quat="-0.5 0.5 0.5 0.5">
                                            <inertial pos="0 0 0" mass="0.05" diaginertia="0.001 0.001 0.001"/>
                                            <joint name="hand_mrl_joint" pos="0 0 0" axis="0 0 1" limited="true" range="-2.53073 9.25025" damping="0.5"/>
                                            <geom size="0.001"/>
                                        </body> -->
                                        <body name="hand_thumb_abd_link" pos="0.0134 0.038 0.156675" quat="-0.153046 0.690346 0.690346 0.153046">
                                            <inertial pos="-0.0132 0.0037 -0.0017" mass="0.014" diaginertia="0.001 0.001 0.001" />
                                            <joint name="hand_thumb_abd_joint" pos="0 0 0" axis="0 0 1" limited="true" range="0 1.5708" damping="0.5" />
                                            <geom type="mesh" mesh="thumb_abd_collision" />
                                            <body name="hand_thumb_virtual_1_link" pos="0.0225 0.003 0" quat="0.840756 -0.541415 0 0">
                                                <inertial pos="0.0065 0 0" mass="0.01" diaginertia="0.001 0.001 0.001" />
                                                <joint name="hand_thumb_virtual_1_joint" pos="0 0 0" axis="0 0 1" limited="true" range="0 0.785398" damping="0.5" />
                                                <geom size="0.0065 0.001 0.006" pos="0.0065 0 0" type="box" />
                                                <body name="hand_thumb_flex_1_link" pos="0.013 0 0">
                                                    <inertial pos="0.0047 0.0031 0" mass="0.009" diaginertia="0.001 0.001 0.001" />
                                                    <joint name="hand_thumb_flex_1_joint" pos="0 0 0" axis="0 0 1" limited="true" range="0 0.785398" damping="0.5" />
                                                    <geom type="mesh" mesh="finger_flex_collision" />
                                                    <body name="hand_thumb_virtual_2_link" pos="0.009 0 0">
                                                        <inertial pos="0.0065 0 0" mass="0.01" diaginertia="0.001 0.001 0.001" />
                                                        <joint name="hand_thumb_virtual_2_joint" pos="0 0 0" axis="0 0 1" limited="true" range="0 0.785398" damping="0.5" />
                                                        <geom size="0.0065 0.001 0.006" pos="0.0065 0 0" type="box" />
                                                        <body name="hand_thumb_flex_2_link" pos="0.013 0 0">
                                                            <inertial pos="0.0096 0.003 0" mass="0.015" diaginertia="0.001 0.001 0.001" />
                                                            <joint name="hand_thumb_flex_2_joint" pos="0 0 0" axis="0 0 1" limited="true" range="0 0.785398" damping="0.5" />
                                                            <geom type="mesh" mesh="finger_flex_tip_collision" />
                                                        </body>
                                                    </body>
                                                </body>
                                            </body>
                                        </body>
                                        <body name="hand_index_abd_link" pos="0.0042 0.0265 0.193075" quat="0.183013 0.683013 0.183013 0.683013">
                                            <inertial pos="-0.0018 0 0.0028" mass="0.018" diaginertia="0.001 0.001 0.001" />
                                            <joint name="hand_index_abd_joint" pos="0 0 0" axis="0 0 1" limited="true" range="-0.523599 0.523599" damping="0.5" />
                                            <geom type="mesh" mesh="finger_abd_collision" />
                                            <body name="hand_index_virtual_1_link" pos="0.009 0 0" quat="0.707107 0.707107 0 0">
                                                <inertial pos="0.0065 0 0" mass="0.01" diaginertia="0.001 0.001 0.001" />
                                                <joint name="hand_index_virtual_1_joint" pos="0 0 0" axis="0 0 1" limited="true" range="0 0.785398" damping="0.5" />
                                                <geom size="0.0065 0.001 0.006" pos="0.0065 0 0" type="box" />
                                                <body name="hand_index_flex_1_link" pos="0.013 0 0">
                                                    <inertial pos="0.0047 0.0031 0" mass="0.009" diaginertia="0.001 0.001 0.001" />
                                                    <joint name="hand_index_flex_1_joint" pos="0 0 0" axis="0 0 1" limited="true" range="0 0.785398" damping="0.5" />
                                                    <geom type="mesh" mesh="finger_flex_collision" />
                                                    <body name="hand_index_virtual_2_link" pos="0.009 0 0">
                                                        <inertial pos="0.0065 0 0" mass="0.01" diaginertia="0.001 0.001 0.001" />
                                                        <joint name="hand_index_virtual_2_joint" pos="0 0 0" axis="0 0 1" limited="true" range="0 0.785398" damping="0.5" />
                                                        <geom size="0.0065 0.001 0.006" pos="0.0065 0 0" type="box" />
                                                        <body name="hand_index_flex_2_link" pos="0.013 0 0">
                                                            <inertial pos="0.0047 0.0031 0" mass="0.009" diaginertia="0.001 0.001 0.001" />
                                                            <joint name="hand_index_flex_2_joint" pos="0 0 0" axis="0 0 1" limited="true" range="0 0.785398" damping="0.5" />
                                                            <geom type="mesh" mesh="finger_flex_collision" />
                                                            <body name="hand_index_virtual_3_link" pos="0.009 0 0">
                                                                <inertial pos="0.0065 0 0" mass="0.01" diaginertia="0.001 0.001 0.001" />
                                                                <joint name="hand_index_virtual_3_joint" pos="0 0 0" axis="0 0 1" limited="true" range="0 0.785398" damping="0.5" />
                                                                <geom size="0.0065 0.001 0.006" pos="0.0065 0 0" type="box" />
                                                                <body name="hand_index_flex_3_link" pos="0.013 0 0">
                                                                    <inertial pos="0.0096 0.003 0" mass="0.015" diaginertia="0.001 0.001 0.001" />
                                                                    <joint name="hand_index_flex_3_joint" pos="0 0 0" axis="0 0 1" limited="true" range="0 0.785398" damping="0.5" />
                                                                    <geom type="mesh" mesh="finger_flex_tip_collision" />
                                                                </body>
                                                            </body>
                                                        </body>
                                                    </body>
                                                </body>
                                            </body>
                                        </body>
                                        <body name="hand_middle_abd_link" pos="0.0042 0.007 0.200075" quat="0 0.707107 0 0.707107">
                                            <inertial pos="-0.0018 0 0.0028" mass="0.018" diaginertia="0.001 0.001 0.001" />
                                            <joint name="hand_middle_abd_joint" pos="0 0 0" axis="0 0 1" limited="true" range="-0.523599 0.523599" damping="0.5" />
                                            <geom type="mesh" mesh="finger_abd_collision" />
                                            <body name="hand_middle_virtual_1_link" pos="0.009 0 0" quat="0.707107 0.707107 0 0">
                                                <inertial pos="0.0065 0 0" mass="0.01" diaginertia="0.001 0.001 0.001" />
                                                <joint name="hand_middle_virtual_1_joint" pos="0 0 0" axis="0 0 1" limited="true" range="0 0.785398" damping="0.5" />
                                                <geom size="0.0065 0.001 0.006" pos="0.0065 0 0" type="box" />
                                                <body name="hand_middle_flex_1_link" pos="0.013 0 0">
                                                    <inertial pos="0.0047 0.0031 0" mass="0.009" diaginertia="0.001 0.001 0.001" />
                                                    <joint name="hand_middle_flex_1_joint" pos="0 0 0" axis="0 0 1" limited="true" range="0 0.785398" damping="0.5" />
                                                    <geom type="mesh" mesh="finger_flex_collision" />
                                                    <body name="hand_middle_virtual_2_link" pos="0.009 0 0">
                                                        <inertial pos="0.0065 0 0" mass="0.01" diaginertia="0.001 0.001 0.001" />
                                                        <joint name="hand_middle_virtual_2_joint" pos="0 0 0" axis="0 0 1" limited="true" range="0 0.785398" damping="0.5" />
                                                        <geom size="0.0065 0.001 0.006" pos="0.0065 0 0" type="box" />
                                                        <body name="hand_middle_flex_2_link" pos="0.013 0 0">
                                                            <inertial pos="0.0047 0.0031 0" mass="0.009" diaginertia="0.001 0.001 0.001" />
                                                            <joint name="hand_middle_flex_2_joint" pos="0 0 0" axis="0 0 1" limited="true" range="0 0.785398" damping="0.5" />
                                                            <geom type="mesh" mesh="finger_flex_collision" />
                                                            <body name="hand_middle_virtual_3_link" pos="0.009 0 0">
                                                                <inertial pos="0.0065 0 0" mass="0.01" diaginertia="0.001 0.001 0.001" />
                                                                <joint name="hand_middle_virtual_3_joint" pos="0 0 0" axis="0 0 1" limited="true" range="0 0.785398" damping="0.5" />
                                                                <geom size="0.0065 0.001 0.006" pos="0.0065 0 0" type="box" />
                                                                <body name="hand_middle_flex_3_link" pos="0.013 0 0">
                                                                    <inertial pos="0.0096 0.003 0" mass="0.015" diaginertia="0.001 0.001 0.001" />
                                                                    <joint name="hand_middle_flex_3_joint" pos="0 0 0" axis="0 0 1" limited="true" range="0 0.785398" damping="0.5" />
                                                                    <geom type="mesh" mesh="finger_flex_tip_collision" />
                                                                </body>
                                                            </body>
                                                        </body>
                                                    </body>
                                                </body>
                                            </body>
                                        </body>
                                        <body name="hand_ring_abd_link" pos="0.0042 -0.0125 0.193075" quat="-0.092296 0.701057 -0.092296 0.701057">
                                            <inertial pos="-0.0018 0 0.0028" mass="0.018" diaginertia="0.001 0.001 0.001" />
                                            <joint name="hand_ring_abd_joint" pos="0 0 0" axis="0 0 1" limited="true" range="-0.523599 0.523599" damping="0.5" />
                                            <geom type="mesh" mesh="finger_abd_collision" />
                                            <body name="hand_ring_virtual_1_link" pos="0.009 0 0" quat="0.707107 0.707107 0 0">
                                                <inertial pos="0.0065 0 0" mass="0.01" diaginertia="0.001 0.001 0.001" />
                                                <joint name="hand_ring_virtual_1_joint" pos="0 0 0" axis="0 0 1" limited="true" range="0 0.785398" damping="0.5" />
                                                <geom size="0.0065 0.001 0.006" pos="0.0065 0 0" type="box" />
                                                <body name="hand_ring_flex_1_link" pos="0.013 0 0">
                                                    <inertial pos="0.0047 0.0031 0" mass="0.009" diaginertia="0.001 0.001 0.001" />
                                                    <joint name="hand_ring_flex_1_joint" pos="0 0 0" axis="0 0 1" limited="true" range="0 0.785398" damping="0.5" />
                                                    <geom type="mesh" mesh="finger_flex_collision" />
                                                    <body name="hand_ring_virtual_2_link" pos="0.009 0 0">
                                                        <inertial pos="0.0065 0 0" mass="0.01" diaginertia="0.001 0.001 0.001" />
                                                        <joint name="hand_ring_virtual_2_joint" pos="0 0 0" axis="0 0 1" limited="true" range="0 0.785398" damping="0.5" />
                                                        <geom size="0.0065 0.001 0.006" pos="0.0065 0 0" type="box" />
                                                        <body name="hand_ring_flex_2_link" pos="0.013 0 0">
                                                            <inertial pos="0.0047 0.0031 0" mass="0.009" diaginertia="0.001 0.001 0.001" />
                                                            <joint name="hand_ring_flex_2_joint" pos="0 0 0" axis="0 0 1" limited="true" range="0 0.785398" damping="0.5" />
                                                            <geom type="mesh" mesh="finger_flex_collision" />
                                                            <body name="hand_ring_virtual_3_link" pos="0.009 0 0">
                                                                <inertial pos="0.0065 0 0" mass="0.01" diaginertia="0.001 0.001 0.001" />
                                                                <joint name="hand_ring_virtual_3_joint" pos="0 0 0" axis="0 0 1" limited="true" range="0 0.785398" damping="0.5" />
                                                                <geom size="0.0065 0.001 0.006" pos="0.0065 0 0" type="box" />
                                                                <body name="hand_ring_flex_3_link" pos="0.013 0 0">
                                                                    <inertial pos="0.0096 0.003 0" mass="0.015" diaginertia="0.001 0.001 0.001" />
                                                                    <joint name="hand_ring_flex_3_joint" pos="0 0 0" axis="0 0 1" limited="true" range="0 0.785398" damping="0.5" />
                                                                    <geom type="mesh" mesh="finger_flex_tip_collision" />
                                                                </body>
                                                            </body>
                                                        </body>
                                                    </body>
                                                </body>
                                            </body>
                                        </body>
                                        <body name="hand_little_abd_link" pos="0.0042 -0.032 0.183075" quat="-0.183013 0.683013 -0.183013 0.683013">
                                            <inertial pos="-0.0018 0 0.0028" mass="0.018" diaginertia="0.001 0.001 0.001" />
                                            <joint name="hand_little_abd_joint" pos="0 0 0" axis="0 0 1" limited="true" range="-0.523599 0.523599" damping="0.5" />
                                            <geom type="mesh" mesh="finger_abd_collision" />
                                            <body name="hand_little_virtual_1_link" pos="0.009 0 0" quat="0.707107 0.707107 0 0">
                                                <inertial pos="0.0065 0 0" mass="0.01" diaginertia="0.001 0.001 0.001" />
                                                <joint name="hand_little_virtual_1_joint" pos="0 0 0" axis="0 0 1" limited="true" range="0 0.785398" damping="0.5" />
                                                <geom size="0.0065 0.001 0.006" pos="0.0065 0 0" type="box" />
                                                <body name="hand_little_flex_1_link" pos="0.013 0 0">
                                                    <inertial pos="0.0047 0.0031 0" mass="0.009" diaginertia="0.001 0.001 0.001" />
                                                    <joint name="hand_little_flex_1_joint" pos="0 0 0" axis="0 0 1" limited="true" range="0 0.785398" damping="0.5" />
                                                    <geom type="mesh" mesh="finger_flex_collision" />
                                                    <body name="hand_little_virtual_2_link" pos="0.009 0 0">
                                                        <inertial pos="0.0065 0 0" mass="0.01" diaginertia="0.001 0.001 0.001" />
                                                        <joint name="hand_little_virtual_2_joint" pos="0 0 0" axis="0 0 1" limited="true" range="0 0.785398" damping="0.5" />
                                                        <geom size="0.0065 0.001 0.006" pos="0.0065 0 0" type="box" />
                                                        <body name="hand_little_flex_2_link" pos="0.013 0 0">
                                                            <inertial pos="0.0047 0.0031 0" mass="0.009" diaginertia="0.001 0.001 0.001" />
                                                            <joint name="hand_little_flex_2_joint" pos="0 0 0" axis="0 0 1" limited="true" range="0 0.785398" damping="0.5" />
                                                            <geom type="mesh" mesh="finger_flex_collision" />
                                                            <body name="hand_little_virtual_3_link" pos="0.009 0 0">
                                                                <inertial pos="0.0065 0 0" mass="0.01" diaginertia="0.001 0.001 0.001" />
                                                                <joint name="hand_little_virtual_3_joint" pos="0 0 0" axis="0 0 1" limited="true" range="0 0.785398" damping="0.5" />
                                                                <geom size="0.0065 0.001 0.006" pos="0.0065 0 0" type="box" />
                                                                <body name="hand_little_flex_3_link" pos="0.013 0 0">
                                                                    <inertial pos="0.0096 0.003 0" mass="0.015" diaginertia="0.001 0.001 0.001" />
                                                                    <joint name="hand_little_flex_3_joint" pos="0 0 0" axis="0 0 1" limited="true" range="0 0.785398" damping="0.5" />
                                                                    <geom type="mesh" mesh="finger_flex_tip_collision" />
                                                                </body>
                                                            </body>
                                                        </body>
                                                    </body>
                                                </body>
                                            </body>
                                        </body>
                                    </body>
                                </body>
                            </body>
                        </body>
                    </body>
                </body>
            </body>
        </body>
    </worldbody>
</mujoco>