<mujoco model="iai_donbot">
    <compiler angle="radian" meshdir="/home/giang/Workspace/mujoco_ws/src/mujoco_robots/iai_robots/iai_robots_mujoco/model/iai_donbot/meshes/"/>
    <size njmax="500" nconmax="100"/>
    <default/>
    <asset>
        <mesh name="base_without_wheels" file="base_without_wheels.stl"/>
        <mesh name="base" file="base.stl"/>
        <mesh name="shoulder" file="shoulder.stl"/>
        <mesh name="upperarm" file="upperarm.stl"/>
        <mesh name="forearm" file="forearm.stl"/>
        <mesh name="wrist1" file="wrist1.stl"/>
        <mesh name="wrist2" file="wrist2.stl"/>
        <mesh name="wrist3" file="wrist3.stl"/>
        <mesh name="adapter_plate_iso50_kms40_weiss" file="adapter_plate_iso50_kms40_weiss.stl" scale="0.001 0.001 0.001"/>
        <mesh name="kms40_simple" file="kms40_simple.stl" scale="0.001 0.001 0.001"/>
        <mesh name="adapter_kms40_fwk050" file="adapter_kms40_fwk050.stl" scale="0.001 0.001 0.001"/>
        <mesh name="fwk_fwa_050_simple" file="fwk_fwa_050_simple.stl" scale="0.001 0.001 0.001"/>
        <mesh name="adapter_fwa050_wsg50" file="adapter_fwa050_wsg50.stl" scale="0.001 0.001 0.001"/>
        <mesh name="WSG50_110" file="WSG50_110.stl"/>
        <mesh name="GUIDE_WSG50_110" file="GUIDE_WSG50_110.stl" scale="0.001 0.001 0.001"/>
        <mesh name="WSG-FMF" file="WSG-FMF.stl" scale="0.001 0.001 0.001"/>
        <mesh name="refills_camera_holder_and_camera" file="refills_camera_holder_and_camera.stl"/>
    </asset>
    <worldbody>
        <geom size="0.0005 0.0005 0.0005" type="box"/>
        <geom pos="0.25525 0.225 0.1616" type="mesh" rgba="0.792157 0.819608 0.933333 1" mesh="base_without_wheels"/>
        <geom size="0.3 0.2765 0.01" pos="-0.04475 -0.005 0.6216" type="box"/>
        <geom pos="-0.26975 -0.199 0.6316" quat="0 0 0 1" type="mesh" rgba="0.7 0.7 0.7 1" mesh="base"/>
        <geom size="0.06 0.2 0.225" pos="-0.40475 0 0.3866" type="box" rgba="1 1 1 1"/>
        <geom size="0.075 0.15 0.19" pos="0.33025 0 0.3516" type="box" rgba="1 1 1 1"/>
        <geom size="0.035 0.035 0.05" pos="0.22025 0.2235 0.6816" type="box" rgba="1 1 0 1"/>
        <geom size="0.125 0.07 0.025" pos="0.30525 0 0.5666" quat="0.987701 0 -0.156356 0" type="box" rgba="1 1 1 1"/>
        <geom size="0.16 0.03 0.12" pos="0.09525 -0.3105 0.5416" type="box" rgba="1 1 1 1"/>
        <body name="wheel_front_left" pos="0.38525 0.315 0.1016">
            <inertial pos="0 0 0" mass="2" diaginertia="0.01 0.01 0.01"/>
            <joint name="wheel_front_left_joint" pos="0 0 0" axis="0 1 0" limited="true" range="-1000 1000"/>
            <geom size="0.105 0.04" quat="0.707107 0.707107 0 0" type="cylinder" rgba="0.792157 0.819608 0.933333 1"/>
        </body>
        <body name="wheel_back_left" pos="-0.39275 0.315 0.1016">
            <inertial pos="0 0 0" mass="2" diaginertia="0.01 0.01 0.01"/>
            <joint name="wheel_back_left_joint" pos="0 0 0" axis="0 1 0" limited="true" range="-1000 1000"/>
            <geom size="0.105 0.04" quat="0.707107 0.707107 0 0" type="cylinder" rgba="0.792157 0.819608 0.933333 1"/>
        </body>
        <body name="wheel_front_right" pos="0.38525 -0.32 0.1016">
            <inertial pos="0 0 0" mass="2" diaginertia="0.01 0.01 0.01"/>
            <joint name="wheel_front_right_joint" pos="0 0 0" axis="0 1 0" limited="true" range="-1000 1000"/>
            <geom size="0.105 0.04" quat="0.707107 0.707107 0 0" type="cylinder" rgba="0.792157 0.819608 0.933333 1"/>
        </body>
        <body name="wheel_back_right" pos="-0.39275 -0.32 0.1016">
            <inertial pos="0 0 0" mass="2" diaginertia="0.01 0.01 0.01"/>
            <joint name="wheel_back_right_joint" pos="0 0 0" axis="0 1 0" limited="true" range="-1000 1000"/>
            <geom size="0.105 0.04" quat="0.707107 0.707107 0 0" type="cylinder" rgba="0.792157 0.819608 0.933333 1"/>
        </body>
        <body name="ur5_shoulder_link" pos="-0.26975 -0.199 0.720759" quat="0 0 0 1">
            <inertial pos="0 0 0" mass="3.7" diaginertia="0.0149724 0.0149724 0.0104063"/>
            <joint name="ur5_shoulder_pan_joint" pos="0 0 0" axis="0 0 1" limited="true" range="-6.28319 6.28319"/>
            <geom quat="0 0 0 1" type="mesh" rgba="0.7 0.7 0.7 1" mesh="shoulder"/>
            <body name="ur5_upper_arm_link" pos="0 0 0" quat="0.707107 0.707107 0 0">
                <inertial pos="-0.2125 0 0.136" quat="0.707107 0 0.707107 0" mass="8.393" diaginertia="0.133886 0.133886 0.0151074"/>
                <joint name="ur5_shoulder_lift_joint" pos="0 0 0" axis="0 0 1" limited="true" range="-6.28319 6.28319"/>
                <geom pos="0 0 0.136" quat="0.5 0.5 -0.5 -0.5" type="mesh" rgba="0.7 0.7 0.7 1" mesh="upperarm"/>
                <body name="ur5_forearm_link" pos="-0.425 0 0">
                    <inertial pos="-0.2125 0 0.0165" quat="0.707107 0 0.707107 0" mass="2.275" diaginertia="0.0312168 0.0312168 0.004095"/>
                    <joint name="ur5_elbow_joint" pos="0 0 0" axis="0 0 1" limited="true" range="-3.14159 3.14159"/>
                    <geom pos="0 0 0.0165" quat="0.5 0.5 -0.5 -0.5" type="mesh" rgba="0.7 0.7 0.7 1" mesh="forearm"/>
                    <body name="ur5_wrist_1_link" pos="-0.39225 0 0.10915">
                        <inertial pos="0 0 0" quat="0.5 0.5 -0.5 0.5" mass="1.219" diaginertia="0.00342844 0.00262426 0.00262426"/>
                        <joint name="ur5_wrist_1_joint" pos="0 0 0" axis="0 0 1" limited="true" range="-6.28319 6.28319"/>
                        <geom pos="0 0 -0.093" quat="0.707107 0.707107 0 0" type="mesh" rgba="0.7 0.7 0.7 1" mesh="wrist1"/>
                        <body name="ur5_wrist_2_link" pos="0 -0.09465 -1.9413e-11" quat="0.707107 0.707107 0 0">
                            <inertial pos="0 0 0" quat="0.5 0.5 -0.5 0.5" mass="1.219" diaginertia="0.0021942 0.00178515 0.00178515"/>
                            <joint name="ur5_wrist_2_joint" pos="0 0 0" axis="0 0 1" limited="true" range="-6.28319 6.28319"/>
                            <geom pos="0 0 -0.095" type="mesh" rgba="0.7 0.7 0.7 1" mesh="wrist2"/>
                            <body name="ur5_wrist_3_link" pos="0 0.0823 -1.688e-11" quat="0.707107 -0.707107 0 0">
                                <inertial pos="0.0177497 -0.00353721 0.0573026" quat="0.544566 0.273974 0.152579 0.777886" mass="1.67643" diaginertia="1.00446 1.00433 1.0019"/>
                                <joint name="ur5_wrist_3_joint" pos="0 0 0" axis="0 0 1" limited="true" range="-6.28319 6.28319"/>
                                <geom pos="0 0 -0.0823" quat="0.707107 0.707107 0 0" type="mesh" rgba="0.7 0.7 0.7 1" mesh="wrist3"/>
                                <geom size="0.005 0.005 0.005" pos="0 0 -0.01" quat="0.5 0.5 -0.5 0.5" type="box"/>
                                <geom quat="-0.707107 0 0 0.707107" type="mesh" rgba="0.7 0.7 0.7 1" mesh="adapter_plate_iso50_kms40_weiss"/>
                                <geom pos="0 0 0.016" quat="-0.707107 0 0 0.707107" type="mesh" rgba="0.7 0.7 0.7 1" mesh="kms40_simple"/>
                                <geom pos="0 0 0.043" quat="-0.707107 0 0 0.707107" type="mesh" rgba="0.7 0.7 0.7 1" mesh="adapter_kms40_fwk050"/>
                                <geom pos="0 0 0.053" quat="-0.707107 0 0 0.707107" type="mesh" rgba="0.7 0.7 0.7 1" mesh="fwk_fwa_050_simple"/>
                                <geom pos="0 0 0.0671" quat="-0.707107 0 0 0.707107" type="mesh" rgba="0.7 0.7 0.7 1" mesh="adapter_fwa050_wsg50"/>
                                <geom pos="0 0 0.0771" quat="-0.707107 0 0 -0.707107" type="mesh" mesh="WSG50_110"/>
                                <geom pos="0 0 0.0771" quat="0.707107 0 0 -0.707107" type="mesh" rgba="0.56 0.67 0.67 1" mesh="refills_camera_holder_and_camera"/>
                                <geom size="0.04 0.04" pos="0 0 0.038" quat="-0.707107 0 0 0.707107" type="cylinder"/>
                                <body name="gripper_gripper_left_link" pos="0 0 0.0771" quat="-0.707107 0 0 -0.707107">
                                    <inertial pos="-0.000539792 0 0.0285709" quat="0.999908 0 -0.013597 0" mass="0.2312" diaginertia="2.0005 2.0005 2"/>
                                    <joint name="gripper_base_gripper_left_joint" pos="0 0 0" axis="1 0 0" type="slide" limited="true" range="-0.055 -0.0027" damping="100" frictionloss="100"/>
                                    <geom type="mesh" rgba="0 0 0 1" mesh="GUIDE_WSG50_110"/>
                                    <geom pos="0 0 0.023" type="mesh" rgba="0 0 0 1" mesh="WSG-FMF"/>
                                    <geom size="0.004 0.015 0.065" pos="-0.004 0 0.138" type="box" rgba="0.56 0.67 0.67 1"/>
                                    <body name="gripper_gripper_right_link" pos="0 0 0" quat="1.32679e-06 0 0 1">
                                        <inertial pos="-0.000539792 0 0.0285709" quat="0.999908 0 -0.013597 0" mass="0.2312" diaginertia="2.0005 2.0005 2"/>
                                        <joint name="gripper_joint" pos="0 0 0" axis="-1 0 0" type="slide" limited="true" range="0.0065 0.109" damping="100" frictionloss="100"/>
                                        <geom type="mesh" rgba="0 0 0 1" mesh="GUIDE_WSG50_110"/>
                                        <geom pos="0 0 0.023" type="mesh" rgba="0 0 0 1" mesh="WSG-FMF"/>
                                        <geom size="0.004 0.015 0.065" pos="-0.004 0 0.138" type="box" rgba="0.56 0.67 0.67 1"/>
                                    </body>
                                </body>
                            </body>
                        </body>
                    </body>
                </body>
            </body>
        </body>
    </worldbody>
</mujoco>
