<?xml version="1.0" ?>
<robot name="main">
  <link name="world"/>
  <joint name="platform_joint" type="fixed">
    <parent link="world"/>
    <child link="platform"/>
    <origin rpy="0 0 -1.5707963267948966" xyz="0 0 0"/>
  </joint>
  <link name="platform">
    <inertial>
      <origin rpy="0 0 0" xyz="0 0 0"/>
      <mass value="100"/>
      <inertia ixx="1" ixy="0" ixz="0" iyy="1" iyz="0" izz="1"/>
    </inertial>
    <visual>
      <origin rpy="0 0 0" xyz="0 0 0"/>
      <geometry>
        <mesh filename="package://armar_description/meshes/armar6/visual/platform.obj"/>
      </geometry>
      <material name="white">
        <color rgba="1 1 1 1"/>
      </material>
    </visual>
    <collision>
      <origin rpy="0 0 0" xyz="0 0 0"/>
      <geometry>
        <mesh filename="package://armar_description/meshes/armar6/collision/platform.stl"/>
      </geometry>
    </collision>
  </link>
  <joint name="torso_joint" type="prismatic">
    <parent link="platform"/>
    <child link="torso"/>
    <origin rpy="0 0 0" xyz="0 0 1.195"/>
    <axis xyz="0 0 1"/>
    <limit effort="1000" lower="-0.365" upper="0" velocity="0.15"/>
    <dynamics damping="0.5"/>
  </joint>
  <link name="torso">
    <inertial>
      <origin rpy="0 0 0" xyz="0 0 0.0711"/>
      <mass value="9.7089"/>
      <inertia ixx="0.064445" ixy="0" ixz="0.000181" iyy="0.070569" iyz="-0.000044" izz="0.182479"/>
    </inertial>
    <visual>
      <origin rpy="0 0 0" xyz="0 0 0"/>
      <geometry>
        <mesh filename="package://armar_description/meshes/armar6/visual/torso.obj"/>
      </geometry>
      <material name="white">
        <color rgba="1 1 1 1"/>
      </material>
    </visual>
    <collision>
      <origin rpy="0 0 0" xyz="0 0 0"/>
      <geometry>
        <mesh filename="package://armar_description/meshes/armar6/collision/torso.stl"/>
      </geometry>
    </collision>
  </link>
  <joint name="lower_neck_joint" type="fixed">
    <parent link="torso"/>
    <child link="lower_neck"/>
    <origin rpy="0 0 1.5707963267948966" xyz="0 0 0.3685"/>
  </joint>
  <link name="lower_neck">
    <inertial>
      <origin rpy="0 0 0" xyz="0 0 -0.114"/>
      <mass value="0.671"/>
      <inertia ixx="2.9368849e-03" ixy="-9.8073037e-07" ixz="3.4807663e-07" iyy="3.0522742e-03" iyz="1.7456971e-07" izz="4.3647786e-03"/>
    </inertial>
    <visual>
      <origin rpy="0 0 0" xyz="0 0 0"/>
      <geometry>
        <mesh filename="package://armar_description/meshes/armar6/visual/lower_neck.obj"/>
      </geometry>
      <material name="white">
        <color rgba="1 1 1 1"/>
      </material>
    </visual>
    <collision>
      <origin rpy="0 0 0" xyz="0 0 0"/>
      <geometry>
        <mesh filename="package://armar_description/meshes/armar6/collision/lower_neck.stl"/>
      </geometry>
    </collision>
  </link>
  <joint name="middle_neck_joint" type="fixed">
    <parent link="lower_neck"/>
    <child link="middle_neck"/>
    <origin rpy="0 0 0" xyz="0 0 0"/>
  </joint>
  <link name="middle_neck">
    <inertial>
      <origin rpy="0 0 0" xyz="0 0 0"/>
      <mass value="0.304"/>
      <inertia ixx="8.3637709e-04" ixy="7.3326556e-05" ixz="3.2956579e-07" iyy="7.6398772e-04" iyz="3.8719866e-07" izz="1.0940196e-03"/>
    </inertial>
    <visual>
      <origin rpy="0 0 0" xyz="0 0 0"/>
      <geometry>
        <mesh filename="package://armar_description/meshes/armar6/visual/middle_neck.obj"/>
      </geometry>
      <material name="armar_green">
        <color rgba="0.039215686 0.447058824 0.4 1"/>
      </material>
    </visual>
    <collision>
      <origin rpy="0 0 0" xyz="0 0 0"/>
      <geometry>
        <mesh filename="package://armar_description/meshes/armar6/collision/middle_neck.stl"/>
      </geometry>
    </collision>
  </link>
  <joint name="upper_neck_joint" type="fixed">
    <parent link="middle_neck"/>
    <child link="upper_neck"/>
    <origin rpy="1.5707963267948966 0 1.5707963267948966" xyz="0 0 0"/>
  </joint>
  <link name="upper_neck">
    <inertial>
      <origin rpy="0 0 0" xyz="0 0.129 0.088"/>
      <mass value="3.307"/>
      <inertia ixx="4.2049627e-02" ixy="2.1679760e-04" ixz="1.5039253e-04" iyy="3.7165600e-04" iyz="-1.2902959e-02" izz="3.8875838e-02"/>
    </inertial>
    <visual>
      <origin rpy="0 0 0" xyz="0 0 0"/>
      <geometry>
        <mesh filename="package://armar_description/meshes/armar6/visual/upper_neck.obj"/>
      </geometry>
      <material name="white">
        <color rgba="1 1 1 1"/>
      </material>
    </visual>
    <collision>
      <origin rpy="0 0 0" xyz="0 0 0"/>
      <geometry>
        <mesh filename="package://armar_description/meshes/armar6/collision/upper_neck.stl"/>
      </geometry>
    </collision>
  </link>
  <joint name="arm_cla_joint_r0" type="fixed">
    <parent link="torso"/>
    <child link="arm_cla_r0"/>
    <origin rpy="0 0 1.5707963267948966" xyz="-0.09 0.0 0.1"/>
  </joint>
  <link name="arm_cla_r0">
    <inertial>
      <origin rpy="0 0 0" xyz="0 0 0"/>
      <mass value="1.0"/>
      <inertia ixx="0.005094" ixy="0" ixz="0" iyy="0.00445008" iyz="0" izz="0.0032066"/>
    </inertial>
    <visual>
      <origin rpy="0 0 0" xyz="0 0 0"/>
      <geometry>
        <mesh filename="package://armar_description/meshes/armar6/visual/arml_cla.obj" scale="1.016 1.016 1.016"/>
      </geometry>
      <material name="white">
        <color rgba="1 1 1 1"/>
      </material>
    </visual>
    <collision>
      <origin rpy="0 0 0" xyz="0 0 0"/>
      <geometry>
        <mesh filename="package://armar_description/meshes/armar6/collision/arml_cla.stl"/>
      </geometry>
    </collision>
  </link>
  <joint name="arm_t12_joint_r0" type="revolute">
    <parent link="arm_cla_r0"/>
    <child link="arm_t12_r0"/>
    <origin rpy="0 0 0" xyz="0 0 0"/>
    <axis xyz="0 0 1"/>
    <limit effort="240" lower="-1.3962634016" upper="1.3962634016" velocity="1.710422666954443"/>
    <dynamics damping="0.5"/>
  </joint>
  <link name="arm_t12_r0">
    <inertial>
      <origin rpy="0 0 0" xyz="0.0 0.1419 0.0283"/>
      <mass value="3.5488"/>
      <inertia ixx="0.018383" ixy="0.000021" ixz="0.000211" iyy="0.014306" iyz="-0.002042" izz="0.010714"/>
    </inertial>
    <visual>
      <origin rpy="0 0 0" xyz="0 0 0"/>
      <geometry>
        <mesh filename="package://armar_description/meshes/armar6/visual/arml_t12.obj"/>
      </geometry>
      <material name="armar_green">
        <color rgba="0.039215686 0.447058824 0.4 1"/>
      </material>
    </visual>
    <collision>
      <origin rpy="0 0 0" xyz="0 0 0"/>
      <geometry>
        <mesh filename="package://armar_description/meshes/armar6/collision/arml_t12.stl"/>
      </geometry>
    </collision>
  </link>
  <joint name="arm_t23_joint_r0" type="revolute">
    <parent link="arm_t12_r0"/>
    <child link="arm_t23_r0"/>
    <origin rpy="-1.3089971 0 0" xyz="0 0.289777748 0.077645714"/>
    <axis xyz="0 0 1"/>
    <limit effort="200" lower="-1.570796327" upper="1.570796327" velocity="1.710422666954443"/>
    <dynamics damping="0.5"/>
  </joint>
  <link name="arm_t23_r0">
    <inertial>
      <origin rpy="0 0 0" xyz="0.00015 -0.0036 0.0211"/>
      <mass value="3.03804"/>
      <inertia ixx="0.009401" ixy="-0.000018" ixz="-0.000003" iyy="0.012958" iyz="-0.000054" izz="0.013138"/>
    </inertial>
    <visual>
      <origin rpy="0 0 0" xyz="0 0 0"/>
      <geometry>
        <mesh filename="package://armar_description/meshes/armar6/visual/arml_t23.obj"/>
      </geometry>
      <material name="armar_green">
        <color rgba="0.039215686 0.447058824 0.4 1"/>
      </material>
    </visual>
    <collision>
      <origin rpy="0 0 0" xyz="0 0 0"/>
      <geometry>
        <mesh filename="package://armar_description/meshes/armar6/collision/arml_t23.stl"/>
      </geometry>
    </collision>
  </link>
  <joint name="arm_t34_joint_r0" type="revolute">
    <parent link="arm_t23_r0"/>
    <child link="arm_t34_r0"/>
    <origin rpy="1.5707963, 1.3089969 1.5707963" xyz="0 0 0"/>
    <axis xyz="0 0 1"/>
    <limit effort="200" lower="-0.24" upper="3.1" velocity="1.710422666954443"/>
    <dynamics damping="0.5"/>
  </joint>
  <link name="arm_t34_r0">
    <inertial>
      <origin rpy="0 0 0" xyz="-0.01285 0.11 0.00467"/>
      <mass value="3.46206"/>
      <inertia ixx="0.015225" ixy="0.000148" ixz="0.000739" iyy="0.011775" iyz="0.000467" izz="0.009438"/>
    </inertial>
    <visual>
      <origin rpy="0 0 0" xyz="0 0 0"/>
      <geometry>
        <mesh filename="package://armar_description/meshes/armar6/visual/arml_t34.obj"/>
      </geometry>
      <material name="armar_green">
        <color rgba="0.039215686 0.447058824 0.4 1"/>
      </material>
    </visual>
    <collision>
      <origin rpy="0 0 0" xyz="0 0 0"/>
      <geometry>
        <mesh filename="package://armar_description/meshes/armar6/collision/arml_t34.stl"/>
      </geometry>
    </collision>
  </link>
  <joint name="arm_t45_joint_r0" type="revolute">
    <parent link="arm_t34_r0"/>
    <child link="arm_t45_r0"/>
    <origin rpy="-1.5707963 0 0" xyz="0 0 0"/>
    <axis xyz="0 0 1"/>
    <limit effort="200" lower="-1.570796327" upper="1.570796327" velocity="1.710422666954443"/>
    <dynamics damping="0.5"/>
  </joint>
  <link name="arm_t45_r0">
    <inertial>
      <origin rpy="0 0 0" xyz="0.0163 -0.0332 0.315"/>
      <mass value="3.31477"/>
      <inertia ixx="0.018629" ixy="0.000853" ixz="-0.00045" iyy="0.011775" iyz="0.004029" izz="0.017761"/>
    </inertial>
    <visual>
      <origin rpy="0 0 0" xyz="0 0 0"/>
      <geometry>
        <mesh filename="package://armar_description/meshes/armar6/visual/arml_t45.obj"/>
      </geometry>
      <material name="armar_green">
        <color rgba="0.039215686 0.447058824 0.4 1"/>
      </material>
    </visual>
    <collision>
      <origin rpy="0 0 0" xyz="0 0 0"/>
      <geometry>
        <mesh filename="package://armar_description/meshes/armar6/collision/arml_t45.stl"/>
      </geometry>
    </collision>
  </link>
  <joint name="arm_t56_joint_r0" type="revolute">
    <parent link="arm_t45_r0"/>
    <child link="arm_t56_r0"/>
    <origin rpy="0 1.5707963 0" xyz="0 -0.055 0.409"/>
    <axis xyz="0 0 1"/>
    <limit effort="200" lower="0" upper="2.51" velocity="1.710422666954443"/>
    <dynamics damping="0.5"/>
  </joint>
  <link name="arm_t56_r0">
    <inertial>
      <origin rpy="0 0 0" xyz="-0.09107 0.00476 -0.00899"/>
      <mass value="2.63888"/>
      <inertia ixx="0.007551" ixy="0.000371" ixz="0.000125" iyy="0.009482" iyz="0.000003" izz="0.011298"/>
    </inertial>
    <visual>
      <origin rpy="0 0 0" xyz="0 0 0"/>
      <geometry>
        <mesh filename="package://armar_description/meshes/armar6/visual/arml_t56.obj"/>
      </geometry>
      <material name="armar_green">
        <color rgba="0.039215686 0.447058824 0.4 1"/>
      </material>
    </visual>
    <collision>
      <origin rpy="0 0 0" xyz="0 0 0"/>
      <geometry>
        <mesh filename="package://armar_description/meshes/armar6/collision/arml_t56.stl"/>
      </geometry>
    </collision>
  </link>
  <joint name="arm_t67_joint_r0" type="revolute">
    <parent link="arm_t56_r0"/>
    <child link="arm_t67_r0"/>
    <origin rpy="0 -1.5707963 0" xyz="0 0 0"/>
    <axis xyz="0 0 1"/>
    <limit effort="200" lower="-1.570796327" upper="1.570796327" velocity="1.710422666954443"/>
    <dynamics damping="0.5"/>
  </joint>
  <link name="arm_t67_r0">
    <inertial>
      <origin rpy="0 0 0" xyz="0.00107 0.01939 0.25303"/>
      <mass value="2.71787"/>
      <inertia ixx="0.011854" ixy="0.000068" ixz="0.000083" iyy="0.007149" iyz="-0.00184" izz="0.0095"/>
    </inertial>
    <visual>
      <origin rpy="0 0 0" xyz="0 0 0"/>
      <geometry>
        <mesh filename="package://armar_description/meshes/armar6/visual/arml_t67.obj"/>
      </geometry>
      <material name="white">
        <color rgba="1 1 1 1"/>
      </material>
    </visual>
    <collision>
      <origin rpy="0 0 0" xyz="0 0 0"/>
      <geometry>
        <mesh filename="package://armar_description/meshes/armar6/collision/arml_t67.stl"/>
      </geometry>
    </collision>
  </link>
  <joint name="arm_t78_joint_r0" type="revolute">
    <parent link="arm_t67_r0"/>
    <child link="arm_t78_r0"/>
    <origin rpy="1.5707963 0 0" xyz="0 0 0.364"/>
    <axis xyz="0 0 1"/>
    <limit effort="200" lower="-0.64" upper="0.64" velocity="1.710422666954443"/>
    <dynamics damping="0.5"/>
  </joint>
  <link name="arm_t78_r0">
    <inertial>
      <origin rpy="0 0 0" xyz="-0.00657 -0.00467 0.01181"/>
      <mass value="1.62346"/>
      <inertia ixx="0.001552" ixy="0.000014" ixz="-0.000018" iyy="0.001959" iyz="0.000002" izz="0.002392"/>
    </inertial>
    <visual>
      <origin rpy="0 0 0" xyz="0 0 0"/>
      <geometry>
        <mesh filename="package://armar_description/meshes/armar6/visual/arml_t78.obj"/>
      </geometry>
      <material name="white">
        <color rgba="1 1 1 1"/>
      </material>
    </visual>
    <collision>
      <origin rpy="0 0 0" xyz="0 0 0"/>
      <geometry>
        <mesh filename="package://armar_description/meshes/armar6/collision/arml_t78.stl"/>
      </geometry>
    </collision>
  </link>
  <joint name="arm_t8_joint_r0" type="revolute">
    <parent link="arm_t78_r0"/>
    <child link="arm_t8_r0"/>
    <origin rpy="-1.5707963 1.5707963 0" xyz="0 0 0.0"/>
    <axis xyz="0 -1 0"/>
    <limit effort="200" lower="-1.52" upper="1.52" velocity="1.710422666954443"/>
    <dynamics damping="0.5"/>
  </joint>
  <link name="arm_t8_r0">
    <inertial>
      <origin rpy="0 0 0" xyz="-0.0120 0.0267 0.094"/>
      <mass value="0.528074"/>
      <inertia ixx="0.002188" ixy="0.000007" ixz="-0.000004" iyy="0.001519" iyz="0.000256" izz="0.001176"/>
    </inertial>
    <visual>
      <origin rpy="0 0 0" xyz="0 0 0"/>
      <geometry>
        <mesh filename="package://armar_description/meshes/armar6/visual/arml_t8.obj"/>
      </geometry>
      <material name="white">
        <color rgba="1 1 1 1"/>
      </material>
    </visual>
    <collision>
      <origin rpy="0 0 0" xyz="0 0 0"/>
      <geometry>
        <mesh filename="package://armar_description/meshes/armar6/collision/arml_t8.stl"/>
      </geometry>
    </collision>
  </link>
  <joint name="hand_fixed_joint_r0" type="fixed">
    <parent link="arm_t8_r0"/>
    <child link="hand_fixed_r0"/>
    <origin rpy="0 0 0" xyz="-0.022 0 0.2645"/>
  </joint>
  <link name="hand_fixed_r0">
    <inertial>
      <origin rpy="0 0 0" xyz="0.015 0.0 -0.025"/>
      <mass value="0.985765"/>
      <inertia ixx="0.0074021" ixy="0" ixz="0" iyy="0.008008" iyz="0" izz="0.0032670"/>
    </inertial>
    <visual>
      <origin rpy="0 0 0" xyz="0 0 0"/>
      <geometry>
        <mesh filename="package://armar_description/meshes/armar6/visual/left_hand_fixed.obj"/>
      </geometry>
      <material name="armar_metal">
        <color rgba="0.251 0.251 0.251 1"/>
      </material>
    </visual>
    <collision>
      <origin rpy="0 0 0" xyz="0 0 0"/>
      <geometry>
        <mesh filename="package://armar_description/meshes/armar6/collision/left_hand_fixed.obj"/>
      </geometry>
    </collision>
  </link>
  <joint name="arm_cla_joint_r1" type="fixed">
    <parent link="torso"/>
    <child link="arm_cla_r1"/>
    <origin rpy="0 0 -1.5707963267948966" xyz="0.09 0.0 0.1"/>
  </joint>
  <link name="arm_cla_r1">
    <inertial>
      <origin rpy="0 0 0" xyz="0 0 0"/>
      <mass value="1.0"/>
      <inertia ixx="0.005094" ixy="0" ixz="0" iyy="0.00445008" iyz="0" izz="0.0032066"/>
    </inertial>
    <visual>
      <origin rpy="0 0 0" xyz="0 0 0"/>
      <geometry>
        <mesh filename="package://armar_description/meshes/armar6/visual/arml_cla.obj" scale="1.016 1.016 1.016"/>
      </geometry>
      <material name="white">
        <color rgba="1 1 1 1"/>
      </material>
    </visual>
    <collision>
      <origin rpy="0 0 0" xyz="0 0 0"/>
      <geometry>
        <mesh filename="package://armar_description/meshes/armar6/collision/arml_cla.stl"/>
      </geometry>
    </collision>
  </link>
  <joint name="arm_t12_joint_r1" type="revolute">
    <parent link="arm_cla_r1"/>
    <child link="arm_t12_r1"/>
    <origin rpy="0 0 0" xyz="0 0 0"/>
    <axis xyz="0 0 1"/>
    <limit effort="240" lower="-1.3962634016" upper="1.3962634016" velocity="1.710422666954443"/>
    <dynamics damping="0.5"/>
  </joint>
  <link name="arm_t12_r1">
    <inertial>
      <origin rpy="0 0 0" xyz="0.0 0.1419 0.0283"/>
      <mass value="3.5488"/>
      <inertia ixx="0.018383" ixy="0.000021" ixz="0.000211" iyy="0.014306" iyz="-0.002042" izz="0.010714"/>
    </inertial>
    <visual>
      <origin rpy="0 0 0" xyz="0 0 0"/>
      <geometry>
        <mesh filename="package://armar_description/meshes/armar6/visual/arml_t12.obj"/>
      </geometry>
      <material name="armar_green">
        <color rgba="0.039215686 0.447058824 0.4 1"/>
      </material>
    </visual>
    <collision>
      <origin rpy="0 0 0" xyz="0 0 0"/>
      <geometry>
        <mesh filename="package://armar_description/meshes/armar6/collision/arml_t12.stl"/>
      </geometry>
    </collision>
  </link>
  <joint name="arm_t23_joint_r1" type="revolute">
    <parent link="arm_t12_r1"/>
    <child link="arm_t23_r1"/>
    <origin rpy="-1.3089971 0 0" xyz="0 0.289777748 0.077645714"/>
    <axis xyz="0 0 1"/>
    <limit effort="200" lower="-1.570796327" upper="1.570796327" velocity="1.710422666954443"/>
    <dynamics damping="0.5"/>
  </joint>
  <link name="arm_t23_r1">
    <inertial>
      <origin rpy="0 0 0" xyz="0.00015 -0.0036 0.0211"/>
      <mass value="3.03804"/>
      <inertia ixx="0.009401" ixy="-0.000018" ixz="-0.000003" iyy="0.012958" iyz="-0.000054" izz="0.013138"/>
    </inertial>
    <visual>
      <origin rpy="0 0 0" xyz="0 0 0"/>
      <geometry>
        <mesh filename="package://armar_description/meshes/armar6/visual/arml_t23.obj"/>
      </geometry>
      <material name="armar_green">
        <color rgba="0.039215686 0.447058824 0.4 1"/>
      </material>
    </visual>
    <collision>
      <origin rpy="0 0 0" xyz="0 0 0"/>
      <geometry>
        <mesh filename="package://armar_description/meshes/armar6/collision/arml_t23.stl"/>
      </geometry>
    </collision>
  </link>
  <joint name="arm_t34_joint_r1" type="revolute">
    <parent link="arm_t23_r1"/>
    <child link="arm_t34_r1"/>
    <origin rpy="1.5707963, 1.3089969 1.5707963" xyz="0 0 0"/>
    <axis xyz="0 0 1"/>
    <limit effort="200" lower="-0.24" upper="3.1" velocity="1.710422666954443"/>
    <dynamics damping="0.5"/>
  </joint>
  <link name="arm_t34_r1">
    <inertial>
      <origin rpy="0 0 0" xyz="-0.01285 0.11 0.00467"/>
      <mass value="3.46206"/>
      <inertia ixx="0.015225" ixy="0.000148" ixz="0.000739" iyy="0.011775" iyz="0.000467" izz="0.009438"/>
    </inertial>
    <visual>
      <origin rpy="0 0 0" xyz="0 0 0"/>
      <geometry>
        <mesh filename="package://armar_description/meshes/armar6/visual/arml_t34.obj"/>
      </geometry>
      <material name="armar_green">
        <color rgba="0.039215686 0.447058824 0.4 1"/>
      </material>
    </visual>
    <collision>
      <origin rpy="0 0 0" xyz="0 0 0"/>
      <geometry>
        <mesh filename="package://armar_description/meshes/armar6/collision/arml_t34.stl"/>
      </geometry>
    </collision>
  </link>
  <joint name="arm_t45_joint_r1" type="revolute">
    <parent link="arm_t34_r1"/>
    <child link="arm_t45_r1"/>
    <origin rpy="-1.5707963 3.141592654 0" xyz="0 0 0"/>
    <axis xyz="0 0 1"/>
    <limit effort="200" lower="-1.570796327" upper="1.570796327" velocity="1.710422666954443"/>
    <dynamics damping="0.5"/>
  </joint>
  <link name="arm_t45_r1">
    <inertial>
      <origin rpy="0 0 0" xyz="0.0163 -0.0332 0.315"/>
      <mass value="3.31477"/>
      <inertia ixx="0.018629" ixy="0.000853" ixz="-0.00045" iyy="0.011775" iyz="0.004029" izz="0.017761"/>
    </inertial>
    <visual>
      <origin rpy="0 0 0" xyz="0 0 0"/>
      <geometry>
        <mesh filename="package://armar_description/meshes/armar6/visual/arml_t45.obj"/>
      </geometry>
      <material name="armar_green">
        <color rgba="0.039215686 0.447058824 0.4 1"/>
      </material>
    </visual>
    <collision>
      <origin rpy="0 0 0" xyz="0 0 0"/>
      <geometry>
        <mesh filename="package://armar_description/meshes/armar6/collision/arml_t45.stl"/>
      </geometry>
    </collision>
  </link>
  <joint name="arm_t56_joint_r1" type="revolute">
    <parent link="arm_t45_r1"/>
    <child link="arm_t56_r1"/>
    <origin rpy="0 1.5707963 0" xyz="0 -0.055 0.409"/>
    <axis xyz="0 0 1"/>
    <limit effort="200" lower="0" upper="2.51" velocity="1.710422666954443"/>
    <dynamics damping="0.5"/>
  </joint>
  <link name="arm_t56_r1">
    <inertial>
      <origin rpy="0 0 0" xyz="-0.09107 0.00476 -0.00899"/>
      <mass value="2.63888"/>
      <inertia ixx="0.007551" ixy="0.000371" ixz="0.000125" iyy="0.009482" iyz="0.000003" izz="0.011298"/>
    </inertial>
    <visual>
      <origin rpy="0 0 0" xyz="0 0 0"/>
      <geometry>
        <mesh filename="package://armar_description/meshes/armar6/visual/arml_t56.obj"/>
      </geometry>
      <material name="armar_green">
        <color rgba="0.039215686 0.447058824 0.4 1"/>
      </material>
    </visual>
    <collision>
      <origin rpy="0 0 0" xyz="0 0 0"/>
      <geometry>
        <mesh filename="package://armar_description/meshes/armar6/collision/arml_t56.stl"/>
      </geometry>
    </collision>
  </link>
  <joint name="arm_t67_joint_r1" type="revolute">
    <parent link="arm_t56_r1"/>
    <child link="arm_t67_r1"/>
    <origin rpy="0 -1.5707963 0" xyz="0 0 0"/>
    <axis xyz="0 0 1"/>
    <limit effort="200" lower="-1.570796327" upper="1.570796327" velocity="1.710422666954443"/>
    <dynamics damping="0.5"/>
  </joint>
  <link name="arm_t67_r1">
    <inertial>
      <origin rpy="0 0 0" xyz="0.00107 0.01939 0.25303"/>
      <mass value="2.71787"/>
      <inertia ixx="0.011854" ixy="0.000068" ixz="0.000083" iyy="0.007149" iyz="-0.00184" izz="0.0095"/>
    </inertial>
    <visual>
      <origin rpy="0 0 0" xyz="0 0 0"/>
      <geometry>
        <mesh filename="package://armar_description/meshes/armar6/visual/arml_t67.obj"/>
      </geometry>
      <material name="white">
        <color rgba="1 1 1 1"/>
      </material>
    </visual>
    <collision>
      <origin rpy="0 0 0" xyz="0 0 0"/>
      <geometry>
        <mesh filename="package://armar_description/meshes/armar6/collision/arml_t67.stl"/>
      </geometry>
    </collision>
  </link>
  <joint name="arm_t78_joint_r1" type="revolute">
    <parent link="arm_t67_r1"/>
    <child link="arm_t78_r1"/>
    <origin rpy="1.5707963 0 0" xyz="0 0 0.364"/>
    <axis xyz="0 0 1"/>
    <limit effort="200" lower="-0.64" upper="0.64" velocity="1.710422666954443"/>
    <dynamics damping="0.5"/>
  </joint>
  <link name="arm_t78_r1">
    <inertial>
      <origin rpy="0 0 0" xyz="-0.00657 -0.00467 0.01181"/>
      <mass value="1.62346"/>
      <inertia ixx="0.001552" ixy="0.000014" ixz="-0.000018" iyy="0.001959" iyz="0.000002" izz="0.002392"/>
    </inertial>
    <visual>
      <origin rpy="0 0 0" xyz="0 0 0"/>
      <geometry>
        <mesh filename="package://armar_description/meshes/armar6/visual/arml_t78.obj"/>
      </geometry>
      <material name="white">
        <color rgba="1 1 1 1"/>
      </material>
    </visual>
    <collision>
      <origin rpy="0 0 0" xyz="0 0 0"/>
      <geometry>
        <mesh filename="package://armar_description/meshes/armar6/collision/arml_t78.stl"/>
      </geometry>
    </collision>
  </link>
  <joint name="arm_t8_joint_r1" type="revolute">
    <parent link="arm_t78_r1"/>
    <child link="arm_t8_r1"/>
    <origin rpy="-1.5707963 1.5707963 0" xyz="0 0 0.0"/>
    <axis xyz="0 -1 0"/>
    <limit effort="200" lower="-1.52" upper="1.52" velocity="1.710422666954443"/>
    <dynamics damping="0.5"/>
  </joint>
  <link name="arm_t8_r1">
    <inertial>
      <origin rpy="0 0 0" xyz="-0.0120 0.0267 0.094"/>
      <mass value="0.528074"/>
      <inertia ixx="0.002188" ixy="0.000007" ixz="-0.000004" iyy="0.001519" iyz="0.000256" izz="0.001176"/>
    </inertial>
    <visual>
      <origin rpy="0 0 0" xyz="0 0 0"/>
      <geometry>
        <mesh filename="package://armar_description/meshes/armar6/visual/arml_t8.obj"/>
      </geometry>
      <material name="white">
        <color rgba="1 1 1 1"/>
      </material>
    </visual>
    <collision>
      <origin rpy="0 0 0" xyz="0 0 0"/>
      <geometry>
        <mesh filename="package://armar_description/meshes/armar6/collision/arml_t8.stl"/>
      </geometry>
    </collision>
  </link>
  <joint name="hand_fixed_joint_r1" type="fixed">
    <parent link="arm_t8_r1"/>
    <child link="hand_fixed_r1"/>
    <origin rpy="0 0 0" xyz="-0.022 0 0.2645"/>
  </joint>
  <link name="hand_fixed_r1">
    <inertial>
      <origin rpy="0 0 0" xyz="0.015 0.0 -0.025"/>
      <mass value="0.985765"/>
      <inertia ixx="0.007464023" ixy="0" ixz="0" iyy="0.0081043" iyz="0" izz="0.0033194"/>
    </inertial>
    <visual>
      <origin rpy="0 0 0" xyz="0 0 0"/>
      <geometry>
        <mesh filename="package://armar_description/meshes/armar6/visual/right_hand_fixed.obj"/>
      </geometry>
      <material name="armar_metal">
        <color rgba="0.251 0.251 0.251 1"/>
      </material>
    </visual>
    <collision>
      <origin rpy="0 0 0" xyz="0 0 0"/>
      <geometry>
        <mesh filename="package://armar_description/meshes/armar6/collision/right_hand_fixed.obj"/>
      </geometry>
    </collision>
  </link>
</robot>
