<?xml version="1.0" ?>
<robot name="main">
  <link name="base">
    <inertial>
      <origin rpy="0 0 0" xyz="0 0 0"/>
      <mass value="0.00001"/>
      <inertia ixx="1" ixy="0" ixz="0" iyy="1" iyz="0" izz="1"/>
    </inertial>
  </link>
  <joint name="root_joint" type="fixed">
    <parent link="base"/>
    <child link="root"/>
    <origin rpy="0 0 1.5707964" xyz="0 0 1.0225"/>
  </joint>
  <link name="root">
    <inertial>
      <origin rpy="0 0 0" xyz="0 0 -0.0464755"/>
      <mass value="5"/>
      <inertia ixx="0.0570551" ixy="0" ixz="0" iyy="0.0867303" iyz="0" izz="0.101375"/>
    </inertial>
    <visual>
      <origin rpy="0 0 0" xyz="0 0 0"/>
      <geometry>
        <mesh filename="package://armar_description/meshes/armar4/visual/root.obj"/>
      </geometry>
      <material name="grey">
        <color rgba="0.537 0.537 0.537 1"/>
      </material>
    </visual>
    <collision>
      <origin rpy="0 0 0" xyz="0 0 0"/>
      <geometry>
        <mesh filename="package://armar_description/meshes/armar4/collision/root.stl"/>
      </geometry>
    </collision>
  </link>
  <joint name="leg_hip1_joint_r0" type="revolute">
    <parent link="root"/>
    <child link="leg_hip1_r0"/>
    <origin rpy="0 -0.6154033 0" xyz="0.124 0 -0.126"/>
    <axis xyz="0 0 1"/>
    <limit effort="240" lower="-0.4906" upper="1.5809" velocity="1.710422666954443"/>
    <dynamics damping="0.5"/>
  </joint>
  <link name="leg_hip1_r0">
    <inertial>
      <origin rpy="0 0 0" xyz="-0.0114784 -0.0190205 0.0463836"/>
      <mass value="1.33"/>
      <inertia ixx="0.00676843" ixy="0" ixz="0" iyy="0.00676843" iyz="0" izz="0.00453669"/>
    </inertial>
    <visual>
      <origin rpy="0 0 0" xyz="0 0 0"/>
      <geometry>
        <mesh filename="package://armar_description/meshes/armar4/visual/legl_hip1_joint.obj"/>
      </geometry>
      <material name="white">
        <color rgba="1 1 1 1"/>
      </material>
    </visual>
    <collision>
      <origin rpy="0 0 0" xyz="0 0 0"/>
      <geometry>
        <mesh filename="package://armar_description/meshes/armar4/collision/legl_hip1_joint.stl"/>
      </geometry>
    </collision>
  </link>
  <joint name="leg_hip2_joint_r0" type="revolute">
    <parent link="leg_hip1_r0"/>
    <child link="leg_hip2_r0"/>
    <origin rpy="0 -1.5707962 0.7853983" xyz="0 0 0"/>
    <axis xyz="0 0 1"/>
    <limit effort="240" lower="-0.1853" upper="0.6542" velocity="1.710422666954443"/>
    <!-- 
     <limit effort="240" lower="-0.1853" upper="0.6542" velocity="1.710422666954443"/>
     <limit effort="240" lower="-0.1853" upper="0.1853" velocity="0.3"/> 
    -->
    <dynamics damping="0.5"/>
  </joint>
  <link name="leg_hip2_r0">
    <inertial>
      <origin rpy="0 0 0" xyz="-0.000313077 0.0280972 0.00778463"/>
      <mass value="0.36"/>
      <inertia ixx="0.000773543" ixy="0" ixz="0" iyy="0.000379211" iyz="0" izz="0.000858843"/>
    </inertial>
    <visual>
      <origin rpy="0 0 0" xyz="0 0 0"/>
      <geometry>
        <mesh filename="package://armar_description/meshes/armar4/visual/legl_hip2_joint.obj"/>
      </geometry>
      <material name="grey">
        <color rgba="0.537 0.537 0.537 1"/>
      </material>
    </visual>
    <collision>
      <origin rpy="0 0 0" xyz="0 0 0"/>
      <geometry>
        <mesh filename="package://armar_description/meshes/armar4/collision/legl_hip2_joint.stl"/>
      </geometry>
    </collision>
  </link>
  <joint name="leg_hip3_joint_r0" type="revolute">
    <parent link="leg_hip2_r0"/>
    <child link="leg_hip3_r0"/>
    <origin rpy="-1.5707964 0 0" xyz="0 0 0"/>
    <axis xyz="0 0 1"/>
    <limit effort="240" lower="-0.9812" upper="0.8177" velocity="1.710422666954443"/>
    <dynamics damping="0.5"/>
  </joint>
  <link name="leg_hip3_r0">
    <inertial>
      <origin rpy="0 0 0" xyz="-0.149052 -0.134842 0.0788454"/>
      <mass value="5.06"/>
      <inertia ixx="0.0570551" ixy="0" ixz="0" iyy="0.0867303" iyz="0" izz="0.101375"/>
    </inertial>
    <visual>
      <origin rpy="0 0 0" xyz="0 0 0"/>
      <geometry>
        <mesh filename="package://armar_description/meshes/armar4/visual/legl_hip3_joint.obj"/>
      </geometry>
      <material name="white">
        <color rgba="1 1 1 1"/>
      </material>
    </visual>
    <collision>
      <origin rpy="0 0 0" xyz="0 0 0"/>
      <geometry>
        <mesh filename="package://armar_description/meshes/armar4/collision/legl_hip3_joint.stl"/>
      </geometry>
    </collision>
  </link>
  <joint name="leg_knee_joint_r0" type="revolute">
    <parent link="leg_hip3_r0"/>
    <child link="leg_knee_r0"/>
    <origin rpy="2.0943953 0.615403 2.3561942" xyz="-0.303136 -0.197542 0.173784"/>
    <axis xyz="1 0 0"/>
    <limit effort="240" lower="0" upper="1.6354" velocity="1.710422666954443"/>
    <dynamics damping="0.5"/>
  </joint>
  <link name="leg_knee_r0">
    <inertial>
      <origin rpy="0 0 0" xyz="0.0200931 0.0134739 -0.186405"/>
      <mass value="4.25"/>
      <inertia ixx="0.089890" ixy="0" ixz="0" iyy="0.0880982" iyz="0" izz="0.0122883"/>
    </inertial>
    <visual>
      <origin rpy="0 0 0" xyz="0 0 0"/>
      <geometry>
        <mesh filename="package://armar_description/meshes/armar4/visual/legl_knee_joint.obj"/>
      </geometry>
      <material name="white">
        <color rgba="1 1 1 1"/>
      </material>
    </visual>
    <collision>
      <origin rpy="0 0 0" xyz="0 0 0"/>
      <geometry>
        <mesh filename="package://armar_description/meshes/armar4/collision/legl_knee_joint.stl"/>
      </geometry>
    </collision>
  </link>
  <joint name="leg_ank1_joint_r0" type="revolute">
    <parent link="leg_knee_r0"/>
    <child link="leg_ank1_r0"/>
    <origin rpy="0 -1.5707963 0" xyz="0 0 -0.4085"/>
    <axis xyz="0 0 1"/>
    <limit effort="240" lower="-0.4906" upper="0.4906" velocity="1.710422666954443"/>
    <dynamics damping="0.5"/>
  </joint>
  <link name="leg_ank1_r0">
    <inertial>
      <origin rpy="0 0 0" xyz="0 0 0"/>
      <mass value="0.5"/>
      <inertia ixx="0.089890" ixy="0" ixz="0" iyy="0.0880982" iyz="0" izz="0.0122883"/>
    </inertial>
    <visual>
      <origin rpy="0 0 0" xyz="0 0 0"/>
      <geometry>
        <sphere radius="0.00"/>
      </geometry>
      <material name="white">
        <color rgba="1 1 1 1"/>
      </material>
    </visual>
    <collision>
      <origin rpy="0 0 0" xyz="0 0 0"/>
      <geometry>
        <sphere radius="0.00"/>
      </geometry>
    </collision>
  </link>
  <joint name="leg_ank2_joint_r0" type="revolute">
    <parent link="leg_ank1_r0"/>
    <child link="leg_ank2_r0"/>
    <origin rpy="1.5707964 0 0" xyz="0 0 0"/>
    <axis xyz="0 0 1"/>
    <limit effort="240" lower="-0.06" upper="0.06" velocity="1.710422666954443"/>
    <dynamics damping="0.5"/>
  </joint>
  <link name="leg_ank2_r0">
    <inertial>
      <origin rpy="0 0 0" xyz="-0.0328382 -0.0160825 0.0358811"/>
      <mass value="1.94"/>
      <inertia ixx="0.0105498" ixy="0" ixz="0" iyy="0.0103366" iyz="0" izz="0.00444324"/>
    </inertial>
    <visual>
      <origin rpy="0 0 0" xyz="0 0 0"/>
      <geometry>
        <mesh filename="package://armar_description/meshes/armar4/visual/legl_ank2_joint.obj"/>
      </geometry>
      <material name="white">
        <color rgba="1 1 1 1"/>
      </material>
    </visual>
    <collision>
      <origin rpy="0 0 0" xyz="0 0 0"/>
      <geometry>
        <mesh filename="package://armar_description/meshes/armar4/collision/legl_ank2_joint.stl"/>
      </geometry>
    </collision>
  </link>
  <joint name="leg_heel_joint_r0" type="fixed">
    <parent link="leg_ank2_r0"/>
    <child link="leg_heel_r0"/>
    <origin rpy="-1.5707964 0 0" xyz="-0.0795 0 -0.053"/>
  </joint>
  <link name="leg_heel_r0">
    <inertial>
      <origin rpy="0 0 0" xyz="-0.00118398 0.00843963 -0.00707974"/>
      <mass value="0.05"/>
      <inertia ixx="1.59042e-05" ixy="0" ixz="0" iyy="9.82349e-06" iyz="0" izz="7.28604e-06"/>
    </inertial>
    <visual>
      <origin rpy="0 0 0" xyz="0 0 0"/>
      <geometry>
        <mesh filename="package://armar_description/meshes/armar4/visual/legl_heel_joint.obj"/>
      </geometry>
      <material name="light_grey">
        <color rgba="0.796078431 0.796078431 0.752941176 1"/>
      </material>
    </visual>
    <collision>
      <origin rpy="0 0 0" xyz="0 0 0"/>
      <geometry>
        <mesh filename="package://armar_description/meshes/armar4/collision/legl_heel_joint.stl"/>
      </geometry>
    </collision>
  </link>
  <joint name="leg_toe_joint_r0" type="fixed">
    <parent link="leg_ank2_r0"/>
    <child link="leg_toe_r0"/>
    <origin rpy="-1.5707964 0 0" xyz="-0.07424 0.0244 0.13112"/>
    <!-- 
    <axis xyz="0 0 1"/>
    <limit effort="240" lower="0" upper="0.785398" velocity="1.710422666954443"/>
    <dynamics damping="0.5"/> 
    -->
  </joint>
  <link name="leg_toe_r0">
    <inertial>
      <origin rpy="0 0 0" xyz="-0.00450309 -0.0217059 0.003872"/>
      <mass value="0.13"/>
      <inertia ixx="9.91014e-05" ixy="0" ixz="0" iyy="7.72887e-05" iyz="0" izz="2.81054e-05"/>
    </inertial>
    <visual>
      <origin rpy="0 0 0" xyz="0 0 0"/>
      <geometry>
        <mesh filename="package://armar_description/meshes/armar4/visual/legl_toe_joint.obj"/>
      </geometry>
      <material name="light_grey">
        <color rgba="0.796078431 0.796078431 0.752941176 1"/>
      </material>
    </visual>
    <collision>
      <origin rpy="0 0 0" xyz="0 0 0"/>
      <geometry>
        <mesh filename="package://armar_description/meshes/armar4/collision/legl_toe_joint.stl"/>
      </geometry>
    </collision>
  </link>
  <joint name="leg_toe2_joint_r0" type="fixed">
    <parent link="leg_ank2_r0"/>
    <child link="leg_toe2_r0"/>
    <origin rpy="-1.1344644 0 0" xyz="-0.0742 -0.006 0.1311"/>
    <!-- 
    <axis xyz="0 0 1"/>
    <limit effort="240" lower="0" upper="0.785398" velocity="1.710422666954443"/>
    <dynamics damping="0.5"/>
    --> 
  </joint>
  <link name="leg_toe2_r0">
    <inertial>
      <origin rpy="0 0 0" xyz="-0.00364243 -0.0248759 -0.0129597"/>
      <mass value="0.13"/>
      <inertia ixx="9.91014e-05" ixy="0" ixz="0" iyy="7.72887e-05" iyz="0" izz="2.81054e-05"/>
    </inertial>
    <visual>
      <origin rpy="0 0 0" xyz="0 0 0"/>
      <geometry>
        <mesh filename="package://armar_description/meshes/armar4/visual/legl_toe2_joint.obj"/>
      </geometry>
      <material name="light_grey">
        <color rgba="0.796078431 0.796078431 0.752941176 1"/>
      </material>
    </visual>
    <collision>
      <origin rpy="0 0 0" xyz="0 0 0"/>
      <geometry>
        <mesh filename="package://armar_description/meshes/armar4/collision/legl_toe2_joint.stl"/>
      </geometry>
    </collision>
  </link>
  <joint name="leg_hip1_joint_r1" type="revolute">
    <parent link="root"/>
    <child link="leg_hip1_r1"/>
    <origin rpy="3.1415927 0.6154033 0" xyz="-0.124 0 -0.126"/>
    <axis xyz="0 0 1"/>
    <limit effort="240" lower="-0.4906" upper="1.5809" velocity="1.710422666954443"/>
    <dynamics damping="0.5"/>
  </joint>
  <link name="leg_hip1_r1">
    <inertial>
      <origin rpy="0 0 0" xyz="0.00955501 0.0122137 -0.0512045"/>
      <mass value="1.33"/>
      <inertia ixx="0.00676843" ixy="0" ixz="0" iyy="0.00676844" iyz="0" izz="0.00453669"/>
    </inertial>
    <visual>
      <origin rpy="0 0 0" xyz="0 0 0"/>
      <geometry>
        <mesh filename="package://armar_description/meshes/armar4/visual/legr_hip1_joint.obj"/>
      </geometry>
      <material name="white">
        <color rgba="1 1 1 1"/>
      </material>
    </visual>
    <collision>
      <origin rpy="0 0 0" xyz="0 0 0"/>
      <geometry>
        <mesh filename="package://armar_description/meshes/armar4/collision/legr_hip1_joint.stl"/>
      </geometry>
    </collision>
  </link>  
  <joint name="leg_hip2_joint_r1" type="revolute">
    <parent link="leg_hip1_r1"/>
    <child link="leg_hip2_r1"/>
    <origin rpy="0 -1.5707962 0.7853983" xyz="0 0 0"/>
    <axis xyz="0 0 1"/>
    <limit effort="240" lower="-0.1853" upper="0.6541" velocity="1.710422666954443"/>
    <!-- 
     <limit effort="240" lower="-0.1853" upper="0.1853" velocity="0.3"/>  
    -->
    <dynamics damping="0.5"/>
  </joint>
  <link name="leg_hip2_r1">
    <inertial>
      <origin rpy="0 0 0" xyz="-0.00120298 -0.0347459 -0.000660893"/>
      <mass value="0.36"/>
      <inertia ixx="0.000773544" ixy="0" ixz="0" iyy="0.000379211" iyz="0" izz="0.000858844"/>
    </inertial>
    <visual>
      <origin rpy="0 0 0" xyz="0 0 0"/>
      <geometry>
        <mesh filename="package://armar_description/meshes/armar4/visual/legr_hip2_joint.obj"/>
      </geometry>
      <material name="grey">
        <color rgba="0.537 0.537 0.537 1"/>
      </material>
    </visual>
    <collision>
      <origin rpy="0 0 0" xyz="0 0 0"/>
      <geometry>
        <mesh filename="package://armar_description/meshes/armar4/collision/legr_hip2_joint.stl"/>
      </geometry>
    </collision>
  </link>
  <joint name="leg_hip3_joint_r1" type="revolute">
    <parent link="leg_hip2_r1"/>
    <child link="leg_hip3_r1"/>
    <origin rpy="-1.5707964 0 0" xyz="0 0 0"/>
    <axis xyz="0 0 1"/>
    <limit effort="240" lower="-0.9812" upper="0.8177" velocity="1.710422666954443"/>
    <dynamics damping="0.5"/>
  </joint>
  <link name="leg_hip3_r1">
    <inertial>
      <origin rpy="0 0 0" xyz="0.154728 0.131798 -0.0639989"/>
      <mass value="5.06"/>
      <inertia ixx="0.0570551" ixy="0" ixz="0" iyy="0.0867303" iyz="0" izz="0.101375"/>
    </inertial>
    <visual>
      <origin rpy="0 0 0" xyz="0 0 0"/>
      <geometry>
        <mesh filename="package://armar_description/meshes/armar4/visual/legr_hip3_joint.obj"/>
      </geometry>
      <material name="white">
        <color rgba="1 1 1 1"/>
      </material>
    </visual>
    <collision>
      <origin rpy="0 0 0" xyz="0 0 0"/>
      <geometry>
        <mesh filename="package://armar_description/meshes/armar4/collision/legr_hip3_joint.stl"/>
      </geometry>
    </collision>
  </link> 
  <joint name="leg_knee_joint_r1" type="revolute">
    <parent link="leg_hip3_r1"/>
    <child link="leg_knee_r1"/>
    <origin rpy="2.0943953 0.615403 2.3561942" xyz="0.3031 0.1975 -0.1738"/>
    <axis xyz="1 0 0"/>
    <limit effort="240" lower="0" upper="1.6354" velocity="1.710422666954443"/>
    <dynamics damping="0.5"/>
  </joint>
  <link name="leg_knee_r1">
    <inertial>
      <origin rpy="0 0 0" xyz="-0.0226642 -0.0123348 0.187084"/>
      <mass value="4.25"/>
      <inertia ixx="0.089890" ixy="0" ixz="0" iyy="0.0881157" iyz="0" izz="0.0123005"/>
    </inertial>
    <visual>
      <origin rpy="0 0 0" xyz="0 0 0"/>
      <geometry>
        <mesh filename="package://armar_description/meshes/armar4/visual/legr_knee_joint.obj"/>
      </geometry>
      <material name="white">
        <color rgba="1 1 1 1"/>
      </material>
    </visual>
    <collision>
      <origin rpy="0 0 0" xyz="0 0 0"/>
      <geometry>
        <mesh filename="package://armar_description/meshes/armar4/collision/legr_knee_joint.stl"/>
      </geometry>
    </collision>
  </link>
  <joint name="leg_ank1_joint_r1" type="revolute">
    <parent link="leg_knee_r1"/>
    <child link="leg_ank1_r1"/>
    <origin rpy="0 -1.5707963 0" xyz="0 0 0.4085"/>
    <axis xyz="0 0 1"/>
    <limit effort="240" lower="-0.4906" upper="0.4906" velocity="1.710422666954443"/>
    <dynamics damping="0.5"/>
  </joint>
  <link name="leg_ank1_r1">
    <inertial>
      <origin rpy="0 0 0" xyz="0 0 0"/>
      <mass value="0.5"/>
      <inertia ixx="0.089890" ixy="0" ixz="0" iyy="0.0880982" iyz="0" izz="0.0122883"/>
    </inertial>
    <visual>
      <origin rpy="0 0 0" xyz="0 0 0"/>
      <geometry>
        <sphere radius="0.00"/>
      </geometry>
      <material name="white">
        <color rgba="1 1 1 1"/>
      </material>
    </visual>
    <collision>
      <origin rpy="0 0 0" xyz="0 0 0"/>
      <geometry>
        <sphere radius="0.00"/>
      </geometry>
    </collision>
  </link>
  <joint name="leg_ank2_joint_r1" type="revolute">
    <parent link="leg_ank1_r1"/>
    <child link="leg_ank2_r1"/>
    <origin rpy="1.5707964 0 0" xyz="0 0 0"/>
    <axis xyz="0 0 1"/>
    <limit effort="240" lower="-0.06" upper="0.06" velocity="1.710422666954443"/>
    <dynamics damping="0.5"/>
  </joint>
  <link name="leg_ank2_r1">
    <inertial>
      <origin rpy="0 0 0" xyz="0.0333756 0.0137197 -0.0381945"/>
      <mass value="1.94"/>
      <inertia ixx="0.0105498" ixy="0" ixz="0" iyy="0.0103366" iyz="0" izz="0.00444324"/>
    </inertial>
    <visual>
      <origin rpy="0 0 0" xyz="0 0 0"/>
      <geometry>
        <mesh filename="package://armar_description/meshes/armar4/visual/legr_ank2_joint.obj"/>
      </geometry>
      <material name="white">
        <color rgba="1 1 1 1"/>
      </material>
    </visual>
    <collision>
      <origin rpy="0 0 0" xyz="0 0 0"/>
      <geometry>
        <mesh filename="package://armar_description/meshes/armar4/collision/legr_ank2_joint.stl"/>
      </geometry>
    </collision>
  </link>
  <joint name="leg_heel_joint_r1" type="fixed">
    <parent link="leg_ank2_r1"/>
    <child link="leg_heel_r1"/>
    <origin rpy="0 0 0" xyz="0.07945 0 0.0529"/>
  </joint>
  <link name="leg_heel_r1">
    <inertial>
      <origin rpy="0 0 0" xyz="-0.00118398 0.00843963 -0.00707974"/>
      <mass value="0.05"/>
      <inertia ixx="1.59042e-05" ixy="0" ixz="0" iyy="7.28912e-06" iyz="0" izz="9.82714e-06"/>
    </inertial>
    <visual>
      <origin rpy="0 0 0" xyz="0 0 0"/>
      <geometry>
        <mesh filename="package://armar_description/meshes/armar4/visual/legr_heel_joint.obj"/>
      </geometry>
      <material name="light_grey">
        <color rgba="0.796078431 0.796078431 0.752941176 1"/>
      </material>
    </visual>
    <collision>
      <origin rpy="0 0 0" xyz="0 0 0"/>
      <geometry>
        <mesh filename="package://armar_description/meshes/armar4/collision/legr_heel_joint.stl"/>
      </geometry>
    </collision>
  </link>
  <joint name="leg_toe_joint_r1" type="fixed">
    <parent link="leg_ank2_r1"/>
    <child link="leg_toe_r1"/>
    <origin rpy="3.1415927 0 3.1415927" xyz="0.0743 -0.0254 -0.13117"/> 
  </joint>
  <link name="leg_toe_r1">
    <inertial>
      <origin rpy="0 0 0" xyz="-0.00461182 -0.00368414 0.0237567"/>
      <mass value="0.13"/>
      <inertia ixx="9.91014e-05" ixy="0" ixz="0" iyy="7.72887e-05" iyz="0" izz="2.81054e-05"/>
    </inertial>
    <visual>
      <origin rpy="0 0 0" xyz="0 0 0"/>
      <geometry>
        <mesh filename="package://armar_description/meshes/armar4/visual/legr_toe_joint.obj"/>
      </geometry>
      <material name="light_grey">
        <color rgba="0.796078431 0.796078431 0.752941176 1"/>
      </material>
    </visual>
    <collision>
      <origin rpy="0 0 0" xyz="0 0 0"/>
      <geometry>
        <mesh filename="package://armar_description/meshes/armar4/collision/legr_toe_joint.stl"/>
      </geometry>
    </collision>
  </link>
  <joint name="leg_toe2_joint_r1" type="fixed">
    <parent link="leg_ank2_r1"/>
    <child link="leg_toe2_r1"/>
    <origin rpy="-1.1344644 0 0" xyz="0.0743 0.006 -0.1312"/>
  </joint>
  <link name="leg_toe2_r1">
    <inertial>
      <origin rpy="0 0 0" xyz="0.00326758 0.0207888 0.0125232"/>
      <mass value="0.13"/>
      <inertia ixx="9.90857e-05" ixy="0" ixz="0" iyy="7.72553e-05" iyz="0" izz="2.8123e-05"/>
    </inertial>
    <visual>
      <origin rpy="0 0 0" xyz="0 0 0"/>
      <geometry>
        <mesh filename="package://armar_description/meshes/armar4/visual/legr_toe2_joint.obj"/>
      </geometry>
      <material name="light_grey">
        <color rgba="0.796078431 0.796078431 0.752941176 1"/>
      </material>
    </visual>
    <collision>
      <origin rpy="0 0 0" xyz="0 0 0"/>
      <geometry>
        <mesh filename="package://armar_description/meshes/armar4/collision/legr_toe2_joint.stl"/>
      </geometry>
    </collision>
  </link>
  <joint name="torso_yaw_joint" type="revolute">
    <parent link="root"/>
    <child link="torso_yaw"/>
    <origin rpy="0 0 0" xyz="0 0 0"/>
    <axis xyz="0 0 1"/>
    <limit effort="1500" lower="-1.5708" upper="1.5708" velocity="0.6"/>
    <dynamics damping="0.5"/>
  </joint>
  <link name="torso_yaw">
    <inertial>
      <origin rpy="0 0 0" xyz="-0.000749969 0 0.074585"/>
      <mass value="1.33"/>
      <inertia ixx="0.0137914" ixy="0" ixz="0" iyy="0.0165096" iyz="0" izz="0.0117209"/>
    </inertial>
    <visual>
      <origin rpy="0 0 0" xyz="0 0 0"/>
      <geometry>
        <mesh filename="package://armar_description/meshes/armar4/visual/torso_yaw_joint.obj"/>
      </geometry>
      <material name="grey">
        <color rgba="0.537 0.537 0.537 1"/>
      </material>
    </visual>
    <collision>
      <origin rpy="0 0 0" xyz="0 0 0"/>
      <geometry>
        <mesh filename="package://armar_description/meshes/armar4/collision/torso_yaw_joint.stl"/>
      </geometry>
    </collision>
  </link>
  <joint name="torso_pitch_joint" type="revolute">
    <parent link="torso_yaw"/>
    <child link="torso_pitch"/>
    <origin rpy="1.5707964 0 1.5707964" xyz="0 0 0.099879"/>
    <axis xyz="0 0 1"/>
    <limit effort="1800" lower="-0.5" upper="0.5" velocity="0.4"/>
    <dynamics damping="0.5"/>
  </joint>
  <link name="torso_pitch">
    <inertial>
      <origin rpy="0 0 0" xyz="-0.0192648 0.13965 -0.000621773"/>
      <mass value="25.49"/>
      <inertia ixx="0.50297" ixy="0" ixz="0" iyy="0.332368" iyz="0" izz="0.479884"/>
    </inertial>
    <visual>
      <origin rpy="0 0 0" xyz="0 0 0"/>
      <geometry>
        <mesh filename="package://armar_description/meshes/armar4/visual/torso_pitch_joint.obj"/>
      </geometry>
      <material name="white">
        <color rgba="1 1 1 1"/>
      </material>
    </visual>
    <collision>
      <origin rpy="0 0 0" xyz="0 0 0"/>
      <geometry>
        <mesh filename="package://armar_description/meshes/armar4/collision/torso_pitch_joint.stl"/>
      </geometry>
    </collision>
  </link>
  <joint name="neck_1_joint" type="fixed">
    <parent link="torso_pitch"/>
    <child link="neck_1"/>
    <origin rpy="0 0 -1.5707964" xyz="0 0.3073 0"/>
  </joint>
  <link name="neck_1">
    <inertial>
      <origin rpy="0 0 0" xyz="0 0.0191001 -0.000249887"/>
      <mass value="0.14"/>
      <inertia ixx="0.000159421" ixy="0" ixz="0" iyy="9.60035e-05" iyz="0" izz="0.000100439"/>
    </inertial>
    <visual>
      <origin rpy="0 0 0" xyz="0 0 0"/>
      <geometry>
        <mesh filename="package://armar_description/meshes/armar4/visual/neck_1_joint.obj"/>
      </geometry>
      <material name="grey">
        <color rgba="0.537 0.537 0.537 1"/>
      </material>
    </visual>
    <collision>
      <origin rpy="0 0 0" xyz="0 0 0"/>
      <geometry>
        <mesh filename="package://armar_description/meshes/armar4/collision/neck_1_joint.stl"/>
      </geometry>
    </collision>
  </link>
  <joint name="neck_2_joint" type="fixed">
    <parent link="neck_1"/>
    <child link="neck_2"/>
    <origin rpy="0 1.5707963 1.5707964" xyz="0 0 0"/>
  </joint>
  <link name="neck_2">
    <inertial>
      <origin rpy="0 0 0" xyz="0 0.0427501 0.0144084"/>
      <mass value="0.13"/>
      <inertia ixx="0.000251672" ixy="0" ixz="0" iyy="0.000120919" iyz="0" izz="0.000168382"/>
    </inertial>
    <visual>
      <origin rpy="0 0 0" xyz="0 0 0"/>
      <geometry>
        <mesh filename="package://armar_description/meshes/armar4/visual/neck_2_joint.obj"/>
      </geometry>
      <material name="light_grey">
        <color rgba="0.796078431 0.796078431 0.752941176 1"/>
      </material>
    </visual>
    <collision>
      <origin rpy="0 0 0" xyz="0 0 0"/>
      <geometry>
        <mesh filename="package://armar_description/meshes/armar4/collision/neck_2_joint.stl"/>
      </geometry>
    </collision>
  </link>
  <joint name="neck_3_joint" type="fixed">
    <parent link="neck_2"/>
    <child link="neck_3"/>
    <origin rpy="0 1.5707963 1.5707964" xyz="0 0.0338 0"/>
  </joint>
  <link name="neck_3">
    <inertial>
      <origin rpy="0 0 0" xyz="-0.00675008 -0.0130999 0.0608498"/>
      <mass value="0.25"/>
      <inertia ixx="0.000465112" ixy="0" ixz="0" iyy="0.000426562" iyz="0" izz="0.00022281"/>
    </inertial>
    <visual>
      <origin rpy="0 0 0" xyz="0 0 0"/>
      <geometry>
        <mesh filename="package://armar_description/meshes/armar4/visual/neck_3_joint.obj"/>
      </geometry>
      <material name="white">
        <color rgba="1 1 1 1"/>
      </material>
    </visual>
    <collision>
      <origin rpy="0 0 0" xyz="0 0 0"/>
      <geometry>
        <mesh filename="package://armar_description/meshes/armar4/collision/neck_3_joint.stl"/>
      </geometry>
    </collision>
  </link>
  <joint name="head_1_joint" type="fixed">
    <parent link="neck_3"/>
    <child link="head_1"/>
    <origin rpy="1.5707964 0 -3.1415925" xyz="0 0 0.1062"/>
  </joint>
  <link name="head_1">
    <inertial>
      <origin rpy="0 0 0" xyz="0.0100501 0 -0.000349847"/>
      <mass value="0.07"/>
      <inertia ixx="2.52845e-05" ixy="0" ixz="0" iyy="3.20675e-05" iyz="0" izz="2.7363e-05"/>
    </inertial>
    <visual>
      <origin rpy="0 0 0" xyz="0 0 0"/>
      <geometry>
        <mesh filename="package://armar_description/meshes/armar4/visual/head_1_joint.obj"/>
      </geometry>
      <material name="white">
        <color rgba="1 1 1 1"/>
      </material>
    </visual>
    <collision>
      <origin rpy="0 0 0" xyz="0 0 0"/>
      <geometry>
        <mesh filename="package://armar_description/meshes/armar4/collision/head_1_joint.stl"/>
      </geometry>
    </collision>
  </link>
 <joint name="head_2_joint" type="fixed">
    <parent link="head_1"/>
    <child link="head_2"/>
    <origin rpy="0 1.5707963 0" xyz="0.00465 0 0"/>
  </joint>
  <link name="head_2">
    <inertial>
      <origin rpy="0 0 0" xyz="0.00124981 0.0820215 0.0210557"/>
      <mass value="1.34"/>
      <inertia ixx="0.00954863" ixy="0" ixz="0" iyy="0.00822691" iyz="0" izz="0.00721911"/>
    </inertial>
    <visual>
      <origin rpy="0 0 0" xyz="0 0 0"/>
      <geometry>
        <mesh filename="package://armar_description/meshes/armar4/visual/head_2_joint.obj"/>
      </geometry>
      <material name="white">
        <color rgba="1 1 1 1"/>
      </material>
    </visual>
    <collision>
      <origin rpy="0 0 0" xyz="0 0 0"/>
      <geometry>
        <mesh filename="package://armar_description/meshes/armar4/collision/head_2_joint.stl"/>
      </geometry>
    </collision>
  </link>
  <joint name="eye_1_joint_r0" type="fixed">
    <parent link="head_2"/>
    <child link="eye_1_r0"/>
    <origin rpy="1.5707964 0 -1.5707964" xyz="-0.0105 0.0726517 -0.06315"/>
  </joint>
  <link name="eye_1_r0">
    <inertial>
      <origin rpy="0 0 0" xyz="0.00262986 0.0195001 0.0209721"/>
      <mass value="0.05"/>
      <inertia ixx="2.52845e-05" ixy="0" ixz="0" iyy="3.20675e-05" iyz="0" izz="2.7363e-05"/>
    </inertial>
    <visual>
      <origin rpy="0 0 0" xyz="0 0 0"/>
      <geometry>
        <mesh filename="package://armar_description/meshes/armar4/visual/eyel_1_joint.obj"/>
      </geometry>
      <material name="grey">
        <color rgba="0.537 0.537 0.537 1"/>
      </material>
    </visual>
    <collision>
      <origin rpy="0 0 0" xyz="0 0 0"/>
      <geometry>
        <sphere radius="0.00"/>
      </geometry>
    </collision>
  </link>
  <joint name="eye_2_joint_r0" type="fixed">
    <parent link="eye_1_r0"/>
    <child link="eye_2_r0"/>
    <origin rpy="-1.5707964 0 -1.5707964" xyz="0 0 0.036"/>
  </joint>
  <link name="eye_2_r0">
    <inertial>
      <origin rpy="0 0 0" xyz="0.00624987 0 0.00269453"/>
      <mass value="0.05"/>
      <inertia ixx="2.18594e-05" ixy="0" ixz="0" iyy="1.52203e-05" iyz="0" izz="1.41891e-05"/>
    </inertial>
    <visual>
      <origin rpy="0 0 0" xyz="0 0 0"/>
      <geometry>
        <mesh filename="package://armar_description/meshes/armar4/visual/eyel_2_joint.obj"/>
      </geometry>
      <material name="white">
        <color rgba="1 1 1 1"/>
      </material>
    </visual>
    <collision>
      <origin rpy="0 0 0" xyz="0 0 0"/>
      <geometry>
        <mesh filename="package://armar_description/meshes/armar4/collision/eyel_2_joint.stl"/>
      </geometry>
    </collision>
  </link>
  <joint name="eye_1_joint_r1" type="fixed">
    <parent link="head_2"/>
    <child link="eye_1_r1"/>
    <origin rpy="1.5707964 0 -1.5707964" xyz="0.015 0.0726517 -0.06315"/>
  </joint>
  <link name="eye_1_r1">
    <inertial>
      <origin rpy="0 0 0" xyz="0.00262986 0.0195001 -0.0148498"/>
      <mass value="0.05"/>
      <inertia ixx="2.52845e-05" ixy="0" ixz="0" iyy="3.20675e-05" iyz="0" izz="2.7363e-05"/>
    </inertial>
    <visual>
      <origin rpy="0 0 0" xyz="0 0 0"/>
      <geometry>
        <mesh filename="package://armar_description/meshes/armar4/visual/eyer_1_joint.obj"/>
      </geometry>
      <material name="grey">
        <color rgba="0.537 0.537 0.537 1"/>
      </material>
    </visual>
    <collision>
      <origin rpy="0 0 0" xyz="0 0 0"/>
      <geometry>
        <sphere radius="0.00"/>
      </geometry>
    </collision>
  </link>
  <joint name="eye_2_joint_r1" type="fixed">
    <parent link="eye_1_r1"/>
    <child link="eye_2_r1"/>
    <origin rpy="-1.5707964 0 -1.5707964" xyz="0 0 -0.0315"/>
  </joint>
  <link name="eye_2_r1">
    <inertial>
      <origin rpy="0 0 0" xyz="0.00624987 0 0.00269453"/>
      <mass value="0.05"/>
      <inertia ixx="2.18594e-05" ixy="0" ixz="0" iyy="1.52203e-05" iyz="0" izz="1.41891e-05"/>
    </inertial>
    <visual>
      <origin rpy="0 0 0" xyz="0 0 0"/>
      <geometry>
        <mesh filename="package://armar_description/meshes/armar4/visual/eyer_2_joint.obj"/>
      </geometry>
      <material name="white">
        <color rgba="1 1 1 1"/>
      </material>
    </visual>
    <collision>
      <origin rpy="0 0 0" xyz="0 0 0"/>
      <geometry>
        <mesh filename="package://armar_description/meshes/armar4/collision/eyer_2_joint.stl"/>
      </geometry>
    </collision>
  </link>
  <joint name="arm_sho1_joint_r0" type="revolute">
    <parent link="torso_pitch"/>
    <child link="arm_sho1_r0"/>
    <origin rpy="1.5707963 0 0" xyz="0 0.2103 0"/>
    <axis xyz="0 0 1"/>
    <limit effort="240" lower="0" upper="0.785398" velocity="0.6"/>
    <dynamics damping="0.5"/>
  </joint>
  <link name="arm_sho1_r0">
    <inertial>
      <origin rpy="0 0 0" xyz="-0.00635488 0.0837574 -0.0328287"/>
      <mass value="0.58"/>
      <inertia ixx="0.00137353" ixy="0" ixz="0" iyy="0.00204376" iyz="0" izz="0.00196295"/>
    </inertial>
    <visual>
      <origin rpy="0 0 0" xyz="0 0 0"/>
      <geometry>
        <mesh filename="package://armar_description/meshes/armar4/visual/arml_sho1_joint.obj"/>
      </geometry>
      <material name="white">
        <color rgba="1 1 1 1"/>
      </material>
    </visual>
    <collision>
      <origin rpy="0 0 0" xyz="0 0 0"/>
      <geometry>
        <mesh filename="package://armar_description/meshes/armar4/collision/arml_sho1_joint.stl"/>
      </geometry>
    </collision>
  </link>
  <joint name="arm_sho2_joint_r0" type="revolute">
    <parent link="arm_sho1_r0"/>
    <child link="arm_sho2_r0"/>
    <origin rpy="1.3089971 0 0" xyz="0 0.136249 -0.0599"/>
    <axis xyz="0 0 1"/>
    <limit effort="240" lower="-0.523599" upper="2.61799" velocity="1.710422666954443"/>
    <dynamics damping="0.5"/>
  </joint>
  <link name="arm_sho2_r0">
    <inertial>
      <origin rpy="0 0 0" xyz="-0.00149987 -0.00344511 -0.0512163"/>
      <mass value="0.52"/>
      <inertia ixx="0.000596991" ixy="0" ixz="0" iyy="0.000663986" iyz="0" izz="0.000420505"/>
    </inertial>
    <visual>
      <origin rpy="0 0 0" xyz="0 0 0"/>
      <geometry>
        <mesh filename="package://armar_description/meshes/armar4/visual/arml_sho2_joint.obj"/>
      </geometry>
      <material name="white">
        <color rgba="1 1 1 1"/>
      </material>
    </visual>
    <collision>
      <origin rpy="0 0 0" xyz="0 0 0"/>
      <geometry>
        <mesh filename="package://armar_description/meshes/armar4/collision/arml_sho2_joint.stl"/>
      </geometry>
    </collision>
  </link>
  <joint name="arm_sho3_joint_r0" type="revolute">
    <parent link="arm_sho2_r0"/>
    <child link="arm_sho3_r0"/>
    <origin rpy="-1.5707964 1.4835301 1.5707964" xyz="0.0165 0 -0.066"/>
    <axis xyz="0 0 1"/>
    <limit effort="240" lower="-0.261799" upper="1.39626" velocity="1.710422666954443"/>
    <dynamics damping="0.5"/>
  </joint>
  <link name="arm_sho3_r0">
    <inertial>
      <origin rpy="0 0 0" xyz="0 -0.0575318 0.0134998"/>
      <mass value="0.51"/>
      <inertia ixx="0.00109943" ixy="0" ixz="0" iyy="0.000491725" iyz="0" izz="0.00106067"/>
    </inertial>
    <visual>
      <origin rpy="0 0 0" xyz="0 0 0"/>
      <geometry>
        <mesh filename="package://armar_description/meshes/armar4/visual/arml_sho3_joint.obj"/>
      </geometry>
      <material name="white">
        <color rgba="1 1 1 1"/>
      </material>
    </visual>
    <collision>
      <origin rpy="0 0 0" xyz="0 0 0"/>
      <geometry>
        <mesh filename="package://armar_description/meshes/armar4/collision/arml_sho3_joint.stl"/>
      </geometry>
    </collision>
  </link>
  <joint name="arm_sho4_joint_r0" type="revolute">
    <parent link="arm_sho3_r0"/>
    <child link="arm_sho4_r0"/>
    <origin rpy="-1.5707964 0 0" xyz="0 -0.1026 0.0165"/>
    <axis xyz="0 0 1"/>
    <limit effort="240" lower="-1.39626" upper="2.96706" velocity="1.710422666954443"/>
    <dynamics damping="0.5"/>
  </joint>
  <link name="arm_sho4_r0">
    <inertial>
      <origin rpy="0 0 0" xyz="0.00188906 -0.00191048 -0.110437"/>
      <mass value="1.44"/>
      <inertia ixx="0.00541288" ixy="0" ixz="0" iyy="0.00551224" iyz="0" izz="0.0011448"/>
    </inertial>
    <visual>
      <origin rpy="0 0 0" xyz="0 0 0"/>
      <geometry>
        <mesh filename="package://armar_description/meshes/armar4/visual/arml_sho4_joint.obj"/>
      </geometry>
      <material name="white">
        <color rgba="1 1 1 1"/>
      </material>
    </visual>
    <collision>
      <origin rpy="0 0 0" xyz="0 0 0"/>
      <geometry>
        <mesh filename="package://armar_description/meshes/armar4/collision/arml_sho4_joint.stl"/>
      </geometry>
    </collision>
  </link>
  <joint name="arm_elb1_joint_r0" type="revolute">
    <parent link="arm_sho4_r0"/>
    <child link="arm_elb1_r0"/>
    <origin rpy="1.5707963 0 -1.5707963" xyz="-0.0215 -0.01 -0.1974"/>
    <axis xyz="0 0 1"/>
    <limit effort="240" lower="-0.0872665" upper="1.8151424" velocity="1.710422666954443"/>
    <dynamics damping="0.5"/>
  </joint>
  <link name="arm_elb1_r0">
    <inertial>
      <origin rpy="0 0 0" xyz="0 -0.0334756 -0.026321"/>
      <mass value="0.61"/>
      <inertia ixx="0.00114668" ixy="0" ixz="0" iyy="0.000480917" iyz="0" izz="0.0010953"/>
    </inertial>
    <visual>
      <origin rpy="0 0 0" xyz="0 0 0"/>
      <geometry>
        <mesh filename="package://armar_description/meshes/armar4/visual/arml_elb1_joint.obj"/>
      </geometry>
      <material name="white">
        <color rgba="1 1 1 1"/>
      </material>
    </visual>
    <collision>
      <origin rpy="0 0 0" xyz="0 0 0"/>
      <geometry>
        <mesh filename="package://armar_description/meshes/armar4/collision/arml_elb1_joint.stl"/>
      </geometry>
    </collision>
  </link>
  <joint name="arm_elb2_joint_r0" type="revolute">
    <parent link="arm_elb1_r0"/>
    <child link="arm_elb2_r0"/>
    <origin rpy="0 1.5707963 1.5707964" xyz="0 -0.0858 -0.0205"/>
    <axis xyz="0 0 1"/>
    <limit effort="240" lower="-3.14159" upper="1.5708" velocity="1.710422666954443"/>
    <dynamics damping="0.5"/>
  </joint>
  <link name="arm_elb2_r0">
    <inertial>
      <origin rpy="0 0 0" xyz="0.00297504 -0.0000305709 -0.0877993"/>
      <mass value="0.43"/>
      <inertia ixx="0.00142316" ixy="0" ixz="0" iyy="0.00122507" iyz="0" izz="0.000422436"/>
    </inertial>
    <visual>
      <origin rpy="0 0 0" xyz="0 0 0"/>
      <geometry>
        <mesh filename="package://armar_description/meshes/armar4/visual/arml_elb2_joint.obj"/>
      </geometry>
      <material name="white">
        <color rgba="1 1 1 1"/>
      </material>
    </visual>
    <collision>
      <origin rpy="0 0 0" xyz="0 0 0"/>
      <geometry>
        <mesh filename="package://armar_description/meshes/armar4/collision/arml_elb2_joint.stl"/>
      </geometry>
    </collision>
  </link>
  <joint name="arm_wri1_joint_r0" type="revolute">
    <parent link="arm_elb2_r0"/>
    <child link="arm_wri1_r0"/>
    <origin rpy="-1.5707963 0 1.5707963" xyz="0 0 -0.1642"/>
    <axis xyz="0 0 1"/>
    <limit effort="240" lower="-0.15" upper="0.15" velocity="0.3"/>
    <dynamics damping="0.5"/>
  </joint>
  <link name="arm_wri1_r0">
    <inertial>
      <origin rpy="0 0 0" xyz="0 0 0"/>
      <mass value="0.5"/>
      <inertia ixx="0.00034257419" ixy="0" ixz="0" iyy="0.0006284882" iyz="0" izz="0.000588308"/>
    </inertial>
    <visual>
      <origin rpy="0 0 0" xyz="0 0 0"/>
      <geometry>
        <mesh filename="package://armar_description/meshes/armar4/visual/arml_wri1_joint.obj"/>
      </geometry>
      <material name="light_grey">
        <color rgba="0.796078431 0.796078431 0.752941176 1"/>
      </material>
    </visual>
  </link>
  <joint name="arm_wri2_joint_r0" type="revolute">
    <parent link="arm_wri1_r0"/>
    <child link="arm_wri2_r0"/>
    <origin rpy="1.5707963 0 1.5707963" xyz="0 0 0"/>
    <axis xyz="0 0 1"/>
    <limit effort="240" lower="-1.5708" upper="1.5708" velocity="1.710422666954443"/>
    <dynamics damping="0.5"/>
  </joint>
  <link name="arm_wri2_r0">
    <inertial>
      <origin rpy="0 0 0" xyz="0.0306435 -0.00259348 0.00000821687"/>
      <mass value="0.58"/>
      <inertia ixx="0.000423639" ixy="0" ixz="0" iyy="0.000982669" iyz="0" izz="0.00079084"/>
    </inertial>
    <visual>
      <origin rpy="0 0 0" xyz="0 0 0"/>
      <geometry>
        <mesh filename="package://armar_description/meshes/armar4/visual/handl_static.obj"/>
      </geometry>
      <material name="white">
        <color rgba="1 1 1 1"/>
      </material>
    </visual>
    <collision>
      <origin rpy="0 0 0" xyz="0 0 0"/>
      <geometry>
        <mesh filename="package://armar_description/meshes/armar4/collision/handl_static.obj"/>
      </geometry>
    </collision>
  </link>
  <joint name="arm_sho1_joint_r1" type="revolute">
    <parent link="torso_pitch"/>
    <child link="arm_sho1_r1"/>
    <origin rpy="-1.5707964 0 0" xyz="0 0.2103 0"/>
    <axis xyz="0 0 1"/>
    <limit effort="240" lower="0" upper="0.785398" velocity="0.6"/>
    <dynamics damping="0.5"/>
  </joint>
  <link name="arm_sho1_r1">
    <inertial>
      <origin rpy="0 0 0" xyz="-0.00635496 0.109694 0.0328288"/>
      <mass value="0.77"/> <!-- heavier than arml_shoe1 -->
      <inertia ixx="0.00182348" ixy="0" ixz="0" iyy="0.00271326" iyz="0" izz="0.00260599"/>
    </inertial>
    <visual>
      <origin rpy="0 0 0" xyz="0 0 0"/>
      <geometry>
        <mesh filename="package://armar_description/meshes/armar4/visual/armr_sho1_joint.obj"/>
      </geometry>
      <material name="white">
        <color rgba="1 1 1 1"/>
      </material>
    </visual>
    <collision>
      <origin rpy="0 0 0" xyz="0 0 0"/>
      <geometry>
        <mesh filename="package://armar_description/meshes/armar4/collision/armr_sho1_joint.stl"/>
      </geometry>
    </collision>
  </link>
  <joint name="arm_sho2_joint_r1" type="revolute">
    <parent link="arm_sho1_r1"/>
    <child link="arm_sho2_r1"/>
    <origin rpy="-1.3089971 0 0" xyz="0 0.136249 0.0599"/>
    <axis xyz="0 0 1"/>
    <limit effort="240" lower="-0.523599" upper="2.61799" velocity="1.710422666954443"/>
    <dynamics damping="0.5"/>
  </joint>
  <link name="arm_sho2_r1">
    <inertial>
      <origin rpy="0 0 0" xyz="-0.0015 -0.0000173714 0.0492432"/>
      <mass value="0.58"/>
      <inertia ixx="0.00061498" ixy="0" ixz="0" iyy="0.000689705" iyz="0" izz="0.000469024"/>
    </inertial>
    <visual>
      <origin rpy="0 0 0" xyz="0 0 0"/>
      <geometry>
        <mesh filename="package://armar_description/meshes/armar4/visual/armr_sho2_joint.obj"/>
      </geometry>
      <material name="white">
        <color rgba="1 1 1 1"/>
      </material>
    </visual>
    <collision>
      <origin rpy="0 0 0" xyz="0 0 0"/>
      <geometry>
        <mesh filename="package://armar_description/meshes/armar4/collision/armr_sho2_joint.stl"/>
      </geometry>
    </collision>
  </link>
  <joint name="arm_sho3_joint_r1" type="revolute">
    <parent link="arm_sho2_r1"/>
    <child link="arm_sho3_r1"/>
    <origin rpy="-1.5707964 1.4835301 -1.5707964" xyz="-0.0165 0 0.066"/>
    <axis xyz="0 0 1"/>
    <limit effort="240" lower="-0.261799" upper="1.39626" velocity="1.710422666954443"/>
    <dynamics damping="0.5"/>
  </joint>
  <link name="arm_sho3_r1">
    <inertial>
      <origin rpy="0 0 0" xyz="0 -0.0575318 0.0134998"/>
      <mass value="0.51"/>
      <inertia ixx="0" ixy="0" ixz="0" iyy="0.0575321" iyz="0" izz="0.0195"/>
    </inertial>
    <visual>
      <origin rpy="0 0 0" xyz="0 0 0"/>
      <geometry>
        <mesh filename="package://armar_description/meshes/armar4/visual/armr_sho3_joint.obj"/>
      </geometry>
      <material name="white">
        <color rgba="1 1 1 1"/>
      </material>
    </visual>
    <collision>
      <origin rpy="0 0 0" xyz="0 0 0"/>
      <geometry>
        <mesh filename="package://armar_description/meshes/armar4/collision/armr_sho3_joint.stl"/>
      </geometry>
    </collision>
  </link>
  <joint name="arm_sho4_joint_r1" type="revolute">
    <parent link="arm_sho3_r1"/>
    <child link="arm_sho4_r1"/>
    <origin rpy="-1.5707964 0 0" xyz="0 0.1026 0.0165"/>
    <axis xyz="0 0 1"/>
    <limit effort="240" lower="-1.39626" upper="2.96706" velocity="1.710422666954443"/>
    <dynamics damping="0.5"/>
  </joint>
  <link name="arm_sho4_r1">
    <inertial>
      <origin rpy="0 0 0" xyz="-0.00549999 0.008 0.114167"/>
      <mass value="1.44"/>
      <inertia ixx="0.00678104" ixy="0" ixz="0" iyy="0.00688041" iyz="0" izz="0.0011448"/>
    </inertial>
    <visual>
      <origin rpy="0 0 0" xyz="0 0 0"/>
      <geometry>
        <mesh filename="package://armar_description/meshes/armar4/visual/armr_sho4_joint.obj"/>
      </geometry>
      <material name="white">
        <color rgba="1 1 1 1"/>
      </material>
    </visual>
    <collision>
      <origin rpy="0 0 0" xyz="0 0 0"/>
      <geometry>
        <mesh filename="package://armar_description/meshes/armar4/collision/armr_sho4_joint.stl"/>
      </geometry>
    </collision>
  </link>
  <joint name="arm_elb1_joint_r1" type="revolute">
    <parent link="arm_sho4_r1"/>
    <child link="arm_elb1_r1"/>
    <origin rpy="-1.5707964 0 1.5707964" xyz="-0.0215 0.01 0.1974"/>
    <axis xyz="0 0 1"/>
    <limit effort="240" lower="-0.0872665" upper="1.8151424" velocity="1.710422666954443"/>
    <dynamics damping="0.5"/>
  </joint>
  <link name="arm_elb1_r1">
    <inertial>
      <origin rpy="0 0 0" xyz="0 -0.0334756 -0.0166789"/>
      <mass value="0.61"/>
      <inertia ixx="0.00114668" ixy="0" ixz="0" iyy="0.000480918" iyz="0" izz="0.0010953"/>
    </inertial>
    <visual>
      <origin rpy="0 0 0" xyz="0 0 0"/>
      <geometry>
        <mesh filename="package://armar_description/meshes/armar4/visual/armr_elb1_joint.obj"/>
      </geometry>
      <material name="white">
        <color rgba="1 1 1 1"/>
      </material>
    </visual>
    <collision>
      <origin rpy="0 0 0" xyz="0 0 0"/>
      <geometry>
        <mesh filename="package://armar_description/meshes/armar4/collision/armr_elb1_joint.stl"/>
      </geometry>
    </collision>
  </link>
  <joint name="arm_elb2_joint_r1" type="revolute">
    <parent link="arm_elb1_r1"/>
    <child link="arm_elb2_r1"/>
    <origin rpy="0 1.5707963 -1.5707964" xyz="0 -0.0858 -0.0205"/>
    <axis xyz="0 0 1"/>
    <limit effort="240" lower="-3.14159" upper="1.5708" velocity="1.710422666954443"/>
    <dynamics damping="0.5"/>
  </joint>
  <link name="arm_elb2_r1">
    <inertial>
      <origin rpy="0 0 0" xyz="-0.000975135 0.0000310054 0.0877994"/>
      <mass value="0.43"/>
      <inertia ixx="0.00142282" ixy="0" ixz="0" iyy="0.00122507" iyz="0" izz="0.000422095"/>
    </inertial>
    <visual>
      <origin rpy="0 0 0" xyz="0 0 0"/>
      <geometry>
        <mesh filename="package://armar_description/meshes/armar4/visual/armr_elb2_joint.obj"/>
      </geometry>
      <material name="white">
        <color rgba="1 1 1 1"/>
      </material>
    </visual>
    <collision>
      <origin rpy="0 0 0" xyz="0 0 0"/>
      <geometry>
        <mesh filename="package://armar_description/meshes/armar4/collision/armr_elb2_joint.stl"/>
      </geometry>
    </collision>
  </link>
  <joint name="arm_wri1_joint_r1" type="revolute">
    <parent link="arm_elb2_r1"/>
    <child link="arm_wri1_r1"/>
    <origin rpy="1.5707963 0 -1.5707963" xyz="-0.0005 0 0.1642"/>
    <axis xyz="0 0 1"/>
    <limit effort="240" lower="-0.15" upper="0.15" velocity="0.3"/>
    <dynamics damping="0.5"/>
  </joint>
  <link name="arm_wri1_r1">
    <inertial>
      <origin rpy="0 0 0" xyz="0 0 0"/>
      <mass value="0.5"/>
      <inertia ixx="0.00034257419" ixy="0" ixz="0" iyy="0.0006284882" iyz="0" izz="0.000588308"/>
    </inertial>
    <visual>
      <origin rpy="0 0 0" xyz="0 0 0"/>
      <geometry>
        <mesh filename="package://armar_description/meshes/armar4/visual/armr_wri1_joint.obj"/>
      </geometry>
      <material name="light_grey">
        <color rgba="0.796078431 0.796078431 0.752941176 1"/>
      </material>
    </visual>
  </link>
  <joint name="arm_wri2_joint_r1" type="revolute">
    <parent link="arm_wri1_r1"/>
    <child link="arm_wri2_r1"/>
    <origin rpy="-1.5707964 0 1.5707964" xyz="0 0 0"/>
    <axis xyz="0 0 1"/>
    <limit effort="240" lower="-1.5708" upper="1.5708" velocity="1.710422666954443"/>
    <dynamics damping="0.5"/>
  </joint>
  <link name="arm_wri2_r1">
    <inertial>
      <origin rpy="0 0 0" xyz="0.0306435 -0.0000936201 0"/>
      <mass value="0.58"/>
      <inertia ixx="0.000423253" ixy="0" ixz="0" iyy="0.000982141" iyz="0" izz="0.00079098"/>
    </inertial>
    <visual>
      <origin rpy="0 0 0" xyz="0 0 0"/>
      <geometry>
        <mesh filename="package://armar_description/meshes/armar4/visual/handr_static.obj"/>
      </geometry>
      <material name="white">
        <color rgba="1 1 1 1"/>
      </material>
    </visual>
    <collision>
      <origin rpy="0 0 0" xyz="0 0 0"/>
      <geometry>
        <mesh filename="package://armar_description/meshes/armar4/collision/handr_static.obj"/>
      </geometry>
    </collision>
  </link>
</robot>
