<mujoco model="ur5">
    <option timestep="0.0001" integrator="RK4" gravity="0 0 -9.81" >
		<flag sensornoise="disable" energy="enable" contact="enable" />
	</option>
    <compiler angle="radian" />
    <size njmax="500" nconmax="100" />
    <asset>
        <mesh name="base" file="meshes/base.stl" />
        <mesh name="shoulder" file="meshes/shoulder.stl" />
        <mesh name="upperarm" file="meshes/upperarm.stl" />
        <mesh name="forearm" file="meshes/forearm.stl" />
        <mesh name="wrist1" file="meshes/wrist1.stl" />
        <mesh name="wrist2" file="meshes/wrist2.stl" />
        <mesh name="wrist3" file="meshes/wrist3.stl" />
    </asset>
    <worldbody>
        <geom type="mesh" rgba="0.7 0.7 0.7 1" mesh="base" />
        <body name="shoulder_link" pos="0 0 0.089159">
            <inertial pos="0 0 0" mass="3.7" diaginertia="0.0102675 0.0102675 0.00666" />
            <joint name="shoulder_pan_joint" pos="0 0 0" axis="0 0 1" limited="true" range="-6.28319 6.28319" />
            <geom type="mesh" rgba="0.7 0.7 0.7 1" mesh="shoulder" />
            <body name="upper_arm_link" pos="0 0.13585 0" quat="0.707107 0 0.707107 0">
                <inertial pos="0 0 0.28" mass="8.393" diaginertia="0.226891 0.226891 0.0151074" />
                <joint name="shoulder_lift_joint" pos="0 0 0" axis="0 1 0" limited="true" range="-6.28319 6.28319" />
                <geom type="mesh" rgba="0.7 0.7 0.7 1" mesh="upperarm" />
                <body name="forearm_link" pos="0 -0.1197 0.425">
                    <inertial pos="0 0 0.196125" mass="2.275" diaginertia="0.0312168 0.0312168 0.004095" />
                    <joint name="elbow_joint" pos="0 0 0" axis="0 1 0" limited="true" range="-3.14159 3.14159" />
                    <geom type="mesh" rgba="0.7 0.7 0.7 1" mesh="forearm" />
                    <body name="wrist_1_link" pos="0 0 0.39225" quat="0.707107 0 0.707107 0">
                        <inertial pos="0 0.093 0" mass="1.219" diaginertia="0.0025599 0.0025599 0.0021942" />
                        <joint name="wrist_1_joint" pos="0 0 0" axis="0 1 0" limited="true" range="-6.28319 6.28319" />
                        <geom type="mesh" rgba="0.7 0.7 0.7 1" mesh="wrist1" />
                        <body name="wrist_2_link" pos="0 0.093 0">
                            <inertial pos="0 0 0.09465" mass="1.219" diaginertia="0.0025599 0.0025599 0.0021942" />
                            <joint name="wrist_2_joint" pos="0 0 0" axis="0 0 1" limited="true" range="-6.28319 6.28319" />
                            <geom type="mesh" rgba="0.7 0.7 0.7 1" mesh="wrist2" />
                            <body name="wrist_3_link" pos="0 0 0.09465">
                                <inertial pos="0 0.0650884 0" quat="0.707107 0 0 0.707107" mass="0.1889" diaginertia="0.000132134 8.47648e-05 8.47648e-05" />
                                <joint name="wrist_3_joint" pos="0 0 0" axis="0 1 0" limited="true" range="-6.28319 6.28319" />
                                <geom type="mesh" rgba="0.7 0.7 0.7 1" mesh="wrist3" />
                                <geom size="0.005 0.005 0.005" pos="0 0.0723 0" quat="0.707107 0 0 0.707107" type="box" />
                            </body>
                        </body>
                    </body>
                </body>
            </body>
        </body>
    </worldbody>

    <contact>
        <exclude body1="world" body2="shoulder_link"/>
        <exclude body1="world" body2="upper_arm_link"/>
        <exclude body1="world" body2="forearm_link"/>
        <exclude body1="world" body2="wrist_1_link"/>
        <exclude body1="world" body2="wrist_2_link"/>
        <exclude body1="world" body2="wrist_3_link"/>
        <exclude body1="shoulder_link" body2="shoulder_link"/>
        <exclude body1="shoulder_link" body2="upper_arm_link"/>
        <exclude body1="upper_arm_link" body2="forearm_link"/>
        <exclude body1="forearm_link" body2="wrist_1_link"/>
        <exclude body1="wrist_1_link" body2="wrist_2_link"/>
        <exclude body1="wrist_2_link" body2="wrist_3_link"/>
    </contact>

</mujoco>
