<?xml version="1.0"?>
<robot name="physics">
    <mujoco>
        <compiler meshdir="/home/giangnguyen/Workspace/mujoco_ws/src/mujoco_robots/cartpole/cartpole_mujoco/model/cartpole/meshes" strippath="false" balanceinertia="true" discardvisual="true"/>
    </mujoco>
    <link name="root"/>
    <link name="odom_x">
        <inertial>
            <origin xyz="0 0 0"/>
            <mass value="0.01"/>
            <inertia ixx="0.01" ixy="0.0" ixz="0.0" iyy="0.01" iyz="0.0" izz="0.01"/>
        </inertial>
    </link>
    <link name="cart">
        <visual>
            <geometry>
                <sphere radius="0.1"/>
            </geometry>
            <origin xyz="0 0 0"/>
            <material name="blue">
                <color rgba="0 0 .8 1"/>
            </material>
        </visual>
        <collision>
            <geometry>
                <sphere radius="0.1"/>
            </geometry>
            <origin xyz="0 0 0"/>
        </collision>
        <inertial>
            <mass value="1"/>
            <inertia ixx="1.0" ixy="0.0" ixz="0.0" iyy="1.0" iyz="0.0" izz="1.0"/>
        </inertial>
    </link>
    <link name="pole">
        <visual>
            <geometry>
                <box size="0.05 0.05 1.0"/>
            </geometry>
            <origin xyz="0 0 0.6"/>
            <material name="white">
                <color rgba="1 1 1 1"/>
            </material>
        </visual>
        <inertial>
            <origin xyz="0 0 0.6"/>
            <mass value="10"/>
            <inertia ixx="1.0" ixy="0.0" ixz="0.0" iyy="1.0" iyz="0.0" izz="1.0"/>
        </inertial>
        <collision>
            <geometry>
                <box size="0.05 0.05 1.0"/>
            </geometry>
            <origin xyz="0 0 0.6"/>
        </collision>
    </link>
    <link name="pole_x">
        <inertial>
            <origin xyz="0 0 0"/>
            <mass value="0.01"/>
            <inertia ixx="0.01" ixy="0.0" ixz="0.0" iyy="0.01" iyz="0.0" izz="0.01"/>
        </inertial>
    </link>
    <joint name="odom_x_joint" type="prismatic">
        <axis xyz="1 0 0"/>
        <origin xyz="0.0 0.0 0.0"/>
        <parent link="root"/>
        <child link="odom_x"/>
        <limit effort="100" lower="-1" upper="1" velocity="1"/>
    </joint>
    <joint name="odom_y_joint" type="prismatic">
        <axis xyz="0 1 0"/>
        <origin xyz="0.0 0.0 0.0"/>
        <parent link="odom_x"/>
        <child link="cart"/>
        <limit effort="100" lower="-1" upper="1" velocity="1"/>
    </joint>
    <joint name="cart_to_pole_x" type="revolute">
        <axis xyz="1 0 0"/>
        <origin xyz="0.0 0.0 0.0"/>
        <parent link="cart"/>
        <child link="pole_x"/>
        <limit effort="100" lower="-6.28" upper="6.28" velocity="3.14"/>
    </joint>
    <joint name="pole_x_to_pole" type="revolute">
        <axis xyz="0 1 0"/>
        <origin xyz="0.0 0.0 0"/>
        <parent link="pole_x"/>
        <child link="pole"/>
        <limit effort="100" lower="-6.28" upper="6.28" velocity="3.14"/>
    </joint>
</robot>
