<?xml version="1.0" encoding="utf-8"?>
<!-- =================================================================================== -->
<!-- |    This document was autogenerated by xacro from ridgeback.urdf.xacro           | -->
<!-- |    EDITING THIS FILE BY HAND IS NOT RECOMMENDED                                 | -->
<!-- =================================================================================== -->
<robot name="ridgeback">
  <material name="dark_grey">
    <color rgba="0.2 0.2 0.2 1.0" />
  </material>
  <material name="light_grey">
    <color rgba="0.4 0.4 0.4 1.0" />
  </material>
  <material name="red">
    <color rgba="0.8 0.0 0.0 1.0" />
  </material>
  <material name="white">
    <color rgba="0.9 0.9 0.9 1.0" />
  </material>
  <material name="yellow">
    <color rgba="0.8 0.8 0.0 1.0" />
  </material>
  <material name="black">
    <color rgba="0.15 0.15 0.15 1.0" />
  </material>
  <link name="front_rocker_link">
    <visual>
      <origin rpy="1.57079632679 0 1.57079632679" xyz="0 0 0" />
      <geometry>
        <mesh filename="package://ridgeback_description/meshes/rocker.stl" />
      </geometry>
      <material name="black" />
    </visual>
    <inertial>
      <origin rpy="1.57079632679 0 1.57079632679" xyz="0 0 0" />
      <mass value="10.267" />
      <inertia ixx="0.0288" ixy="2.20484e-6" ixz="-1.3145e-5" iyy="0.4324" iyz="1.8944e-3" izz="0.4130" />
    </inertial>
  </link>
  <joint name="front_rocker" type="revolute">
    <parent link="axle_link" />
    <child link="front_rocker_link" />
    <origin rpy="0 0 0" xyz="0.319 0 0" />
    <axis xyz="1 0 0" />
    <limit effort="0" lower="-0.08726" upper="0.08726" velocity="0" />
  </joint>
  <link name="front_left_wheel_link">
    <visual>
      <origin rpy="1.57079632679 0 0" xyz="0 0 0" />
      <geometry>
        <mesh filename="package://ridgeback_description/meshes/wheel.stl" />
      </geometry>
      <material name="black" />
    </visual>
    <collision>
      <origin rpy="1.57079632679 0 0" xyz="0 0 0" />
      <geometry>
        <cylinder length="0.079" radius="0.0759" />
      </geometry>
    </collision>
    <inertial>
      <origin rpy="0 0 0" xyz="0 0 0" />
      <mass value="2.3" />
      <inertia ixx="3.3212e-3" ixy="0" ixz="0" iyy="6.6424e-3" iyz="0" izz="3.3212e-3" />
    </inertial>
  </link>
  <joint name="front_left_wheel" type="continuous">
    <parent link="front_rocker_link" />
    <child link="front_left_wheel_link" />
    <origin rpy="0 0 0" xyz="0 0.2755 0" />
    <axis xyz="0 1 0" />
  </joint>
  <transmission name="front_wheel_trans">
    <type>transmission_interface/SimpleTransmission</type>
    <joint name="front_left_wheel">
      <hardwareInterface>hardware_interface/VelocityJointInterface</hardwareInterface>
    </joint>
    <actuator name="front_left_actuator">
      <mechanicalReduction>1</mechanicalReduction>
    </actuator>
  </transmission>
  <link name="front_right_wheel_link">
    <visual>
      <origin rpy="1.57079632679 0 0" xyz="0 0 0" />
      <geometry>
        <mesh filename="package://ridgeback_description/meshes/wheel.stl" />
      </geometry>
      <material name="black" />
    </visual>
    <collision>
      <origin rpy="1.57079632679 0 0" xyz="0 0 0" />
      <geometry>
        <cylinder length="0.079" radius="0.0759" />
      </geometry>
    </collision>
    <inertial>
      <origin rpy="0 0 0" xyz="0 0 0" />
      <mass value="2.3" />
      <inertia ixx="3.3212e-3" ixy="0" ixz="0" iyy="6.6424e-3" iyz="0" izz="3.3212e-3" />
    </inertial>
  </link>
  <joint name="front_right_wheel" type="continuous">
    <parent link="front_rocker_link" />
    <child link="front_right_wheel_link" />
    <origin rpy="0 0 0" xyz="0 -0.2755 0" />
    <axis xyz="0 1 0" />
  </joint>
  <transmission name="front_wheel_trans">
    <type>transmission_interface/SimpleTransmission</type>
    <joint name="front_right_wheel">
      <hardwareInterface>hardware_interface/VelocityJointInterface</hardwareInterface>
    </joint>
    <actuator name="front_right_actuator">
      <mechanicalReduction>1</mechanicalReduction>
    </actuator>
  </transmission>
  <link name="rear_rocker_link">
    <visual>
      <origin rpy="1.57079632679 0 1.57079632679" xyz="0 0 0" />
      <geometry>
        <mesh filename="package://ridgeback_description/meshes/rocker.stl" />
      </geometry>
      <material name="black" />
    </visual>
    <inertial>
      <origin rpy="1.57079632679 0 1.57079632679" xyz="0 0 0" />
      <mass value="10.267" />
      <inertia ixx="0.0288" ixy="2.20484e-6" ixz="-1.3145e-5" iyy="0.4324" iyz="1.8944e-3" izz="0.4130" />
    </inertial>
  </link>
  <joint name="rear_rocker" type="fixed">
    <parent link="axle_link" />
    <child link="rear_rocker_link" />
    <origin rpy="0 0 0" xyz="-0.319 0 0" />
    <axis xyz="1 0 0" />
    <limit effort="0" velocity="0" />
  </joint>
  <link name="rear_left_wheel_link">
    <visual>
      <origin rpy="1.57079632679 0 0" xyz="0 0 0" />
      <geometry>
        <mesh filename="package://ridgeback_description/meshes/wheel.stl" />
      </geometry>
      <material name="black" />
    </visual>
    <collision>
      <origin rpy="1.57079632679 0 0" xyz="0 0 0" />
      <geometry>
        <cylinder length="0.079" radius="0.0759" />
      </geometry>
    </collision>
    <inertial>
      <origin rpy="0 0 0" xyz="0 0 0" />
      <mass value="2.3" />
      <inertia ixx="3.3212e-3" ixy="0" ixz="0" iyy="6.6424e-3" iyz="0" izz="3.3212e-3" />
    </inertial>
  </link>
  <joint name="rear_left_wheel" type="continuous">
    <parent link="rear_rocker_link" />
    <child link="rear_left_wheel_link" />
    <origin rpy="0 0 0" xyz="0 0.2755 0" />
    <axis xyz="0 1 0" />
  </joint>
  <transmission name="rear_wheel_trans">
    <type>transmission_interface/SimpleTransmission</type>
    <joint name="rear_left_wheel">
      <hardwareInterface>hardware_interface/VelocityJointInterface</hardwareInterface>
    </joint>
    <actuator name="rear_left_actuator">
      <mechanicalReduction>1</mechanicalReduction>
    </actuator>
  </transmission>
  <link name="rear_right_wheel_link">
    <visual>
      <origin rpy="1.57079632679 0 0" xyz="0 0 0" />
      <geometry>
        <mesh filename="package://ridgeback_description/meshes/wheel.stl" />
      </geometry>
      <material name="black" />
    </visual>
    <collision>
      <origin rpy="1.57079632679 0 0" xyz="0 0 0" />
      <geometry>
        <cylinder length="0.079" radius="0.0759" />
      </geometry>
    </collision>
    <inertial>
      <origin rpy="0 0 0" xyz="0 0 0" />
      <mass value="2.3" />
      <inertia ixx="3.3212e-3" ixy="0" ixz="0" iyy="6.6424e-3" iyz="0" izz="3.3212e-3" />
    </inertial>
  </link>
  <joint name="rear_right_wheel" type="continuous">
    <parent link="rear_rocker_link" />
    <child link="rear_right_wheel_link" />
    <origin rpy="0 0 0" xyz="0 -0.2755 0" />
    <axis xyz="0 1 0" />
  </joint>
  <transmission name="rear_wheel_trans">
    <type>transmission_interface/SimpleTransmission</type>
    <joint name="rear_right_wheel">
      <hardwareInterface>hardware_interface/VelocityJointInterface</hardwareInterface>
    </joint>
    <actuator name="rear_right_actuator">
      <mechanicalReduction>1</mechanicalReduction>
    </actuator>
  </transmission>
  <link name="base_link" />
  <joint name="base_link_joint" type="fixed">
    <origin rpy="0 0 0" xyz="0 0 0" />
    <parent link="base_link" />
    <child link="chassis_link" />
  </joint>
  <link name="chassis_link">
    <visual>
      <origin rpy="0 0 0" xyz="0 0 0" />
      <geometry>
        <mesh filename="package://ridgeback_description/meshes/body.stl" />
      </geometry>
      <material name="black" />
    </visual>
    <collision>
      <origin xyz="0 0 0" />
      <geometry>
        <mesh filename="package://ridgeback_description/meshes/body-collision.stl" />
      </geometry>
    </collision>
    <inertial>
      <origin rpy="1.57079632679 0 1.57079632679" xyz="0.012 0.002 0.067" />
      <mass value="165.304" />
      <inertia ixx="4.4744" ixy="0.03098" ixz="0.003647" iyy="7.1624" iyz="0.1228" izz="4.6155" />
    </inertial>
  </link>
  <joint name="right_side_cover_link_joint" type="fixed">
    <origin rpy="0 0 0" xyz="0 0 0" />
    <parent link="chassis_link" />
    <child link="right_side_cover_link" />
  </joint>
  <joint name="left_side_cover_link_joint" type="fixed">
    <origin rpy="0 0 0" xyz="0 0 0" />
    <parent link="chassis_link" />
    <child link="left_side_cover_link" />
  </joint>
  <link name="left_side_cover_link">
    <visual>
      <origin rpy="0 0 3.14159265359" xyz="0 0 0" />
      <geometry>
        <mesh filename="package://ridgeback_description/meshes/side-cover.stl" />
      </geometry>
      <material name="yellow" />
    </visual>
  </link>
  <link name="right_side_cover_link">
    <visual>
      <origin rpy="0 0 0" xyz="0 0 0" />
      <geometry>
        <mesh filename="package://ridgeback_description/meshes/side-cover.stl" />
      </geometry>
      <material name="yellow" />
    </visual>
  </link>
  <joint name="front_cover_link_joint" type="fixed">
    <origin rpy="0 0 0" xyz="0 0 0" />
    <parent link="chassis_link" />
    <child link="front_cover_link" />
  </joint>
  <link name="front_cover_link">
    <visual>
      <origin rpy="0 0 0" xyz="0 0 0" />
      <geometry>
        <mesh filename="package://ridgeback_description/meshes/end-cover.stl" />
      </geometry>
      <material name="black" />
    </visual>
  </link>
  <joint name="rear_cover_link_joint" type="fixed">
    <origin rpy="0 0 0" xyz="0 0 0" />
    <parent link="chassis_link" />
    <child link="rear_cover_link" />
  </joint>
  <link name="rear_cover_link">
    <visual>
      <origin rpy="0 0 3.14159265359" xyz="0 0 0" />
      <geometry>
        <mesh filename="package://ridgeback_description/meshes/end-cover.stl" />
      </geometry>
      <material name="black" />
    </visual>
  </link>
  <joint name="front_lights_link_joint" type="fixed">
    <origin rpy="0 0 0" xyz="0 0 0" />
    <parent link="chassis_link" />
    <child link="front_lights_link" />
  </joint>
  <joint name="rear_lights_link_joint" type="fixed">
    <origin rpy="0 0 0" xyz="0 0 0" />
    <parent link="chassis_link" />
    <child link="rear_lights_link" />
  </joint>
  <link name="front_lights_link">
    <visual>
      <origin rpy="0 0 0" xyz="0 0 0" />
      <geometry>
        <mesh filename="package://ridgeback_description/meshes/lights.stl" />
      </geometry>
      <material name="white" />
    </visual>
  </link>
  <link name="rear_lights_link">
    <visual>
      <origin rpy="0 0 3.14159265359" xyz="0 0 0" />
      <geometry>
        <mesh filename="package://ridgeback_description/meshes/lights.stl" />
      </geometry>
      <material name="red" />
    </visual>
  </link>
  <joint name="top_link_joint" type="fixed">
    <origin rpy="0 0 0" xyz="0 0 0" />
    <parent link="chassis_link" />
    <child link="top_link" />
  </joint>
  <link name="top_link">
    <visual>
      <origin rpy="0 0 0" xyz="0 0 0" />
      <geometry>
        <mesh filename="package://ridgeback_description/meshes/top.stl" />
      </geometry>
      <material name="black" />
    </visual>
    <collision>
      <origin rpy="0 0 0" xyz="0 0 0" />
      <geometry>
        <mesh filename="package://ridgeback_description/meshes/top.stl" />
      </geometry>
    </collision>
  </link>
  <joint name="axle_joint" type="fixed">
    <origin rpy="0 0 0" xyz="0 0 0.05" />
    <parent link="chassis_link" />
    <child link="axle_link" />
  </joint>
  <link name="axle_link">
    <visual>
      <origin rpy="0 1.57079632679 0" xyz="0 0 0" />
      <geometry>
        <mesh filename="package://ridgeback_description/meshes/axle.stl" />
      </geometry>
      <material name="black" />
    </visual>
  </link>
  <link name="imu_link">
    <inertial>
      <mass value="0.001" />
      <origin rpy="0 0 0" xyz="0 0 0" />
      <inertia ixx="1e-09" ixy="0.0" ixz="0.0" iyy="1e-09" iyz="0.0" izz="1e-09" />
    </inertial>
  </link>
  <joint name="imu_joint" type="fixed">
    <parent link="chassis_link" />
    <child link="imu_link" />
    <origin rpy="0 0 0" xyz="0.2085 -0.2902 0.1681" />
  </joint>
  <link name="mid_mount" />
  <joint name="mid_mount_joint" type="fixed">
    <parent link="base_link" />
    <child link="mid_mount" />
    <origin rpy="0 0 0" xyz="0 0 0.28" />
  </joint>
  <gazebo>
    <plugin filename="libgazebo_ros_control.so" name="gazebo_ros_control">
      <robotNamespace>/</robotNamespace>
    </plugin>
    <plugin filename="libridgeback_ros_force_based_move.so" name="ridgeback_ros_force_based_move">
      <robotNamespace>/</robotNamespace>
      <commandTopic>cmd_vel</commandTopic>
      <odometryTopic>odom</odometryTopic>
      <odometryFrame>odom</odometryFrame>
      <odometryRate>25.0</odometryRate>
      <robotBaseFrame>base_link</robotBaseFrame>
      <cmdVelTimeOut>0.25</cmdVelTimeOut>
      <!-- Don't publish a transform: the controller does it. -->
      <publishOdometryTf>0</publishOdometryTf>
      <yaw_velocity_p_gain>500.0</yaw_velocity_p_gain>
      <x_velocity_p_gain>10000.0</x_velocity_p_gain>
      <y_velocity_p_gain>10000.0</y_velocity_p_gain>
    </plugin>
    <plugin filename="libhector_gazebo_ros_imu.so" name="imu_controller">
      <robotNamespace>/</robotNamespace>
      <updateRate>50.0</updateRate>
      <bodyName>imu_link</bodyName>
      <topicName>imu/data</topicName>
      <frameId>base_link</frameId>
      <accelDrift>0.005 0.005 0.005</accelDrift>
      <accelGaussianNoise>0.005 0.005 0.005</accelGaussianNoise>
      <rateDrift>0.00005 0.00005 0.00005</rateDrift>
      <rateGaussianNoise>0.00005 0.00005 0.00005</rateGaussianNoise>
      <headingDrift>0.005</headingDrift>
      <headingGaussianNoise>0.005</headingGaussianNoise>
    </plugin>
    <plugin filename="libgazebo_ros_joint_state_publisher.so" name="gazebo_ros_joint_state_publisher">
      <jointName>front_rocker</jointName>
      <robotNamespace>/</robotNamespace>
      <updateRate>50.0</updateRate>
    </plugin>
  </gazebo>
  <!-- All static links get collapsed down to base_link in Gazebo, so that's
       the one to apply the colour to (in Gazebo 5+). -->
  <gazebo reference="base_link">
    <material>Gazebo/DarkGrey</material>
    <gravity>true</gravity>
  </gazebo>
  <!-- Individual link colouring still needed in Gazebo 2.x -->
  <gazebo reference="chassis_link">
    <material>Gazebo/DarkGrey</material>
  </gazebo>
  <gazebo reference="top_link">
    <material>Gazebo/DarkGrey</material>
  </gazebo>
  <gazebo reference="left_side_cover_link">
    <material>Gazebo/Yellow</material>
  </gazebo>
  <gazebo reference="right_side_cover_link">
    <material>Gazebo/Yellow</material>
  </gazebo>
  <gazebo reference="front_cover_link">
    <material>Gazebo/DarkGrey</material>
  </gazebo>
  <gazebo reference="rear_cover_link">
    <material>Gazebo/DarkGrey</material>
  </gazebo>
  <gazebo reference="front_lights_link">
    <material>Gazebo/White</material>
  </gazebo>
  <gazebo reference="rear_lights_link">
    <material>Gazebo/Red</material>
  </gazebo>
  <gazebo reference="front_rocker_link">
    <material>Gazebo/DarkGrey</material>
  </gazebo>
  <gazebo reference="rear_rocker_link">
    <material>Gazebo/DarkGrey</material>
  </gazebo>
  <gazebo reference="axle_link">
    <material>Gazebo/DarkGrey</material>
  </gazebo>
  <!-- Wheel friction to zero, as movement is handled by applying forces at
       the body level. -->
  <gazebo reference="front_left_wheel_link">
    <material>Gazebo/DarkGrey</material>
    <mu1>0.0</mu1>
    <mu2>0.0</mu2>
  </gazebo>
  <gazebo reference="front_right_wheel_link">
    <material>Gazebo/DarkGrey</material>
    <mu1>0.0</mu1>
    <mu2>0.0</mu2>
  </gazebo>
  <gazebo reference="rear_left_wheel_link">
    <material>Gazebo/DarkGrey</material>
    <mu1>0.0</mu1>
    <mu2>0.0</mu2>
  </gazebo>
  <gazebo reference="rear_right_wheel_link">
    <material>Gazebo/DarkGrey</material>
    <mu1>0.0</mu1>
    <mu2>0.0</mu2>
  </gazebo>
  <!-- This is an wheel-level solution to possibly revisit at a future date. -->
  <!--<gazebo>
    <plugin name="mecanum_gazebo" filename="libmecanum_force_plugin.so">
      <wheelJointName>front_left_wheel</wheelJointName>
      <forceScaleFactor>1</forceScaleFactor>
    </plugin>
    <plugin name="mecanum_gazebo" filename="libmecanum_force_plugin.so">
      <wheelJointName>front_right_wheel</wheelJointName>
      <forceScaleFactor>-1</forceScaleFactor>
    </plugin>
    <plugin name="mecanum_gazebo" filename="libmecanum_force_plugin.so">
      <wheelJointName>rear_left_wheel</wheelJointName>
      <forceScaleFactor>-1</forceScaleFactor>
    </plugin>
    <plugin name="mecanum_gazebo" filename="libmecanum_force_plugin.so">
      <wheelJointName>rear_right_wheel</wheelJointName>
      <forceScaleFactor>1</forceScaleFactor>
    </plugin>
  </gazebo> -->
  <!--
    As you add to this URDF, please be aware that both the robot and
    simulation include it. You must retain compatibility with all of
    the following launch files:

    ridgeback_viz/launch/view_model.launch
    ridgeback_gazebo/launch/ridgeback_world.launch
    ridgeback_base/launch/base.launch
  -->
  <joint name="front_laser_joint" type="fixed">
    <origin rpy="0 0 0.0" xyz="0.3932 0 0.2330" />
    <parent link="chassis_link" />
    <child link="front_laser" />
  </joint>
  <link name="front_laser">
    <inertial>
      <mass value="0.130" />
      <origin xyz="0 0 0" />
      <inertia ixx="8.01666346e-05" ixy="0.0" ixz="0.0" iyy="8.01666346e-05" iyz="0.0" izz="5.4166645e-05" />
    </inertial>
    <visual>
      <origin rpy="0 0 0" xyz="0 0 0" />
      <geometry>
        <!-- Origin of this mesh is the focal point of the LIDAR. -->
        <mesh filename="package://ridgeback_description/meshes/ust-10lx.stl" />
      </geometry>
      <material name="dark_grey" />
    </visual>
    <collision>
      <origin rpy="0 0 0" xyz="0 0 -0.0122" />
      <geometry>
        <box size="0.05 0.05 0.07" />
      </geometry>
    </collision>
  </link>
  <gazebo reference="front_laser">
    <turnGravityOff>false</turnGravityOff>
    <sensor name="front_laser" type="ray">
      <pose>0 0 0 0 0 0</pose>
      <visualize>false</visualize>
      <update_rate>50</update_rate>
      <ray>
        <scan>
          <horizontal>
            <samples>720</samples>
            <resolution>1</resolution>
            <min_angle>-2.35619</min_angle>
            <max_angle>2.35619</max_angle>
          </horizontal>
        </scan>
        <range>
          <min>0.20</min>
          <max>10.0</max>
          <resolution>0.01</resolution>
        </range>
        <noise>
          <type>gaussian</type>
          <mean>0.0</mean>
          <stddev>0.001</stddev>
        </noise>
      </ray>
      <plugin filename="libgazebo_ros_laser.so" name="gazebo_ros_laser">
        <topicName>front/scan</topicName>
        <frameName>front_laser</frameName>
        <hokuyoMinIntensity>101</hokuyoMinIntensity>
      </plugin>
    </sensor>
    <material>Gazebo/DarkGrey</material>
  </gazebo>
  <joint name="rear_laser_joint" type="fixed">
    <origin rpy="0 0 3.14159265359" xyz="-0.3932 0 0.2330" />
    <parent link="chassis_link" />
    <child link="rear_laser" />
  </joint>
  <link name="rear_laser">
    <inertial>
      <mass value="0.130" />
      <origin xyz="0 0 0" />
      <inertia ixx="8.01666346e-05" ixy="0.0" ixz="0.0" iyy="8.01666346e-05" iyz="0.0" izz="5.4166645e-05" />
    </inertial>
    <visual>
      <origin rpy="0 0 0" xyz="0 0 0" />
      <geometry>
        <!-- Origin of this mesh is the focal point of the LIDAR. -->
        <mesh filename="package://ridgeback_description/meshes/ust-10lx.stl" />
      </geometry>
      <material name="dark_grey" />
    </visual>
    <collision>
      <origin rpy="0 0 0" xyz="0 0 -0.0122" />
      <geometry>
        <box size="0.05 0.05 0.07" />
      </geometry>
    </collision>
  </link>
  <gazebo reference="rear_laser">
    <turnGravityOff>false</turnGravityOff>
    <sensor name="rear_laser" type="ray">
      <pose>0 0 0 0 0 0</pose>
      <visualize>false</visualize>
      <update_rate>50</update_rate>
      <ray>
        <scan>
          <horizontal>
            <samples>720</samples>
            <resolution>1</resolution>
            <min_angle>-2.35619</min_angle>
            <max_angle>2.35619</max_angle>
          </horizontal>
        </scan>
        <range>
          <min>0.20</min>
          <max>10.0</max>
          <resolution>0.01</resolution>
        </range>
        <noise>
          <type>gaussian</type>
          <mean>0.0</mean>
          <stddev>0.001</stddev>
        </noise>
      </ray>
      <plugin filename="libgazebo_ros_laser.so" name="gazebo_ros_laser">
        <topicName>rear/scan</topicName>
        <frameName>rear_laser</frameName>
        <hokuyoMinIntensity>101</hokuyoMinIntensity>
      </plugin>
    </sensor>
    <material>Gazebo/DarkGrey</material>
  </gazebo>
  <link name="leg_1_link">
    <visual>
      <origin rpy="0 0 0" xyz="0 0 0" />
      <geometry>
        <mesh filename="package://ridgeback_manipulation_description/meshes/fams-table-leg.stl" />
      </geometry>
      <material name="light_grey" />
    </visual>
    <collision>
      <origin rpy="0 0 0" xyz="0 0 0.15" />
      <geometry>
        <box size="0.04 0.04 0.30" />
      </geometry>
    </collision>
  </link>
  <link name="leg_2_link">
    <visual>
      <origin rpy="0 0 0" xyz="0 0 0" />
      <geometry>
        <mesh filename="package://ridgeback_manipulation_description/meshes/fams-table-leg.stl" />
      </geometry>
      <material name="light_grey" />
    </visual>
    <collision>
      <origin rpy="0 0 0" xyz="0 0 0.15" />
      <geometry>
        <box size="0.04 0.04 0.30" />
      </geometry>
    </collision>
  </link>
  <link name="leg_3_link">
    <visual>
      <origin rpy="0 0 0" xyz="0 0 0" />
      <geometry>
        <mesh filename="package://ridgeback_manipulation_description/meshes/fams-table-leg.stl" />
      </geometry>
      <material name="light_grey" />
    </visual>
    <collision>
      <origin rpy="0 0 0" xyz="0 0 0.15" />
      <geometry>
        <box size="0.04 0.04 0.30" />
      </geometry>
    </collision>
  </link>
  <link name="leg_4_link">
    <visual>
      <origin rpy="0 0 0" xyz="0 0 0" />
      <geometry>
        <mesh filename="package://ridgeback_manipulation_description/meshes/fams-table-leg.stl" />
      </geometry>
      <material name="light_grey" />
    </visual>
    <collision>
      <origin rpy="0 0 0" xyz="0 0 0.15" />
      <geometry>
        <box size="0.04 0.04 0.30" />
      </geometry>
    </collision>
  </link>
  <link name="leg_5_link">
    <visual>
      <origin rpy="0 0 0" xyz="0 0 0" />
      <geometry>
        <mesh filename="package://ridgeback_manipulation_description/meshes/fams-table-leg.stl" />
      </geometry>
      <material name="light_grey" />
    </visual>
    <collision>
      <origin rpy="0 0 0" xyz="0 0 0.15" />
      <geometry>
        <box size="0.04 0.04 0.30" />
      </geometry>
    </collision>
  </link>
  <link name="leg_6_link">
    <visual>
      <origin rpy="0 0 0" xyz="0 0 0" />
      <geometry>
        <mesh filename="package://ridgeback_manipulation_description/meshes/fams-table-leg.stl" />
      </geometry>
      <material name="light_grey" />
    </visual>
    <collision>
      <origin rpy="0 0 0" xyz="0 0 0.15" />
      <geometry>
        <box size="0.04 0.04 0.30" />
      </geometry>
    </collision>
  </link>
  <link name="leg_7_link">
    <visual>
      <origin rpy="0 0 0" xyz="0 0 0" />
      <geometry>
        <mesh filename="package://ridgeback_manipulation_description/meshes/fams-table-leg.stl" />
      </geometry>
      <material name="light_grey" />
    </visual>
    <collision>
      <origin rpy="0 0 0" xyz="0 0 0.15" />
      <geometry>
        <box size="0.04 0.04 0.30" />
      </geometry>
    </collision>
  </link>
  <link name="leg_8_link">
    <visual>
      <origin rpy="0 0 0" xyz="0 0 0" />
      <geometry>
        <mesh filename="package://ridgeback_manipulation_description/meshes/fams-table-leg.stl" />
      </geometry>
      <material name="light_grey" />
    </visual>
    <collision>
      <origin rpy="0 0 0" xyz="0 0 0.15" />
      <geometry>
        <box size="0.04 0.04 0.30" />
      </geometry>
    </collision>
  </link>
  <link name="table_top_link">
    <visual>
      <geometry>
        <mesh filename="package://ridgeback_description/meshes/top.stl" />
      </geometry>
      <material name="black" />
    </visual>
    <collision>
      <geometry>
        <mesh filename="package://ridgeback_description/meshes/top.stl" />
      </geometry>
    </collision>
  </link>
  <link name="fams_mid_link" />
  <link name="arm_mount_link" />
  <joint name="leg_1_joint" type="fixed">
    <origin rpy="0 0 0.20943951023" xyz="0.40 0.155 0" />
    <parent link="mid_mount" />
    <child link="leg_1_link" />
  </joint>
  <joint name="leg_2_joint" type="fixed">
    <origin rpy="0 0 -0.20943951023" xyz="0.40 -0.155 0" />
    <parent link="mid_mount" />
    <child link="leg_2_link" />
  </joint>
  <joint name="leg_3_joint" type="fixed">
    <origin rpy="0 0 0" xyz="0.28 0.365 0" />
    <parent link="mid_mount" />
    <child link="leg_3_link" />
  </joint>
  <joint name="leg_4_joint" type="fixed">
    <origin rpy="0 0 0" xyz="0.28 -0.365 0" />
    <parent link="mid_mount" />
    <child link="leg_4_link" />
  </joint>
  <joint name="leg_5_joint" type="fixed">
    <origin rpy="0 0 0" xyz="0 0.365 0" />
    <parent link="mid_mount" />
    <child link="leg_5_link" />
  </joint>
  <joint name="leg_6_joint" type="fixed">
    <origin rpy="0 0 0" xyz="0 -0.365 0" />
    <parent link="mid_mount" />
    <child link="leg_6_link" />
  </joint>
  <joint name="leg_7_joint" type="fixed">
    <origin rpy="0 0 -0.26179938779" xyz="-0.38 0.3 0" />
    <parent link="mid_mount" />
    <child link="leg_7_link" />
  </joint>
  <joint name="leg_8_joint" type="fixed">
    <origin rpy="0 0 0.26179938779" xyz="-0.38 -0.3 0" />
    <parent link="mid_mount" />
    <child link="leg_8_link" />
  </joint>
  <joint name="table_top_joint" type="fixed">
    <origin rpy="0 0 0" xyz="0 0 0.3063499" />
    <parent link="chassis_link" />
    <child link="table_top_link" />
  </joint>
  <joint name="fams_mid_joint" type="fixed">
    <origin rpy="0 0 0" xyz="0 0 0.586499" />
    <parent link="base_link" />
    <child link="fams_mid_link" />
  </joint>
  <joint name="arm_mount_joint" type="fixed">
    <parent link="fams_mid_link" />
    <child link="arm_mount_link" />
    <origin rpy="0 0 0" xyz="0.33 0 0" />
  </joint>
  <joint name="franka_mount_joint" type="fixed">
    <parent link="arm_mount_link" />
    <child link="franka_mount_link" />
    <origin rpy="0 0 0" xyz="0 0 0" />
  </joint>
  <link name="franka_mount_link" />
  <joint name="panda_joint_franka_mount_link" type="fixed">
    <parent link="franka_mount_link" />
    <child link="panda_link0" />
    <origin rpy="0 0 0" xyz="0 0 0" />
  </joint>
  <link name="panda_link0">
    <visual>
      <geometry>
        <mesh filename="package://franka_description/meshes/visual/link0.dae" />
      </geometry>
    </visual>
    <collision>
      <origin rpy="0 1.57079632679 0" xyz="-0.075 0 0.06" />
      <geometry>
        <cylinder length="0.03" radius="0.06" />
      </geometry>
    </collision>
    <collision>
      <origin rpy="0 0 0" xyz="-0.06 0 0.06" />
      <geometry>
        <sphere radius="0.06" />
      </geometry>
    </collision>
    <collision>
      <origin rpy="0 0 0" xyz="-0.09 0 0.06" />
      <geometry>
        <sphere radius="0.06" />
      </geometry>
    </collision>
  </link>
  <link name="panda_link1">
    <visual>
      <geometry>
        <mesh filename="package://franka_description/meshes/visual/link1.dae" />
      </geometry>
    </visual>
    <collision>
      <origin rpy="0 0 0" xyz="0 0 -0.1915" />
      <geometry>
        <cylinder length="0.2830" radius="0.06" />
      </geometry>
    </collision>
    <collision>
      <origin rpy="0 0 0" xyz="0 0 -0.333" />
      <geometry>
        <sphere radius="0.06" />
      </geometry>
    </collision>
    <collision>
      <origin rpy="0 0 0" xyz="0 0 -0.05" />
      <geometry>
        <sphere radius="0.06" />
      </geometry>
    </collision>
  </link>
  <joint name="panda_joint1" type="revolute">
    <safety_controller k_position="100.0" k_velocity="40.0" soft_lower_limit="-2.8973" soft_upper_limit="2.8973" />
    <origin rpy="0 0 0" xyz="0 0 0.333" />
    <parent link="panda_link0" />
    <child link="panda_link1" />
    <axis xyz="0 0 1" />
    <limit effort="87" lower="-2.8973" upper="2.8973" velocity="2.1750" />
  </joint>
  <link name="panda_link2">
    <visual>
      <geometry>
        <mesh filename="package://franka_description/meshes/visual/link2.dae" />
      </geometry>
    </visual>
    <collision>
      <origin rpy="0 0 0" xyz="0 0 0" />
      <geometry>
        <cylinder length="0.12" radius="0.06" />
      </geometry>
    </collision>
    <collision>
      <origin rpy="0 0 0" xyz="0 0 -0.06" />
      <geometry>
        <sphere radius="0.06" />
      </geometry>
    </collision>
    <collision>
      <origin rpy="0 0 0" xyz="0 0 0.06" />
      <geometry>
        <sphere radius="0.06" />
      </geometry>
    </collision>
  </link>
  <joint name="panda_joint2" type="revolute">
    <safety_controller k_position="100.0" k_velocity="40.0" soft_lower_limit="-1.7628" soft_upper_limit="1.7628" />
    <origin rpy="-1.57079632679 0 0" xyz="0 0 0" />
    <parent link="panda_link1" />
    <child link="panda_link2" />
    <axis xyz="0 0 1" />
    <limit effort="87" lower="-1.7628" upper="1.7628" velocity="2.1750" />
  </joint>
  <link name="panda_link3">
    <visual>
      <geometry>
        <mesh filename="package://franka_description/meshes/visual/link3.dae" />
      </geometry>
    </visual>
    <collision>
      <origin rpy="0 0 0" xyz="0 0 -0.145" />
      <geometry>
        <cylinder length="0.15" radius="0.06" />
      </geometry>
    </collision>
    <collision>
      <origin rpy="0 0 0" xyz="0 0 -0.22" />
      <geometry>
        <sphere radius="0.06" />
      </geometry>
    </collision>
    <collision>
      <origin rpy="0 0 0" xyz="0 0 -0.07" />
      <geometry>
        <sphere radius="0.06" />
      </geometry>
    </collision>
  </link>
  <joint name="panda_joint3" type="revolute">
    <safety_controller k_position="100.0" k_velocity="40.0" soft_lower_limit="-2.8973" soft_upper_limit="2.8973" />
    <origin rpy="1.57079632679 0 0" xyz="0 -0.316 0" />
    <parent link="panda_link2" />
    <child link="panda_link3" />
    <axis xyz="0 0 1" />
    <limit effort="87" lower="-2.8973" upper="2.8973" velocity="2.1750" />
  </joint>
  <link name="panda_link4">
    <visual>
      <geometry>
        <mesh filename="package://franka_description/meshes/visual/link4.dae" />
      </geometry>
    </visual>
    <collision>
      <origin rpy="0 0 0" xyz="0 0 0" />
      <geometry>
        <cylinder length="0.12" radius="0.06" />
      </geometry>
    </collision>
    <collision>
      <origin rpy="0 0 0" xyz="0 0 0.06" />
      <geometry>
        <sphere radius="0.06" />
      </geometry>
    </collision>
    <collision>
      <origin rpy="0 0 0" xyz="0 0 -0.06" />
      <geometry>
        <sphere radius="0.06" />
      </geometry>
    </collision>
  </link>
  <joint name="panda_joint4" type="revolute">
    <safety_controller k_position="100.0" k_velocity="40.0" soft_lower_limit="-3.0718" soft_upper_limit="-0.0698" />
    <origin rpy="1.57079632679 0 0" xyz="0.0825 0 0" />
    <parent link="panda_link3" />
    <child link="panda_link4" />
    <axis xyz="0 0 1" />
    <limit effort="87" lower="-3.0718" upper="-0.0698" velocity="2.1750" />
  </joint>
  <link name="panda_link5">
    <visual>
      <geometry>
        <mesh filename="package://franka_description/meshes/visual/link5.dae" />
      </geometry>
    </visual>
    <collision>
      <origin rpy="0 0 0" xyz="0 0 -0.26" />
      <geometry>
        <cylinder length="0.1" radius="0.06" />
      </geometry>
    </collision>
    <collision>
      <origin rpy="0 0 0" xyz="0 0 -0.31" />
      <geometry>
        <sphere radius="0.06" />
      </geometry>
    </collision>
    <collision>
      <origin rpy="0 0 0" xyz="0 0 -0.21" />
      <geometry>
        <sphere radius="0.06" />
      </geometry>
    </collision>
    <collision>
      <origin rpy="0 0 0" xyz="0 0.08 -0.13" />
      <geometry>
        <cylinder length="0.14" radius="0.025" />
      </geometry>
    </collision>
    <collision>
      <origin rpy="0 0 0" xyz="0 0.08 -0.06" />
      <geometry>
        <sphere radius="0.025" />
      </geometry>
    </collision>
    <collision>
      <origin rpy="0 0 0" xyz="0 0.08 -0.20" />
      <geometry>
        <sphere radius="0.025" />
      </geometry>
    </collision>
  </link>
  <joint name="panda_joint5" type="revolute">
    <safety_controller k_position="100.0" k_velocity="40.0" soft_lower_limit="-2.8973" soft_upper_limit="2.8973" />
    <origin rpy="-1.57079632679 0 0" xyz="-0.0825 0.384 0" />
    <parent link="panda_link4" />
    <child link="panda_link5" />
    <axis xyz="0 0 1" />
    <limit effort="12" lower="-2.8973" upper="2.8973" velocity="2.6100" />
  </joint>
  <link name="panda_link6">
    <visual>
      <geometry>
        <mesh filename="package://franka_description/meshes/visual/link6.dae" />
      </geometry>
    </visual>
    <collision>
      <origin rpy="0 0 0" xyz="0 0 -0.03" />
      <geometry>
        <cylinder length="0.08" radius="0.05" />
      </geometry>
    </collision>
    <collision>
      <origin rpy="0 0 0" xyz="0 0 0.01" />
      <geometry>
        <sphere radius="0.05" />
      </geometry>
    </collision>
    <collision>
      <origin rpy="0 0 0" xyz="0 0 -0.07" />
      <geometry>
        <sphere radius="0.05" />
      </geometry>
    </collision>
  </link>
  <joint name="panda_joint6" type="revolute">
    <safety_controller k_position="100.0" k_velocity="40.0" soft_lower_limit="-0.0175" soft_upper_limit="3.7525" />
    <origin rpy="1.57079632679 0 0" xyz="0 0 0" />
    <parent link="panda_link5" />
    <child link="panda_link6" />
    <axis xyz="0 0 1" />
    <limit effort="12" lower="-0.0175" upper="3.7525" velocity="2.6100" />
  </joint>
  <link name="panda_link7">
    <visual>
      <geometry>
        <mesh filename="package://franka_description/meshes/visual/link7.dae" />
      </geometry>
    </visual>
    <collision>
      <origin rpy="0 0 0" xyz="0 0 0.01" />
      <geometry>
        <cylinder length="0.14" radius="0.04" />
      </geometry>
    </collision>
    <collision>
      <origin rpy="0 0 0" xyz="0 0 0.08" />
      <geometry>
        <sphere radius="0.04" />
      </geometry>
    </collision>
    <collision>
      <origin rpy="0 0 0" xyz="0 0 -0.06" />
      <geometry>
        <sphere radius="0.04" />
      </geometry>
    </collision>
  </link>
  <joint name="panda_joint7" type="revolute">
    <safety_controller k_position="100.0" k_velocity="40.0" soft_lower_limit="-2.8973" soft_upper_limit="2.8973" />
    <origin rpy="1.57079632679 0 0" xyz="0.088 0 0" />
    <parent link="panda_link6" />
    <child link="panda_link7" />
    <axis xyz="0 0 1" />
    <limit effort="12" lower="-2.8973" upper="2.8973" velocity="2.6100" />
  </joint>
  <link name="panda_link8">
    <collision>
      <origin rpy="3.14159265359 1.57079632679 1.57079632679" xyz="0.0424 0.0424 -0.0250" />
      <geometry>
        <cylinder length="0.01" radius="0.03" />
      </geometry>
    </collision>
    <collision>
      <origin rpy="0 0 0" xyz="0.0424 0.0424 -0.02" />
      <geometry>
        <sphere radius="0.03" />
      </geometry>
    </collision>
    <collision>
      <origin rpy="0 0 0" xyz="0.0424 0.0424 -0.03" />
      <geometry>
        <sphere radius="0.03" />
      </geometry>
    </collision>
  </link>
  <joint name="panda_joint8" type="fixed">
    <origin rpy="0 0 0" xyz="0 0 0.107" />
    <parent link="panda_link7" />
    <child link="panda_link8" />
  </joint>
  <joint name="panda_hand_joint" type="fixed">
    <parent link="panda_link8" />
    <child link="panda_hand" />
    <origin rpy="0 0 -0.785398163397" xyz="0 0 0" />
  </joint>
  <link name="panda_hand">
    <visual>
      <geometry>
        <mesh filename="package://franka_description/meshes/visual/hand.dae" />
      </geometry>
    </visual>
    <collision>
      <geometry>
        <mesh filename="package://franka_description/meshes/collision/hand.stl" />
      </geometry>
    </collision>
  </link>
  <link name="panda_leftfinger">
    <visual>
      <geometry>
        <mesh filename="package://franka_description/meshes/visual/finger.dae" />
      </geometry>
    </visual>
    <collision>
      <geometry>
        <mesh filename="package://franka_description/meshes/collision/finger.stl" />
      </geometry>
    </collision>
  </link>
  <link name="panda_rightfinger">
    <visual>
      <origin rpy="0 0 3.14159265359" xyz="0 0 0" />
      <geometry>
        <mesh filename="package://franka_description/meshes/visual/finger.dae" />
      </geometry>
    </visual>
    <collision>
      <origin rpy="0 0 3.14159265359" xyz="0 0 0" />
      <geometry>
        <mesh filename="package://franka_description/meshes/collision/finger.stl" />
      </geometry>
    </collision>
  </link>
  <joint name="panda_finger_joint1" type="prismatic">
    <parent link="panda_hand" />
    <child link="panda_leftfinger" />
    <origin rpy="0 0 0" xyz="0 0 0.0584" />
    <axis xyz="0 1 0" />
    <limit effort="20" lower="0.0" upper="0.04" velocity="0.2" />
  </joint>
  <joint name="panda_finger_joint2" type="prismatic">
    <parent link="panda_hand" />
    <child link="panda_rightfinger" />
    <origin rpy="0 0 0" xyz="0 0 0.0584" />
    <axis xyz="0 -1 0" />
    <limit effort="20" lower="0.0" upper="0.04" velocity="0.2" />
    <mimic joint="panda_finger_joint1" />
  </joint>
</robot>